Workbook

Sheet How to use
B2: MyFinMantra — Cash Flow Statement (Indirect Method)
B3: Client service format · Clear books. Confident business.
B5: Purpose | C5: Prepares the cash flow statement under the indirect method (AS 3 / Ind AS 7 format) from two balance sheets and a few profit and loss figures, with a built-in check that the computed closing cash agrees with the balance sheet.
B7: Colour legend
B8: 12,500 | C8: Blue text on yellow = input. Type or paste your client's figures here.
B9: Formula | C9: Black text = formula. Don't overwrite; it updates automatically.
B10: Header | C10: Section and column headings.
B12: Steps
B13: Step 1 | C13: On 'Balance Sheet', enter the previous year and current year figures. The check row must show 0.
B14: Step 2 | C14: On 'P&L & Other Info', enter profit before tax, depreciation, finance costs, interest income, tax paid and the other items listed.
B15: Step 3 | C15: Open 'Cash Flow Statement'. Operating, investing and financing activities calculate automatically.
B16: Step 4 | C16: The final check compares computed closing cash with the balance sheet. If it isn't 0, look at the reserves check on 'P&L & Other Info' and any items not covered (e.g. revaluation, bonus shares).
B18: Notes
C19: Purchase of PPE is derived: closing net PPE − opening net PPE + depreciation + book value of PPE sold.
C20: Interest paid is taken as equal to finance costs and interest received as interest income (no accruals). Changes in investments are treated as purchases / sales for cash.
C21: Increase in share capital is treated as cash raised; securities premium should be added via reserves only if received in cash.
B23: Sample figures are filled in so you can see how the format works. Replace them with your own data.
B25: Free template by MyFinMantra
B26: Accounting, GST, payroll and Virtual CFO services · www.myfinmantra.com · WhatsApp +91 97118 99555
B27: General template for guidance only — verify rates and rules for your case. Not professional advice.

Sheet Cash Flow Statement
B2: ="Cash flow statement for the year" -> Cash flow statement for the year
B3: Indirect method (AS 3 / Ind AS 7) · ₹
B5: Particulars | C5: ₹ | D5: ₹
B6: A. Cash flow from operating activities
B7: Profit before tax | C7: ='P&L & Other Info'!$C$5 -> 1650000
B8: Adjustments for:
B9: Depreciation and amortisation | C9: ='P&L & Other Info'!$C$7 -> 410000
B10: Finance costs | C10: ='P&L & Other Info'!$C$8 -> 210000
B11: Interest income | C11: =-'P&L & Other Info'!$C$9 -> -35000
B12: Dividend income | C12: =-'P&L & Other Info'!$C$10 -> 0
B13: (Profit) / loss on sale of PPE | C13: =-'P&L & Other Info'!$C$11 -> -15000
B14: Operating profit before working capital changes | D14: =SUM(C7:C13) -> 2220000
B15: Changes in working capital:
B16: (Increase) / decrease in inventories | C16: =-('Balance Sheet'!$D$19-'Balance Sheet'!$C$19) -> -150000
B17: (Increase) / decrease in trade receivables | C17: =-('Balance Sheet'!$D$20-'Balance Sheet'!$C$20) -> -320000
B18: (Increase) / decrease in short-term loans and advances | C18: =-('Balance Sheet'!$D$21-'Balance Sheet'!$C$21) -> 20000
B19: (Increase) / decrease in other current assets | C19: =-('Balance Sheet'!$D$22-'Balance Sheet'!$C$22) -> -20000
B20: Increase / (decrease) in trade payables | C20: =('Balance Sheet'!$D$11-'Balance Sheet'!$C$11) -> 180000
B21: Increase / (decrease) in other current liabilities | C21: =('Balance Sheet'!$D$12-'Balance Sheet'!$C$12) -> 60000
B22: Increase / (decrease) in short-term provisions | C22: =('Balance Sheet'!$D$13-'Balance Sheet'!$C$13) -> 30000
B23: Cash generated from operations | D23: =D14+SUM(C15:C22) -> 2020000
B24: Income tax paid (net) | C24: =-'P&L & Other Info'!$C$13 -> -410000
B25: Net cash from operating activities (A) | D25: =D23+SUM(C24:C24) -> 1610000
B27: B. Cash flow from investing activities
B28: Purchase of property, plant and equipment | C28: =-('Balance Sheet'!$D$17-'Balance Sheet'!$C$17+'P&L & Other Info'!$C$7+('P&L & Other Info'!$C$12-'P&L & Other Info'!$C$11)) -> -910000
B29: Proceeds from sale of PPE | C29: ='P&L & Other Info'!$C$12 -> 75000
B30: (Purchase) / sale of investments (net) | C30: =-('Balance Sheet'!$D$18-'Balance Sheet'!$C$18) -> -200000
B31: Interest received | C31: ='P&L & Other Info'!$C$9 -> 35000
B32: Dividend received | C32: ='P&L & Other Info'!$C$10 -> 0
B33: Net cash used in investing activities (B) | D33: =SUM(C28:C32) -> -1000000
B35: C. Cash flow from financing activities
B36: Proceeds from issue of share capital | C36: =('Balance Sheet'!$D$7-'Balance Sheet'!$C$7) -> 500000
B37: Proceeds from / (repayment of) long-term borrowings (net) | C37: =('Balance Sheet'!$D$9-'Balance Sheet'!$C$9) -> -300000
B38: Proceeds from / (repayment of) short-term borrowings (net) | C38: =('Balance Sheet'!$D$10-'Balance Sheet'!$C$10) -> 150000
B39: Finance costs paid | C39: =-'P&L & Other Info'!$C$8 -> -210000
B40: Dividends paid | C40: =-'P&L & Other Info'!$C$14 -> -350000
B41: Net cash from / (used in) financing activities (C) | D41: =SUM(C36:C40) -> -210000
B43: Net increase / (decrease) in cash and cash equivalents (A + B + C) | D43: =D25+D33+D41 -> 400000
B45: Cash and cash equivalents at the beginning of the year | C45: ='Balance Sheet'!$C$23 -> 450000
B46: Cash and cash equivalents at the end of the year | D46: =D43+C45 -> 850000
...

Sheet Balance Sheet
B2: Balance sheet
B3: Enter figures as per the financial statements (₹)
B5: Particulars (₹) | C5: Previous year | D5: Current year
B6: Equity and liabilities
B7: Share capital | C7: 1000000 | D7: 1500000
B8: Reserves and surplus (other equity) | C8: 2400000 | D8: 3270000
B9: Long-term borrowings | C9: 1800000 | D9: 1500000
B10: Short-term borrowings | C10: 500000 | D10: 650000
B11: Trade payables | C11: 900000 | D11: 1080000
B12: Other current liabilities | C12: 300000 | D12: 360000
B13: Short-term provisions (excl. tax) | C13: 120000 | D13: 150000
B14: Current tax liabilities (net) | C14: 80000 | D14: 100000
B15: Total equity and liabilities | C15: =SUM(C7:C14) -> 7100000 | D15: =SUM(D7:D14) -> 8610000
B16: Assets
B17: Property, plant and equipment (net) | C17: 3200000 | D17: 3640000
B18: Non-current investments | C18: 500000 | D18: 700000
B19: Inventories | C19: 1100000 | D19: 1250000
B20: Trade receivables | C20: 1500000 | D20: 1820000
B21: Short-term loans and advances | C21: 200000 | D21: 180000
B22: Other current assets | C22: 150000 | D22: 170000
B23: Cash and cash equivalents | C23: 450000 | D23: 850000
B24: Total assets | C24: =SUM(C17:C23) -> 7100000 | D24: =SUM(D17:D23) -> 8610000
B26: Check: assets − liabilities (should be 0) | C26: =C24-C15 -> 0 | D26: =D24-D15 -> 0

Sheet P&L & Other Info
B2: Profit & loss and other information
B3: Current year figures (₹)
B5: Profit before tax | C5: 1650000
B6: Tax expense (current + deferred) | C6: 430000
B7: Depreciation and amortisation | C7: 410000
B8: Finance costs | C8: 210000
B9: Interest income | C9: 35000
B10: Dividend income | C10: 0
B11: Profit / (loss) on sale of PPE | C11: 15000 | D11: Enter a loss as a negative number
B12: Sale proceeds of PPE | C12: 75000
B13: Income tax paid (cash) | C13: 410000 | D13: Advance tax + self-assessment tax paid, net of refunds
B14: Dividends paid | C14: 350000
B16: Reserves check
B17: Profit after tax | C17: =C5-C6 -> 1220000
B18: Less: dividends paid | C18: =C14 -> 350000
B19: Expected increase in reserves | C19: =C17-C18 -> 870000
B20: Actual increase in reserves (balance sheet) | C20: ='Balance Sheet'!$D$8-'Balance Sheet'!$C$8 -> 870000
B21: Difference (should be 0) | C21: =C20-C19 -> 0
