Workbook

Sheet How to use
B2: MyFinMantra — Payroll Calculator (PF, ESI, PT, LWF, TDS)
B3: Client service format · Clear books. Confident business.
B5: Purpose | C5: Monthly payroll for up to 100 employees: earned salary for paid days, PF on the ₹25,000 wage ceiling, ESI, state-wise Professional Tax and Labour Welfare Fund, an estimated monthly TDS (new tax regime), net pay, employer cost, challan summary and a printable payslip.
B7: Colour legend
B8: 12,500 | C8: Blue text on yellow = input. Type or paste your client's figures here.
B9: Formula | C9: Black text = formula. Don't overwrite; it updates automatically.
B10: Header | C10: Section and column headings.
B12: Steps
B13: Step 1 | C13: On 'Rates & Settings', set the company name and the payroll month. Rates are pre-filled for 2026-27; update them if the government changes them.
B14: Step 2 | C14: On 'Payroll', enter each employee once: state, PF options and the fixed monthly salary structure (Basic, DA, HRA and allowances).
B15: Step 3 | C15: Every month, change the payroll month and enter paid days (and any other deductions or TDS override). Everything else calculates.
B16: Step 4 | C16: Use 'Challan Summary' for the PF ECR, ESI, PT, LWF and TDS amounts to pay, with due dates.
B17: Step 5 | C17: On 'Payslip', pick an employee ID to print a payslip (File → Export → PDF).
B19: Notes
C20: PF: 12% employee and 12% employer on PF wages; ceiling ₹25,000 a month from 17 Sep 2026 (S.O. 5109(E)); employer share splits into EPS 8.33% (on wages up to the ceiling) and EPF for the balance; EDLI 0.5% and admin charges 0.5% (EPFO's ₹500 minimum admin charge per establishment is not applied).
C21: Labour Codes (in force from 21 Nov 2025): if Basic + DA is below 50% of total pay, the shortfall is added to 'wages' for PF. Switch this off on 'Rates & Settings' if not applicable.
C22: ESI: 0.75% employee and 3.25% employer, for employees whose fixed gross is up to ₹21,000 a month; amounts rounded up to the next rupee.
C23: PT is automatic for states with monthly slabs. For Tamil Nadu, Kerala (half-yearly) and Madhya Pradesh (quarterly), enter PT in the 'PT override' column. Haryana, Delhi, UP and Rajasthan levy no PT.
C24: TDS is an estimate under the new regime on fixed salary only (standard deduction ₹75,000, ₹12 lakh rebate, 4% cess; surcharge ignored). Use 'TDS override' for exact figures.
B26: Sample figures are filled in so you can see how the format works. Replace them with your own data.
B28: Free template by MyFinMantra
B29: Accounting, GST, payroll and Virtual CFO services · www.myfinmantra.com · WhatsApp +91 97118 99555
B30: General template for guidance only — verify rates and rules for your case. Not professional advice.

Sheet Payroll
B2: Monthly payroll
B3: ='Rates & Settings'!$C$5&" · Payroll for "&TEXT('Rates & Settings'!$C$6,"mmmm yyyy")&" · "&'Rates & Settings'!$C$7&" days" -> Sample Technologies Pvt Ltd · Payroll for October 2026 · 31 days
B4: Employee | J4: Fixed monthly salary (₹) | Q4: Earnings & statutory wages | U4: Employee deductions | AF4: Employer contributions | AM4: TDS working
B5: Emp ID | C5: Employee name | D5: Designation | E5: State | F5: PF member? | G5: Restrict PF to ceiling? | H5: EPS member? | I5: Paid days | J5: Basic | K5: DA | L5: HRA | M5: Conveyance | N5: Special allowance | O5: Other allowances | P5: Fixed gross | Q5: Earned gross | R5: Earned Basic + DA | S5: Wages (Labour Code) | T5: PF wages | U5: Employee PF | V5: ESI applicable | W5: Employee ESI | X5: PT | Y5: PT override | Z5: LWF employee | AA5: TDS (estimate) | AB5: TDS override | AC5: Other deductions | AD5: Total deductions | AE5: Net pay | AF5: Employer EPF | AG5: Employer EPS | AH5: EDLI | AI5: PF admin | AJ5: Employer ESI | AK5: LWF employer | AL5: Employer cost (month) | AM5: Annual taxable (est.) | AN5: Annual tax (est.)
B6: E001 | C6: Rahul Sharma | D6: Accounts Executive | E6: Haryana | F6: Yes | G6: Yes | H6: Yes | I6: 31 | J6: 8000 | K6: 0 | L6: 4000 | M6: 1600 | N6: 6400 | O6: 0 | P6: =IF(B6="","",SUM(J6:O6)) -> 20000 | Q6: =IF(B6="","",ROUND(P6*N(I6)/'Rates & Settings'!$C$7,0)) -> 20000 | R6: =IF(B6="","",ROUND((N(J6)+N(K6))*N(I6)/'Rates & Settings'!$C$7,0)) -> 8000 | S6: =IF(B6="","",IF('Rates & Settings'!$C$14="Yes",MAX(R6,ROUND(Q6*0.5,0)),R6)) -> 10000 | T6: =IF(B6="","",IF(F6="Yes",IF(G6="Yes",MIN(S6,'Rates & Settings'!$C$8),S6),0)) -> 10000 | U6: =IF(B6="","",ROUND(T6*'Rates & Settings'!$C$9,0)) -> 1200 | V6: =IF(B6="","",IF(P6<='Rates & Settings'!$C$17,"Yes","No")) -> Yes | W6: =IF(B6="","",IF(V6="Yes",ROUNDUP(Q6*'Rates & Settings'!$C$15,0),0)) -> 150 | X6: =IF(B6="","",IF(Y6<>"",N(Y6),IF(MONTH('Rates & Settings'!$C$6)=2,SUMIFS('Rates & Settings'!$F$35:$F$70,'Rates & Settings'!$B$35:$B$70,E6,'Rates & Settings'!$C$35:$C$70,"<="&Q6,'Rates & Settings'!$D$35:$D$70,">="&Q6),SUMIFS('Rates & Settings'!$E$35:$E$70,'Rates & Settings'!$B$35:$B$70,E6,'Rates & Settings'!$C$35:$C$70,"<="&Q6,'Rates & Settings'!$D$35:$D$70,">="&Q6)))) -> 0 | Z6: =IF(B6="","",IFERROR(IF(OR(INDEX('Rates & Settings'!$H$75:$H$96,MATCH(E6,'Rates & Settings'!$B$75:$B$96,0))="All",ISNUMBER(SEARCH(","&MONTH('Rates & Settings'!$C$6)&",",","&INDEX('Rates & Settings'!$H$75:$H$96,MATCH(E6,'Rates & Settings'!$B$75:$B$96,0))&","))),IF(INDEX('Rates & Settings'!$C$75:$C$96,MATCH(E6,'Rates & Settings'!$B$75:$B$96,0))="Percent",MIN(ROUND(Q6*INDEX('Rates & Settings'!$D$75:$D$96,MATCH(E6,'Rates & Settings'!$B$75:$B$96,0)),0),INDEX('Rates & Settings'!$F$75:$F$96,MATCH(E6,'Rates & Settings'!$B$75:$B$96,0))),INDEX('Rates & Settings'!$D$75:$D$96,MATCH(E6,'Rates & Settings'!$B$75:$B$96,0))),0),0)) -> 35 | AA6: =IF(B6="","",ROUND(AN6/12,0)) -> 0 | AD6: =IF(B6="","",U6+W6+X6+Z6+IF(AB6<>"",N(AB6),AA6)+N(AC6)) -> 1385 | AE6: =IF(B6="","",Q6-AD6) -> 18615 | AF6: =IF(B6="","",ROUND(T6*'Rates & Settings'!$C$10,0)-AG6) -> 367 | AG6: =IF(B6="","",IF(H6="Yes",ROUND(MIN(T6,'Rates & Settings'!$C$8)*'Rates & Settings'!$C$11,0),0)) -> 833 | AH6: =IF(B6="","",ROUND(MIN(T6,'Rates & Settings'!$C$8)*'Rates & Settings'!$C$12,0)) -> 50 | AI6: =IF(B6="","",ROUND(T6*'Rates & Settings'!$C$13,0)) -> 50 | AJ6: =IF(B6="","",IF(V6="Yes",ROUNDUP(Q6*'Rates & Settings'!$C$16,0),0)) -> 650 | AK6: =IF(B6="","",IFERROR(IF(Z6=0,0,IF(INDEX('Rates & Settings'!$C$75:$C$96,MATCH(E6,'Rates & Settings'!$B$75:$B$96,0))="Percent",MIN(Z6*INDEX('Rates & Settings'!$E$75:$E$96,MATCH(E6,'Rates & Settings'!$B$75:$B$96,0)),INDEX('Rates & Settings'!$G$75:$G$96,MATCH(E6,'Rates & Settings'!$B$75:$B$96,0))),INDEX('Rates & Settings'!$E$75:$E$96,MATCH(E6,'Rates & Settings'!$B$75:$B$96,0)))),0)) -> 70 | AL6: =IF(B6="","",Q6+AF6+AG6+AH6+AI6+AJ6+AK6) -> 22020 | AM6: =IF(B6="","",MAX(0,P6*12-'Rates & Settings'!$C$18)) -> 165000 | AN6: =IF(B6="","",IF(AM6<='Rates & Settings'!$C$19,0,MIN(SUMPRODUCT(--(AM6>'Rates & Settings'!$B$24:$B$30),AM6-'Rates & Settings'!$B$24:$B$30,'Rates & Settings'!$D$24:$D$30),AM6-'Rates & Settings'!$C$19))*(1+'Rates & Settings'!$C$20)) -> 0
B7: E002 | C7: Priya Nair | D7: HR Manager | E7: Karnataka | F7: Yes | G7: Yes | H7: Yes | I7: 31 | J7: 30000 | K7: 0 | L7: 15000 | M7: 1600 | N7: 8400 | O7: 5000 | P7: =IF(B7="","",SUM(J7:O7)) -> 60000 | Q7: =IF(B7="","",ROUND(P7*N(I7)/'Rates & Settings'!$C$7,0)) -> 60000 | R7: =IF(B7="","",ROUND((N(J7)+N(K7))*N(I7)/'Rates & Settings'!$C$7,0)) -> 30000 | S7: =IF(B7="","",IF('Rates & Settings'!$C$14="Yes",MAX(R7,ROUND(Q7*0.5,0)),R7)) -> 30000 | T7: =IF(B7="","",IF(F7="Yes",IF(G7="Yes",MIN(S7,'Rates & Settings'!$C$8),S7),0)) -> 25000 | U7: =IF(B7="","",ROUND(T7*'Rates & Settings'!$C$9,0)) -> 3000 | V7: =IF(B7="","",IF(P7<='Rates & Settings'!$C$17,"Yes","No")) -> No | W7: =IF(B7="","",IF(V7="Yes",ROUNDUP(Q7*'Rates & Settings'!$C$15,0),0)) -> 0 | X7: =IF(B7="","",IF(Y7<>"",N(Y7),IF(MONTH('Rates & Settings'!$C$6)=2,SUMIFS('Rates & Settings'!$F$35:$F$70,'Rates & Settings'!$B$35:$B$70,E7,'Rates & Settings'!$C$35:$C$70,"<="&Q7,'Rates & Settings'!$D$35:$D$70,">="&Q7),SUMIFS('Rates & Settings'!$E$35:$E$70,'Rates & Settings'!$B$35:$B$70,E7,'Rates & Settings'!$C$35:$C$70,"<="&Q7,'Rates & Settings'!$D$35:$D$70,">="&Q7)))) -> 200 | Z7: =IF(B7="","",IFERROR(IF(OR(INDEX('Rates & Settings'!$H$75:$H$96,MATCH(E7,'Rates & Settings'!$B$75:$B$96,0))="All",ISNUMBER(SEARCH(","&MONTH('Rates & Settings'!$C$6)&",",","&INDEX('Rates & Settings'!$H$75:$H$96,MATCH(E7,'Rates & Settings'!$B$75:$B$96,0))&","))),IF(INDEX('Rates & Settings'!$C$75:$C$96,MATCH(E7,'Rates & Settings'!$B$75:$B$96,0))="Percent",MIN(ROUND(Q7*INDEX('Rates & Settings'!$D$75:$D$96,MATCH(E7,'Rates & Settings'!$B$75:$B$96,0)),0),INDEX('Rates & Settings'!$F$75:$F$96,MATCH(E7,'Rates & Settings'!$B$75:$B$96,0))),INDEX('Rates & Settings'!$D$75:$D$96,MATCH(E7,'Rates & Settings'!$B$75:$B$96,0))),0),0)) -> 0 | AA7: =IF(B7="","",ROUND(AN7/12,0)) -> 0 | AD7: =IF(B7="","",U7+W7+X7+Z7+IF(AB7<>"",N(AB7),AA7)+N(AC7)) -> 3200 | AE7: =IF(B7="","",Q7-AD7) -> 56800 | AF7: =IF(B7="","",ROUND(T7*'Rates & Settings'!$C$10,0)-AG7) -> 917 | AG7: =IF(B7="","",IF(H7="Yes",ROUND(MIN(T7,'Rates & Settings'!$C$8)*'Rates & Settings'!$C$11,0),0)) -> 2083 | AH7: =IF(B7="","",ROUND(MIN(T7,'Rates & Settings'!$C$8)*'Rates & Settings'!$C$12,0)) -> 125 | AI7: =IF(B7="","",ROUND(T7*'Rates & Settings'!$C$13,0)) -> 125 | AJ7: =IF(B7="","",IF(V7="Yes",ROUNDUP(Q7*'Rates & Settings'!$C$16,0),0)) -> 0 | AK7: =IF(B7="","",IFERROR(IF(Z7=0,0,IF(INDEX('Rates & Settings'!$C$75:$C$96,MATCH(E7,'Rates & Settings'!$B$75:$B$96,0))="Percent",MIN(Z7*INDEX('Rates & Settings'!$E$75:$E$96,MATCH(E7,'Rates & Settings'!$B$75:$B$96,0)),INDEX('Rates & Settings'!$G$75:$G$96,MATCH(E7,'Rates & Settings'!$B$75:$B$96,0))),INDEX('Rates & Settings'!$E$75:$E$96,MATCH(E7,'Rates & Settings'!$B$75:$B$96,0)))),0)) -> 0 | AL7: =IF(B7="","",Q7+AF7+AG7+AH7+AI7+AJ7+AK7) -> 63250 | AM7: =IF(B7="","",MAX(0,P7*12-'Rates & Settings'!$C$18)) -> 645000 | AN7: =IF(B7="","",IF(AM7<='Rates & Settings'!$C$19,0,MIN(SUMPRODUCT(--(AM7>'Rates & Settings'!$B$24:$B$30),AM7-'Rates & Settings'!$B$24:$B$30,'Rates & Settings'!$D$24:$D$30),AM7-'Rates & Settings'!$C$19))*(1+'Rates & Settings'!$C$20)) -> 0
B8: E003 | C8: Amit Patil | D8: Sales Lead | E8: Maharashtra (Men) | F8: Yes | G8: No | H8: No | I8: 29 | J8: 45000 | K8: 0 | L8: 22500 | M8: 1600 | N8: 15900 | O8: 5000 | P8: =IF(B8="","",SUM(J8:O8)) -> 90000 | Q8: =IF(B8="","",ROUND(P8*N(I8)/'Rates & Settings'!$C$7,0)) -> 84194 | R8: =IF(B8="","",ROUND((N(J8)+N(K8))*N(I8)/'Rates & Settings'!$C$7,0)) -> 42097 | S8: =IF(B8="","",IF('Rates & Settings'!$C$14="Yes",MAX(R8,ROUND(Q8*0.5,0)),R8)) -> 42097 | T8: =IF(B8="","",IF(F8="Yes",IF(G8="Yes",MIN(S8,'Rates & Settings'!$C$8),S8),0)) -> 42097 | U8: =IF(B8="","",ROUND(T8*'Rates & Settings'!$C$9,0)) -> 5052 | V8: =IF(B8="","",IF(P8<='Rates & Settings'!$C$17,"Yes","No")) -> No | W8: =IF(B8="","",IF(V8="Yes",ROUNDUP(Q8*'Rates & Settings'!$C$15,0),0)) -> 0 | X8: =IF(B8="","",IF(Y8<>"",N(Y8),IF(MONTH('Rates & Settings'!$C$6)=2,SUMIFS('Rates & Settings'!$F$35:$F$70,'Rates & Settings'!$B$35:$B$70,E8,'Rates & Settings'!$C$35:$C$70,"<="&Q8,'Rates & Settings'!$D$35:$D$70,">="&Q8),SUMIFS('Rates & Settings'!$E$35:$E$70,'Rates & Settings'!$B$35:$B$70,E8,'Rates & Settings'!$C$35:$C$70,"<="&Q8,'Rates & Settings'!$D$35:$D$70,">="&Q8)))) -> 200 | Z8: =IF(B8="","",IFERROR(IF(OR(INDEX('Rates & Settings'!$H$75:$H$96,MATCH(E8,'Rates & Settings'!$B$75:$B$96,0))="All",ISNUMBER(SEARCH(","&MONTH('Rates & Settings'!$C$6)&",",","&INDEX('Rates & Settings'!$H$75:$H$96,MATCH(E8,'Rates & Settings'!$B$75:$B$96,0))&","))),IF(INDEX('Rates & Settings'!$C$75:$C$96,MATCH(E8,'Rates & Settings'!$B$75:$B$96,0))="Percent",MIN(ROUND(Q8*INDEX('Rates & Settings'!$D$75:$D$96,MATCH(E8,'Rates & Settings'!$B$75:$B$96,0)),0),INDEX('Rates & Settings'!$F$75:$F$96,MATCH(E8,'Rates & Settings'!$B$75:$B$96,0))),INDEX('Rates & Settings'!$D$75:$D$96,MATCH(E8,'Rates & Settings'!$B$75:$B$96,0))),0),0)) -> 0 | AA8: =IF(B8="","",ROUND(AN8/12,0)) -> 0 | AD8: =IF(B8="","",U8+W8+X8+Z8+IF(AB8<>"",N(AB8),AA8)+N(AC8)) -> 5252 | AE8: =IF(B8="","",Q8-AD8) -> 78942 | AF8: =IF(B8="","",ROUND(T8*'Rates & Settings'!$C$10,0)-AG8) -> 5052 | AG8: =IF(B8="","",IF(H8="Yes",ROUND(MIN(T8,'Rates & Settings'!$C$8)*'Rates & Settings'!$C$11,0),0)) -> 0 | AH8: =IF(B8="","",ROUND(MIN(T8,'Rates & Settings'!$C$8)*'Rates & Settings'!$C$12,0)) -> 125 | AI8: =IF(B8="","",ROUND(T8*'Rates & Settings'!$C$13,0)) -> 210 | AJ8: =IF(B8="","",IF(V8="Yes",ROUNDUP(Q8*'Rates & Settings'!$C$16,0),0)) -> 0 | AK8: =IF(B8="","",IFERROR(IF(Z8=0,0,IF(INDEX('Rates & Settings'!$C$75:$C$96,MATCH(E8,'Rates & Settings'!$B$75:$B$96,0))="Percent",MIN(Z8*INDEX('Rates & Settings'!$E$75:$E$96,MATCH(E8,'Rates & Settings'!$B$75:$B$96,0)),INDEX('Rates & Settings'!$G$75:$G$96,MATCH(E8,'Rates & Settings'!$B$75:$B$96,0))),INDEX('Rates & Settings'!$E$75:$E$96,MATCH(E8,'Rates & Settings'!$B$75:$B$96,0)))),0)) -> 0 | AL8: =IF(B8="","",Q8+AF8+AG8+AH8+AI8+AJ8+AK8) -> 89581 | AM8: =IF(B8="","",MAX(0,P8*12-'Rates & Settings'!$C$18)) -> 1005000 | AN8: =IF(B8="","",IF(AM8<='Rates & Settings'!$C$19,0,MIN(SUMPRODUCT(--(AM8>'Rates & Settings'!$B$24:$B$30),AM8-'Rates & Settings'!$B$24:$B$30,'Rates & Settings'!$D$24:$D$30),AM8-'Rates & Settings'!$C$19))*(1+'Rates & Settings'!$C$20)) -> 0
B9: E004 | C9: Sneha Das | D9: Associate | E9: West Bengal | F9: Yes | G9: Yes | H9: Yes | I9: 31 | J9: 9000 | K9: 1000 | L9: 4000 | M9: 1600 | N9: 2400 | O9: 0 | P9: =IF(B9="","",SUM(J9:O9)) -> 18000 | Q9: =IF(B9="","",ROUND(P9*N(I9)/'Rates & Settings'!$C$7,0)) -> 18000 | R9: =IF(B9="","",ROUND((N(J9)+N(K9))*N(I9)/'Rates & Settings'!$C$7,0)) -> 10000 | S9: =IF(B9="","",IF('Rates & Settings'!$C$14="Yes",MAX(R9,ROUND(Q9*0.5,0)),R9)) -> 10000 | T9: =IF(B9="","",IF(F9="Yes",IF(G9="Yes",MIN(S9,'Rates & Settings'!$C$8),S9),0)) -> 10000 | U9: =IF(B9="","",ROUND(T9*'Rates & Settings'!$C$9,0)) -> 1200 | V9: =IF(B9="","",IF(P9<='Rates & Settings'!$C$17,"Yes","No")) -> Yes | W9: =IF(B9="","",IF(V9="Yes",ROUNDUP(Q9*'Rates & Settings'!$C$15,0),0)) -> 135 | X9: =IF(B9="","",IF(Y9<>"",N(Y9),IF(MONTH('Rates & Settings'!$C$6)=2,SUMIFS('Rates & Settings'!$F$35:$F$70,'Rates & Settings'!$B$35:$B$70,E9,'Rates & Settings'!$C$35:$C$70,"<="&Q9,'Rates & Settings'!$D$35:$D$70,">="&Q9),SUMIFS('Rates & Settings'!$E$35:$E$70,'Rates & Settings'!$B$35:$B$70,E9,'Rates & Settings'!$C$35:$C$70,"<="&Q9,'Rates & Settings'!$D$35:$D$70,">="&Q9)))) -> 130 | Z9: =IF(B9="","",IFERROR(IF(OR(INDEX('Rates & Settings'!$H$75:$H$96,MATCH(E9,'Rates & Settings'!$B$75:$B$96,0))="All",ISNUMBER(SEARCH(","&MONTH('Rates & Settings'!$C$6)&",",","&INDEX('Rates & Settings'!$H$75:$H$96,MATCH(E9,'Rates & Settings'!$B$75:$B$96,0))&","))),IF(INDEX('Rates & Settings'!$C$75:$C$96,MATCH(E9,'Rates & Settings'!$B$75:$B$96,0))="Percent",MIN(ROUND(Q9*INDEX('Rates & Settings'!$D$75:$D$96,MATCH(E9,'Rates & Settings'!$B$75:$B$96,0)),0),INDEX('Rates & Settings'!$F$75:$F$96,MATCH(E9,'Rates & Settings'!$B$75:$B$96,0))),INDEX('Rates & Settings'!$D$75:$D$96,MATCH(E9,'Rates & Settings'!$B$75:$B$96,0))),0),0)) -> 0 | AA9: =IF(B9="","",ROUND(AN9/12,0)) -> 0 | AD9: =IF(B9="","",U9+W9+X9+Z9+IF(AB9<>"",N(AB9),AA9)+N(AC9)) -> 1465 | AE9: =IF(B9="","",Q9-AD9) -> 16535 | AF9: =IF(B9="","",ROUND(T9*'Rates & Settings'!$C$10,0)-AG9) -> 367 | AG9: =IF(B9="","",IF(H9="Yes",ROUND(MIN(T9,'Rates & Settings'!$C$8)*'Rates & Settings'!$C$11,0),0)) -> 833 | AH9: =IF(B9="","",ROUND(MIN(T9,'Rates & Settings'!$C$8)*'Rates & Settings'!$C$12,0)) -> 50 | AI9: =IF(B9="","",ROUND(T9*'Rates & Settings'!$C$13,0)) -> 50 | AJ9: =IF(B9="","",IF(V9="Yes",ROUNDUP(Q9*'Rates & Settings'!$C$16,0),0)) -> 585 | AK9: =IF(B9="","",IFERROR(IF(Z9=0,0,IF(INDEX('Rates & Settings'!$C$75:$C$96,MATCH(E9,'Rates & Settings'!$B$75:$B$96,0))="Percent",MIN(Z9*INDEX('Rates & Settings'!$E$75:$E$96,MATCH(E9,'Rates & Settings'!$B$75:$B$96,0)),INDEX('Rates & Settings'!$G$75:$G$96,MATCH(E9,'Rates & Settings'!$B$75:$B$96,0))),INDEX('Rates & Settings'!$E$75:$E$96,MATCH(E9,'Rates & Settings'!$B$75:$B$96,0)))),0)) -> 0 | AL9: =IF(B9="","",Q9+AF9+AG9+AH9+AI9+AJ9+AK9) -> 19885 | AM9: =IF(B9="","",MAX(0,P9*12-'Rates & Settings'!$C$18)) -> 141000 | AN9: =IF(B9="","",IF(AM9<='Rates & Settings'!$C$19,0,MIN(SUMPRODUCT(--(AM9>'Rates & Settings'!$B$24:$B$30),AM9-'Rates & Settings'!$B$24:$B$30,'Rates & Settings'!$D$24:$D$30),AM9-'Rates & Settings'!$C$19))*(1+'Rates & Settings'!$C$20)) -> 0
B10: E005 | C10: Karan Mehta | D10: Consultant | E10: Delhi | F10: No | G10: No | H10: No | I10: 31 | J10: 60000 | K10: 0 | L10: 30000 | M10: 1600 | N10: 28400 | O10: 0 | P10: =IF(B10="","",SUM(J10:O10)) -> 120000 | Q10: =IF(B10="","",ROUND(P10*N(I10)/'Rates & Settings'!$C$7,0)) -> 120000 | R10: =IF(B10="","",ROUND((N(J10)+N(K10))*N(I10)/'Rates & Settings'!$C$7,0)) -> 60000 | S10: =IF(B10="","",IF('Rates & Settings'!$C$14="Yes",MAX(R10,ROUND(Q10*0.5,0)),R10)) -> 60000 | T10: =IF(B10="","",IF(F10="Yes",IF(G10="Yes",MIN(S10,'Rates & Settings'!$C$8),S10),0)) -> 0 | U10: =IF(B10="","",ROUND(T10*'Rates & Settings'!$C$9,0)) -> 0 | V10: =IF(B10="","",IF(P10<='Rates & Settings'!$C$17,"Yes","No")) -> No | W10: =IF(B10="","",IF(V10="Yes",ROUNDUP(Q10*'Rates & Settings'!$C$15,0),0)) -> 0 | X10: =IF(B10="","",IF(Y10<>"",N(Y10),IF(MONTH('Rates & Settings'!$C$6)=2,SUMIFS('Rates & Settings'!$F$35:$F$70,'Rates & Settings'!$B$35:$B$70,E10,'Rates & Settings'!$C$35:$C$70,"<="&Q10,'Rates & Settings'!$D$35:$D$70,">="&Q10),SUMIFS('Rates & Settings'!$E$35:$E$70,'Rates & Settings'!$B$35:$B$70,E10,'Rates & Settings'!$C$35:$C$70,"<="&Q10,'Rates & Settings'!$D$35:$D$70,">="&Q10)))) -> 0 | Z10: =IF(B10="","",IFERROR(IF(OR(INDEX('Rates & Settings'!$H$75:$H$96,MATCH(E10,'Rates & Settings'!$B$75:$B$96,0))="All",ISNUMBER(SEARCH(","&MONTH('Rates & Settings'!$C$6)&",",","&INDEX('Rates & Settings'!$H$75:$H$96,MATCH(E10,'Rates & Settings'!$B$75:$B$96,0))&","))),IF(INDEX('Rates & Settings'!$C$75:$C$96,MATCH(E10,'Rates & Settings'!$B$75:$B$96,0))="Percent",MIN(ROUND(Q10*INDEX('Rates & Settings'!$D$75:$D$96,MATCH(E10,'Rates & Settings'!$B$75:$B$96,0)),0),INDEX('Rates & Settings'!$F$75:$F$96,MATCH(E10,'Rates & Settings'!$B$75:$B$96,0))),INDEX('Rates & Settings'!$D$75:$D$96,MATCH(E10,'Rates & Settings'!$B$75:$B$96,0))),0),0)) -> 0 | AA10: =IF(B10="","",ROUND(AN10/12,0)) -> 7345 | AD10: =IF(B10="","",U10+W10+X10+Z10+IF(AB10<>"",N(AB10),AA10)+N(AC10)) -> 7345 | AE10: =IF(B10="","",Q10-AD10) -> 112655 | AF10: =IF(B10="","",ROUND(T10*'Rates & Settings'!$C$10,0)-AG10) -> 0 | AG10: =IF(B10="","",IF(H10="Yes",ROUND(MIN(T10,'Rates & Settings'!$C$8)*'Rates & Settings'!$C$11,0),0)) -> 0 | AH10: =IF(B10="","",ROUND(MIN(T10,'Rates & Settings'!$C$8)*'Rates & Settings'!$C$12,0)) -> 0 | AI10: =IF(B10="","",ROUND(T10*'Rates & Settings'!$C$13,0)) -> 0 | AJ10: =IF(B10="","",IF(V10="Yes",ROUNDUP(Q10*'Rates & Settings'!$C$16,0),0)) -> 0 | AK10: =IF(B10="","",IFERROR(IF(Z10=0,0,IF(INDEX('Rates & Settings'!$C$75:$C$96,MATCH(E10,'Rates & Settings'!$B$75:$B$96,0))="Percent",MIN(Z10*INDEX('Rates & Settings'!$E$75:$E$96,MATCH(E10,'Rates & Settings'!$B$75:$B$96,0)),INDEX('Rates & Settings'!$G$75:$G$96,MATCH(E10,'Rates & Settings'!$B$75:$B$96,0))),INDEX('Rates & Settings'!$E$75:$E$96,MATCH(E10,'Rates & Settings'!$B$75:$B$96,0)))),0)) -> 0 | AL10: =IF(B10="","",Q10+AF10+AG10+AH10+AI10+AJ10+AK10) -> 120000 | AM10: =IF(B10="","",MAX(0,P10*12-'Rates & Settings'!$C$18)) -> 1365000 | AN10: =IF(B10="","",IF(AM10<='Rates & Settings'!$C$19,0,MIN(SUMPRODUCT(--(AM10>'Rates & Settings'!$B$24:$B$30),AM10-'Rates & Settings'!$B$24:$B$30,'Rates & Settings'!$D$24:$D$30),AM10-'Rates & Settings'!$C$19))*(1+'Rates & Settings'!$C$20)) -> 88140
P11: =IF(B11="","",SUM(J11:O11)) | Q11: =IF(B11="","",ROUND(P11*N(I11)/'Rates & Settings'!$C$7,0)) | R11: =IF(B11="","",ROUND((N(J11)+N(K11))*N(I11)/'Rates & Settings'!$C$7,0)) | S11: =IF(B11="","",IF('Rates & Settings'!$C$14="Yes",MAX(R11,ROUND(Q11*0.5,0)),R11)) | T11: =IF(B11="","",IF(F11="Yes",IF(G11="Yes",MIN(S11,'Rates & Settings'!$C$8),S11),0)) | U11: =IF(B11="","",ROUND(T11*'Rates & Settings'!$C$9,0)) | V11: =IF(B11="","",IF(P11<='Rates & Settings'!$C$17,"Yes","No")) | W11: =IF(B11="","",IF(V11="Yes",ROUNDUP(Q11*'Rates & Settings'!$C$15,0),0)) | X11: =IF(B11="","",IF(Y11<>"",N(Y11),IF(MONTH('Rates & Settings'!$C$6)=2,SUMIFS('Rates & Settings'!$F$35:$F$70,'Rates & Settings'!$B$35:$B$70,E11,'Rates & Settings'!$C$35:$C$70,"<="&Q11,'Rates & Settings'!$D$35:$D$70,">="&Q11),SUMIFS('Rates & Settings'!$E$35:$E$70,'Rates & Settings'!$B$35:$B$70,E11,'Rates & Settings'!$C$35:$C$70,"<="&Q11,'Rates & Settings'!$D$35:$D$70,">="&Q11)))) | Z11: =IF(B11="","",IFERROR(IF(OR(INDEX('Rates & Settings'!$H$75:$H$96,MATCH(E11,'Rates & Settings'!$B$75:$B$96,0))="All",ISNUMBER(SEARCH(","&MONTH('Rates & Settings'!$C$6)&",",","&INDEX('Rates & Settings'!$H$75:$H$96,MATCH(E11,'Rates & Settings'!$B$75:$B$96,0))&","))),IF(INDEX('Rates & Settings'!$C$75:$C$96,MATCH(E11,'Rates & Settings'!$B$75:$B$96,0))="Percent",MIN(ROUND(Q11*INDEX('Rates & Settings'!$D$75:$D$96,MATCH(E11,'Rates & Settings'!$B$75:$B$96,0)),0),INDEX('Rates & Settings'!$F$75:$F$96,MATCH(E11,'Rates & Settings'!$B$75:$B$96,0))),INDEX('Rates & Settings'!$D$75:$D$96,MATCH(E11,'Rates & Settings'!$B$75:$B$96,0))),0),0)) | AA11: =IF(B11="","",ROUND(AN11/12,0)) | AD11: =IF(B11="","",U11+W11+X11+Z11+IF(AB11<>"",N(AB11),AA11)+N(AC11)) | AE11: =IF(B11="","",Q11-AD11) | AF11: =IF(B11="","",ROUND(T11*'Rates & Settings'!$C$10,0)-AG11) | AG11: =IF(B11="","",IF(H11="Yes",ROUND(MIN(T11,'Rates & Settings'!$C$8)*'Rates & Settings'!$C$11,0),0)) | AH11: =IF(B11="","",ROUND(MIN(T11,'Rates & Settings'!$C$8)*'Rates & Settings'!$C$12,0)) | AI11: =IF(B11="","",ROUND(T11*'Rates & Settings'!$C$13,0)) | AJ11: =IF(B11="","",IF(V11="Yes",ROUNDUP(Q11*'Rates & Settings'!$C$16,0),0)) | AK11: =IF(B11="","",IFERROR(IF(Z11=0,0,IF(INDEX('Rates & Settings'!$C$75:$C$96,MATCH(E11,'Rates & Settings'!$B$75:$B$96,0))="Percent",MIN(Z11*INDEX('Rates & Settings'!$E$75:$E$96,MATCH(E11,'Rates & Settings'!$B$75:$B$96,0)),INDEX('Rates & Settings'!$G$75:$G$96,MATCH(E11,'Rates & Settings'!$B$75:$B$96,0))),INDEX('Rates & Settings'!$E$75:$E$96,MATCH(E11,'Rates & Settings'!$B$75:$B$96,0)))),0)) | AL11: =IF(B11="","",Q11+AF11+AG11+AH11+AI11+AJ11+AK11) | AM11: =IF(B11="","",MAX(0,P11*12-'Rates & Settings'!$C$18)) | AN11: =IF(B11="","",IF(AM11<='Rates & Settings'!$C$19,0,MIN(SUMPRODUCT(--(AM11>'Rates & Settings'!$B$24:$B$30),AM11-'Rates & Settings'!$B$24:$B$30,'Rates & Settings'!$D$24:$D$30),AM11-'Rates & Settings'!$C$19))*(1+'Rates & Settings'!$C$20))
P12: =IF(B12="","",SUM(J12:O12)) | Q12: =IF(B12="","",ROUND(P12*N(I12)/'Rates & Settings'!$C$7,0)) | R12: =IF(B12="","",ROUND((N(J12)+N(K12))*N(I12)/'Rates & Settings'!$C$7,0)) | S12: =IF(B12="","",IF('Rates & Settings'!$C$14="Yes",MAX(R12,ROUND(Q12*0.5,0)),R12)) | T12: =IF(B12="","",IF(F12="Yes",IF(G12="Yes",MIN(S12,'Rates & Settings'!$C$8),S12),0)) | U12: =IF(B12="","",ROUND(T12*'Rates & Settings'!$C$9,0)) | V12: =IF(B12="","",IF(P12<='Rates & Settings'!$C$17,"Yes","No")) | W12: =IF(B12="","",IF(V12="Yes",ROUNDUP(Q12*'Rates & Settings'!$C$15,0),0)) | X12: =IF(B12="","",IF(Y12<>"",N(Y12),IF(MONTH('Rates & Settings'!$C$6)=2,SUMIFS('Rates & Settings'!$F$35:$F$70,'Rates & Settings'!$B$35:$B$70,E12,'Rates & Settings'!$C$35:$C$70,"<="&Q12,'Rates & Settings'!$D$35:$D$70,">="&Q12),SUMIFS('Rates & Settings'!$E$35:$E$70,'Rates & Settings'!$B$35:$B$70,E12,'Rates & Settings'!$C$35:$C$70,"<="&Q12,'Rates & Settings'!$D$35:$D$70,">="&Q12)))) | Z12: =IF(B12="","",IFERROR(IF(OR(INDEX('Rates & Settings'!$H$75:$H$96,MATCH(E12,'Rates & Settings'!$B$75:$B$96,0))="All",ISNUMBER(SEARCH(","&MONTH('Rates & Settings'!$C$6)&",",","&INDEX('Rates & Settings'!$H$75:$H$96,MATCH(E12,'Rates & Settings'!$B$75:$B$96,0))&","))),IF(INDEX('Rates & Settings'!$C$75:$C$96,MATCH(E12,'Rates & Settings'!$B$75:$B$96,0))="Percent",MIN(ROUND(Q12*INDEX('Rates & Settings'!$D$75:$D$96,MATCH(E12,'Rates & Settings'!$B$75:$B$96,0)),0),INDEX('Rates & Settings'!$F$75:$F$96,MATCH(E12,'Rates & Settings'!$B$75:$B$96,0))),INDEX('Rates & Settings'!$D$75:$D$96,MATCH(E12,'Rates & Settings'!$B$75:$B$96,0))),0),0)) | AA12: =IF(B12="","",ROUND(AN12/12,0)) | AD12: =IF(B12="","",U12+W12+X12+Z12+IF(AB12<>"",N(AB12),AA12)+N(AC12)) | AE12: =IF(B12="","",Q12-AD12) | AF12: =IF(B12="","",ROUND(T12*'Rates & Settings'!$C$10,0)-AG12) | AG12: =IF(B12="","",IF(H12="Yes",ROUND(MIN(T12,'Rates & Settings'!$C$8)*'Rates & Settings'!$C$11,0),0)) | AH12: =IF(B12="","",ROUND(MIN(T12,'Rates & Settings'!$C$8)*'Rates & Settings'!$C$12,0)) | AI12: =IF(B12="","",ROUND(T12*'Rates & Settings'!$C$13,0)) | AJ12: =IF(B12="","",IF(V12="Yes",ROUNDUP(Q12*'Rates & Settings'!$C$16,0),0)) | AK12: =IF(B12="","",IFERROR(IF(Z12=0,0,IF(INDEX('Rates & Settings'!$C$75:$C$96,MATCH(E12,'Rates & Settings'!$B$75:$B$96,0))="Percent",MIN(Z12*INDEX('Rates & Settings'!$E$75:$E$96,MATCH(E12,'Rates & Settings'!$B$75:$B$96,0)),INDEX('Rates & Settings'!$G$75:$G$96,MATCH(E12,'Rates & Settings'!$B$75:$B$96,0))),INDEX('Rates & Settings'!$E$75:$E$96,MATCH(E12,'Rates & Settings'!$B$75:$B$96,0)))),0)) | AL12: =IF(B12="","",Q12+AF12+AG12+AH12+AI12+AJ12+AK12) | AM12: =IF(B12="","",MAX(0,P12*12-'Rates & Settings'!$C$18)) | AN12: =IF(B12="","",IF(AM12<='Rates & Settings'!$C$19,0,MIN(SUMPRODUCT(--(AM12>'Rates & Settings'!$B$24:$B$30),AM12-'Rates & Settings'!$B$24:$B$30,'Rates & Settings'!$D$24:$D$30),AM12-'Rates & Settings'!$C$19))*(1+'Rates & Settings'!$C$20))
P13: =IF(B13="","",SUM(J13:O13)) | Q13: =IF(B13="","",ROUND(P13*N(I13)/'Rates & Settings'!$C$7,0)) | R13: =IF(B13="","",ROUND((N(J13)+N(K13))*N(I13)/'Rates & Settings'!$C$7,0)) | S13: =IF(B13="","",IF('Rates & Settings'!$C$14="Yes",MAX(R13,ROUND(Q13*0.5,0)),R13)) | T13: =IF(B13="","",IF(F13="Yes",IF(G13="Yes",MIN(S13,'Rates & Settings'!$C$8),S13),0)) | U13: =IF(B13="","",ROUND(T13*'Rates & Settings'!$C$9,0)) | V13: =IF(B13="","",IF(P13<='Rates & Settings'!$C$17,"Yes","No")) | W13: =IF(B13="","",IF(V13="Yes",ROUNDUP(Q13*'Rates & Settings'!$C$15,0),0)) | X13: =IF(B13="","",IF(Y13<>"",N(Y13),IF(MONTH('Rates & Settings'!$C$6)=2,SUMIFS('Rates & Settings'!$F$35:$F$70,'Rates & Settings'!$B$35:$B$70,E13,'Rates & Settings'!$C$35:$C$70,"<="&Q13,'Rates & Settings'!$D$35:$D$70,">="&Q13),SUMIFS('Rates & Settings'!$E$35:$E$70,'Rates & Settings'!$B$35:$B$70,E13,'Rates & Settings'!$C$35:$C$70,"<="&Q13,'Rates & Settings'!$D$35:$D$70,">="&Q13)))) | Z13: =IF(B13="","",IFERROR(IF(OR(INDEX('Rates & Settings'!$H$75:$H$96,MATCH(E13,'Rates & Settings'!$B$75:$B$96,0))="All",ISNUMBER(SEARCH(","&MONTH('Rates & Settings'!$C$6)&",",","&INDEX('Rates & Settings'!$H$75:$H$96,MATCH(E13,'Rates & Settings'!$B$75:$B$96,0))&","))),IF(INDEX('Rates & Settings'!$C$75:$C$96,MATCH(E13,'Rates & Settings'!$B$75:$B$96,0))="Percent",MIN(ROUND(Q13*INDEX('Rates & Settings'!$D$75:$D$96,MATCH(E13,'Rates & Settings'!$B$75:$B$96,0)),0),INDEX('Rates & Settings'!$F$75:$F$96,MATCH(E13,'Rates & Settings'!$B$75:$B$96,0))),INDEX('Rates & Settings'!$D$75:$D$96,MATCH(E13,'Rates & Settings'!$B$75:$B$96,0))),0),0)) | AA13: =IF(B13="","",ROUND(AN13/12,0)) | AD13: =IF(B13="","",U13+W13+X13+Z13+IF(AB13<>"",N(AB13),AA13)+N(AC13)) | AE13: =IF(B13="","",Q13-AD13) | AF13: =IF(B13="","",ROUND(T13*'Rates & Settings'!$C$10,0)-AG13) | AG13: =IF(B13="","",IF(H13="Yes",ROUND(MIN(T13,'Rates & Settings'!$C$8)*'Rates & Settings'!$C$11,0),0)) | AH13: =IF(B13="","",ROUND(MIN(T13,'Rates & Settings'!$C$8)*'Rates & Settings'!$C$12,0)) | AI13: =IF(B13="","",ROUND(T13*'Rates & Settings'!$C$13,0)) | AJ13: =IF(B13="","",IF(V13="Yes",ROUNDUP(Q13*'Rates & Settings'!$C$16,0),0)) | AK13: =IF(B13="","",IFERROR(IF(Z13=0,0,IF(INDEX('Rates & Settings'!$C$75:$C$96,MATCH(E13,'Rates & Settings'!$B$75:$B$96,0))="Percent",MIN(Z13*INDEX('Rates & Settings'!$E$75:$E$96,MATCH(E13,'Rates & Settings'!$B$75:$B$96,0)),INDEX('Rates & Settings'!$G$75:$G$96,MATCH(E13,'Rates & Settings'!$B$75:$B$96,0))),INDEX('Rates & Settings'!$E$75:$E$96,MATCH(E13,'Rates & Settings'!$B$75:$B$96,0)))),0)) | AL13: =IF(B13="","",Q13+AF13+AG13+AH13+AI13+AJ13+AK13) | AM13: =IF(B13="","",MAX(0,P13*12-'Rates & Settings'!$C$18)) | AN13: =IF(B13="","",IF(AM13<='Rates & Settings'!$C$19,0,MIN(SUMPRODUCT(--(AM13>'Rates & Settings'!$B$24:$B$30),AM13-'Rates & Settings'!$B$24:$B$30,'Rates & Settings'!$D$24:$D$30),AM13-'Rates & Settings'!$C$19))*(1+'Rates & Settings'!$C$20))
P14: =IF(B14="","",SUM(J14:O14)) | Q14: =IF(B14="","",ROUND(P14*N(I14)/'Rates & Settings'!$C$7,0)) | R14: =IF(B14="","",ROUND((N(J14)+N(K14))*N(I14)/'Rates & Settings'!$C$7,0)) | S14: =IF(B14="","",IF('Rates & Settings'!$C$14="Yes",MAX(R14,ROUND(Q14*0.5,0)),R14)) | T14: =IF(B14="","",IF(F14="Yes",IF(G14="Yes",MIN(S14,'Rates & Settings'!$C$8),S14),0)) | U14: =IF(B14="","",ROUND(T14*'Rates & Settings'!$C$9,0)) | V14: =IF(B14="","",IF(P14<='Rates & Settings'!$C$17,"Yes","No")) | W14: =IF(B14="","",IF(V14="Yes",ROUNDUP(Q14*'Rates & Settings'!$C$15,0),0)) | X14: =IF(B14="","",IF(Y14<>"",N(Y14),IF(MONTH('Rates & Settings'!$C$6)=2,SUMIFS('Rates & Settings'!$F$35:$F$70,'Rates & Settings'!$B$35:$B$70,E14,'Rates & Settings'!$C$35:$C$70,"<="&Q14,'Rates & Settings'!$D$35:$D$70,">="&Q14),SUMIFS('Rates & Settings'!$E$35:$E$70,'Rates & Settings'!$B$35:$B$70,E14,'Rates & Settings'!$C$35:$C$70,"<="&Q14,'Rates & Settings'!$D$35:$D$70,">="&Q14)))) | Z14: =IF(B14="","",IFERROR(IF(OR(INDEX('Rates & Settings'!$H$75:$H$96,MATCH(E14,'Rates & Settings'!$B$75:$B$96,0))="All",ISNUMBER(SEARCH(","&MONTH('Rates & Settings'!$C$6)&",",","&INDEX('Rates & Settings'!$H$75:$H$96,MATCH(E14,'Rates & Settings'!$B$75:$B$96,0))&","))),IF(INDEX('Rates & Settings'!$C$75:$C$96,MATCH(E14,'Rates & Settings'!$B$75:$B$96,0))="Percent",MIN(ROUND(Q14*INDEX('Rates & Settings'!$D$75:$D$96,MATCH(E14,'Rates & Settings'!$B$75:$B$96,0)),0),INDEX('Rates & Settings'!$F$75:$F$96,MATCH(E14,'Rates & Settings'!$B$75:$B$96,0))),INDEX('Rates & Settings'!$D$75:$D$96,MATCH(E14,'Rates & Settings'!$B$75:$B$96,0))),0),0)) | AA14: =IF(B14="","",ROUND(AN14/12,0)) | AD14: =IF(B14="","",U14+W14+X14+Z14+IF(AB14<>"",N(AB14),AA14)+N(AC14)) | AE14: =IF(B14="","",Q14-AD14) | AF14: =IF(B14="","",ROUND(T14*'Rates & Settings'!$C$10,0)-AG14) | AG14: =IF(B14="","",IF(H14="Yes",ROUND(MIN(T14,'Rates & Settings'!$C$8)*'Rates & Settings'!$C$11,0),0)) | AH14: =IF(B14="","",ROUND(MIN(T14,'Rates & Settings'!$C$8)*'Rates & Settings'!$C$12,0)) | AI14: =IF(B14="","",ROUND(T14*'Rates & Settings'!$C$13,0)) | AJ14: =IF(B14="","",IF(V14="Yes",ROUNDUP(Q14*'Rates & Settings'!$C$16,0),0)) | AK14: =IF(B14="","",IFERROR(IF(Z14=0,0,IF(INDEX('Rates & Settings'!$C$75:$C$96,MATCH(E14,'Rates & Settings'!$B$75:$B$96,0))="Percent",MIN(Z14*INDEX('Rates & Settings'!$E$75:$E$96,MATCH(E14,'Rates & Settings'!$B$75:$B$96,0)),INDEX('Rates & Settings'!$G$75:$G$96,MATCH(E14,'Rates & Settings'!$B$75:$B$96,0))),INDEX('Rates & Settings'!$E$75:$E$96,MATCH(E14,'Rates & Settings'!$B$75:$B$96,0)))),0)) | AL14: =IF(B14="","",Q14+AF14+AG14+AH14+AI14+AJ14+AK14) | AM14: =IF(B14="","",MAX(0,P14*12-'Rates & Settings'!$C$18)) | AN14: =IF(B14="","",IF(AM14<='Rates & Settings'!$C$19,0,MIN(SUMPRODUCT(--(AM14>'Rates & Settings'!$B$24:$B$30),AM14-'Rates & Settings'!$B$24:$B$30,'Rates & Settings'!$D$24:$D$30),AM14-'Rates & Settings'!$C$19))*(1+'Rates & Settings'!$C$20))
P15: =IF(B15="","",SUM(J15:O15)) | Q15: =IF(B15="","",ROUND(P15*N(I15)/'Rates & Settings'!$C$7,0)) | R15: =IF(B15="","",ROUND((N(J15)+N(K15))*N(I15)/'Rates & Settings'!$C$7,0)) | S15: =IF(B15="","",IF('Rates & Settings'!$C$14="Yes",MAX(R15,ROUND(Q15*0.5,0)),R15)) | T15: =IF(B15="","",IF(F15="Yes",IF(G15="Yes",MIN(S15,'Rates & Settings'!$C$8),S15),0)) | U15: =IF(B15="","",ROUND(T15*'Rates & Settings'!$C$9,0)) | V15: =IF(B15="","",IF(P15<='Rates & Settings'!$C$17,"Yes","No")) | W15: =IF(B15="","",IF(V15="Yes",ROUNDUP(Q15*'Rates & Settings'!$C$15,0),0)) | X15: =IF(B15="","",IF(Y15<>"",N(Y15),IF(MONTH('Rates & Settings'!$C$6)=2,SUMIFS('Rates & Settings'!$F$35:$F$70,'Rates & Settings'!$B$35:$B$70,E15,'Rates & Settings'!$C$35:$C$70,"<="&Q15,'Rates & Settings'!$D$35:$D$70,">="&Q15),SUMIFS('Rates & Settings'!$E$35:$E$70,'Rates & Settings'!$B$35:$B$70,E15,'Rates & Settings'!$C$35:$C$70,"<="&Q15,'Rates & Settings'!$D$35:$D$70,">="&Q15)))) | Z15: =IF(B15="","",IFERROR(IF(OR(INDEX('Rates & Settings'!$H$75:$H$96,MATCH(E15,'Rates & Settings'!$B$75:$B$96,0))="All",ISNUMBER(SEARCH(","&MONTH('Rates & Settings'!$C$6)&",",","&INDEX('Rates & Settings'!$H$75:$H$96,MATCH(E15,'Rates & Settings'!$B$75:$B$96,0))&","))),IF(INDEX('Rates & Settings'!$C$75:$C$96,MATCH(E15,'Rates & Settings'!$B$75:$B$96,0))="Percent",MIN(ROUND(Q15*INDEX('Rates & Settings'!$D$75:$D$96,MATCH(E15,'Rates & Settings'!$B$75:$B$96,0)),0),INDEX('Rates & Settings'!$F$75:$F$96,MATCH(E15,'Rates & Settings'!$B$75:$B$96,0))),INDEX('Rates & Settings'!$D$75:$D$96,MATCH(E15,'Rates & Settings'!$B$75:$B$96,0))),0),0)) | AA15: =IF(B15="","",ROUND(AN15/12,0)) | AD15: =IF(B15="","",U15+W15+X15+Z15+IF(AB15<>"",N(AB15),AA15)+N(AC15)) | AE15: =IF(B15="","",Q15-AD15) | AF15: =IF(B15="","",ROUND(T15*'Rates & Settings'!$C$10,0)-AG15) | AG15: =IF(B15="","",IF(H15="Yes",ROUND(MIN(T15,'Rates & Settings'!$C$8)*'Rates & Settings'!$C$11,0),0)) | AH15: =IF(B15="","",ROUND(MIN(T15,'Rates & Settings'!$C$8)*'Rates & Settings'!$C$12,0)) | AI15: =IF(B15="","",ROUND(T15*'Rates & Settings'!$C$13,0)) | AJ15: =IF(B15="","",IF(V15="Yes",ROUNDUP(Q15*'Rates & Settings'!$C$16,0),0)) | AK15: =IF(B15="","",IFERROR(IF(Z15=0,0,IF(INDEX('Rates & Settings'!$C$75:$C$96,MATCH(E15,'Rates & Settings'!$B$75:$B$96,0))="Percent",MIN(Z15*INDEX('Rates & Settings'!$E$75:$E$96,MATCH(E15,'Rates & Settings'!$B$75:$B$96,0)),INDEX('Rates & Settings'!$G$75:$G$96,MATCH(E15,'Rates & Settings'!$B$75:$B$96,0))),INDEX('Rates & Settings'!$E$75:$E$96,MATCH(E15,'Rates & Settings'!$B$75:$B$96,0)))),0)) | AL15: =IF(B15="","",Q15+AF15+AG15+AH15+AI15+AJ15+AK15) | AM15: =IF(B15="","",MAX(0,P15*12-'Rates & Settings'!$C$18)) | AN15: =IF(B15="","",IF(AM15<='Rates & Settings'!$C$19,0,MIN(SUMPRODUCT(--(AM15>'Rates & Settings'!$B$24:$B$30),AM15-'Rates & Settings'!$B$24:$B$30,'Rates & Settings'!$D$24:$D$30),AM15-'Rates & Settings'!$C$19))*(1+'Rates & Settings'!$C$20))
P16: =IF(B16="","",SUM(J16:O16)) | Q16: =IF(B16="","",ROUND(P16*N(I16)/'Rates & Settings'!$C$7,0)) | R16: =IF(B16="","",ROUND((N(J16)+N(K16))*N(I16)/'Rates & Settings'!$C$7,0)) | S16: =IF(B16="","",IF('Rates & Settings'!$C$14="Yes",MAX(R16,ROUND(Q16*0.5,0)),R16)) | T16: =IF(B16="","",IF(F16="Yes",IF(G16="Yes",MIN(S16,'Rates & Settings'!$C$8),S16),0)) | U16: =IF(B16="","",ROUND(T16*'Rates & Settings'!$C$9,0)) | V16: =IF(B16="","",IF(P16<='Rates & Settings'!$C$17,"Yes","No")) | W16: =IF(B16="","",IF(V16="Yes",ROUNDUP(Q16*'Rates & Settings'!$C$15,0),0)) | X16: =IF(B16="","",IF(Y16<>"",N(Y16),IF(MONTH('Rates & Settings'!$C$6)=2,SUMIFS('Rates & Settings'!$F$35:$F$70,'Rates & Settings'!$B$35:$B$70,E16,'Rates & Settings'!$C$35:$C$70,"<="&Q16,'Rates & Settings'!$D$35:$D$70,">="&Q16),SUMIFS('Rates & Settings'!$E$35:$E$70,'Rates & Settings'!$B$35:$B$70,E16,'Rates & Settings'!$C$35:$C$70,"<="&Q16,'Rates & Settings'!$D$35:$D$70,">="&Q16)))) | Z16: =IF(B16="","",IFERROR(IF(OR(INDEX('Rates & Settings'!$H$75:$H$96,MATCH(E16,'Rates & Settings'!$B$75:$B$96,0))="All",ISNUMBER(SEARCH(","&MONTH('Rates & Settings'!$C$6)&",",","&INDEX('Rates & Settings'!$H$75:$H$96,MATCH(E16,'Rates & Settings'!$B$75:$B$96,0))&","))),IF(INDEX('Rates & Settings'!$C$75:$C$96,MATCH(E16,'Rates & Settings'!$B$75:$B$96,0))="Percent",MIN(ROUND(Q16*INDEX('Rates & Settings'!$D$75:$D$96,MATCH(E16,'Rates & Settings'!$B$75:$B$96,0)),0),INDEX('Rates & Settings'!$F$75:$F$96,MATCH(E16,'Rates & Settings'!$B$75:$B$96,0))),INDEX('Rates & Settings'!$D$75:$D$96,MATCH(E16,'Rates & Settings'!$B$75:$B$96,0))),0),0)) | AA16: =IF(B16="","",ROUND(AN16/12,0)) | AD16: =IF(B16="","",U16+W16+X16+Z16+IF(AB16<>"",N(AB16),AA16)+N(AC16)) | AE16: =IF(B16="","",Q16-AD16) | AF16: =IF(B16="","",ROUND(T16*'Rates & Settings'!$C$10,0)-AG16) | AG16: =IF(B16="","",IF(H16="Yes",ROUND(MIN(T16,'Rates & Settings'!$C$8)*'Rates & Settings'!$C$11,0),0)) | AH16: =IF(B16="","",ROUND(MIN(T16,'Rates & Settings'!$C$8)*'Rates & Settings'!$C$12,0)) | AI16: =IF(B16="","",ROUND(T16*'Rates & Settings'!$C$13,0)) | AJ16: =IF(B16="","",IF(V16="Yes",ROUNDUP(Q16*'Rates & Settings'!$C$16,0),0)) | AK16: =IF(B16="","",IFERROR(IF(Z16=0,0,IF(INDEX('Rates & Settings'!$C$75:$C$96,MATCH(E16,'Rates & Settings'!$B$75:$B$96,0))="Percent",MIN(Z16*INDEX('Rates & Settings'!$E$75:$E$96,MATCH(E16,'Rates & Settings'!$B$75:$B$96,0)),INDEX('Rates & Settings'!$G$75:$G$96,MATCH(E16,'Rates & Settings'!$B$75:$B$96,0))),INDEX('Rates & Settings'!$E$75:$E$96,MATCH(E16,'Rates & Settings'!$B$75:$B$96,0)))),0)) | AL16: =IF(B16="","",Q16+AF16+AG16+AH16+AI16+AJ16+AK16) | AM16: =IF(B16="","",MAX(0,P16*12-'Rates & Settings'!$C$18)) | AN16: =IF(B16="","",IF(AM16<='Rates & Settings'!$C$19,0,MIN(SUMPRODUCT(--(AM16>'Rates & Settings'!$B$24:$B$30),AM16-'Rates & Settings'!$B$24:$B$30,'Rates & Settings'!$D$24:$D$30),AM16-'Rates & Settings'!$C$19))*(1+'Rates & Settings'!$C$20))
P17: =IF(B17="","",SUM(J17:O17)) | Q17: =IF(B17="","",ROUND(P17*N(I17)/'Rates & Settings'!$C$7,0)) | R17: =IF(B17="","",ROUND((N(J17)+N(K17))*N(I17)/'Rates & Settings'!$C$7,0)) | S17: =IF(B17="","",IF('Rates & Settings'!$C$14="Yes",MAX(R17,ROUND(Q17*0.5,0)),R17)) | T17: =IF(B17="","",IF(F17="Yes",IF(G17="Yes",MIN(S17,'Rates & Settings'!$C$8),S17),0)) | U17: =IF(B17="","",ROUND(T17*'Rates & Settings'!$C$9,0)) | V17: =IF(B17="","",IF(P17<='Rates & Settings'!$C$17,"Yes","No")) | W17: =IF(B17="","",IF(V17="Yes",ROUNDUP(Q17*'Rates & Settings'!$C$15,0),0)) | X17: =IF(B17="","",IF(Y17<>"",N(Y17),IF(MONTH('Rates & Settings'!$C$6)=2,SUMIFS('Rates & Settings'!$F$35:$F$70,'Rates & Settings'!$B$35:$B$70,E17,'Rates & Settings'!$C$35:$C$70,"<="&Q17,'Rates & Settings'!$D$35:$D$70,">="&Q17),SUMIFS('Rates & Settings'!$E$35:$E$70,'Rates & Settings'!$B$35:$B$70,E17,'Rates & Settings'!$C$35:$C$70,"<="&Q17,'Rates & Settings'!$D$35:$D$70,">="&Q17)))) | Z17: =IF(B17="","",IFERROR(IF(OR(INDEX('Rates & Settings'!$H$75:$H$96,MATCH(E17,'Rates & Settings'!$B$75:$B$96,0))="All",ISNUMBER(SEARCH(","&MONTH('Rates & Settings'!$C$6)&",",","&INDEX('Rates & Settings'!$H$75:$H$96,MATCH(E17,'Rates & Settings'!$B$75:$B$96,0))&","))),IF(INDEX('Rates & Settings'!$C$75:$C$96,MATCH(E17,'Rates & Settings'!$B$75:$B$96,0))="Percent",MIN(ROUND(Q17*INDEX('Rates & Settings'!$D$75:$D$96,MATCH(E17,'Rates & Settings'!$B$75:$B$96,0)),0),INDEX('Rates & Settings'!$F$75:$F$96,MATCH(E17,'Rates & Settings'!$B$75:$B$96,0))),INDEX('Rates & Settings'!$D$75:$D$96,MATCH(E17,'Rates & Settings'!$B$75:$B$96,0))),0),0)) | AA17: =IF(B17="","",ROUND(AN17/12,0)) | AD17: =IF(B17="","",U17+W17+X17+Z17+IF(AB17<>"",N(AB17),AA17)+N(AC17)) | AE17: =IF(B17="","",Q17-AD17) | AF17: =IF(B17="","",ROUND(T17*'Rates & Settings'!$C$10,0)-AG17) | AG17: =IF(B17="","",IF(H17="Yes",ROUND(MIN(T17,'Rates & Settings'!$C$8)*'Rates & Settings'!$C$11,0),0)) | AH17: =IF(B17="","",ROUND(MIN(T17,'Rates & Settings'!$C$8)*'Rates & Settings'!$C$12,0)) | AI17: =IF(B17="","",ROUND(T17*'Rates & Settings'!$C$13,0)) | AJ17: =IF(B17="","",IF(V17="Yes",ROUNDUP(Q17*'Rates & Settings'!$C$16,0),0)) | AK17: =IF(B17="","",IFERROR(IF(Z17=0,0,IF(INDEX('Rates & Settings'!$C$75:$C$96,MATCH(E17,'Rates & Settings'!$B$75:$B$96,0))="Percent",MIN(Z17*INDEX('Rates & Settings'!$E$75:$E$96,MATCH(E17,'Rates & Settings'!$B$75:$B$96,0)),INDEX('Rates & Settings'!$G$75:$G$96,MATCH(E17,'Rates & Settings'!$B$75:$B$96,0))),INDEX('Rates & Settings'!$E$75:$E$96,MATCH(E17,'Rates & Settings'!$B$75:$B$96,0)))),0)) | AL17: =IF(B17="","",Q17+AF17+AG17+AH17+AI17+AJ17+AK17) | AM17: =IF(B17="","",MAX(0,P17*12-'Rates & Settings'!$C$18)) | AN17: =IF(B17="","",IF(AM17<='Rates & Settings'!$C$19,0,MIN(SUMPRODUCT(--(AM17>'Rates & Settings'!$B$24:$B$30),AM17-'Rates & Settings'!$B$24:$B$30,'Rates & Settings'!$D$24:$D$30),AM17-'Rates & Settings'!$C$19))*(1+'Rates & Settings'!$C$20))
P18: =IF(B18="","",SUM(J18:O18)) | Q18: =IF(B18="","",ROUND(P18*N(I18)/'Rates & Settings'!$C$7,0)) | R18: =IF(B18="","",ROUND((N(J18)+N(K18))*N(I18)/'Rates & Settings'!$C$7,0)) | S18: =IF(B18="","",IF('Rates & Settings'!$C$14="Yes",MAX(R18,ROUND(Q18*0.5,0)),R18)) | T18: =IF(B18="","",IF(F18="Yes",IF(G18="Yes",MIN(S18,'Rates & Settings'!$C$8),S18),0)) | U18: =IF(B18="","",ROUND(T18*'Rates & Settings'!$C$9,0)) | V18: =IF(B18="","",IF(P18<='Rates & Settings'!$C$17,"Yes","No")) | W18: =IF(B18="","",IF(V18="Yes",ROUNDUP(Q18*'Rates & Settings'!$C$15,0),0)) | X18: =IF(B18="","",IF(Y18<>"",N(Y18),IF(MONTH('Rates & Settings'!$C$6)=2,SUMIFS('Rates & Settings'!$F$35:$F$70,'Rates & Settings'!$B$35:$B$70,E18,'Rates & Settings'!$C$35:$C$70,"<="&Q18,'Rates & Settings'!$D$35:$D$70,">="&Q18),SUMIFS('Rates & Settings'!$E$35:$E$70,'Rates & Settings'!$B$35:$B$70,E18,'Rates & Settings'!$C$35:$C$70,"<="&Q18,'Rates & Settings'!$D$35:$D$70,">="&Q18)))) | Z18: =IF(B18="","",IFERROR(IF(OR(INDEX('Rates & Settings'!$H$75:$H$96,MATCH(E18,'Rates & Settings'!$B$75:$B$96,0))="All",ISNUMBER(SEARCH(","&MONTH('Rates & Settings'!$C$6)&",",","&INDEX('Rates & Settings'!$H$75:$H$96,MATCH(E18,'Rates & Settings'!$B$75:$B$96,0))&","))),IF(INDEX('Rates & Settings'!$C$75:$C$96,MATCH(E18,'Rates & Settings'!$B$75:$B$96,0))="Percent",MIN(ROUND(Q18*INDEX('Rates & Settings'!$D$75:$D$96,MATCH(E18,'Rates & Settings'!$B$75:$B$96,0)),0),INDEX('Rates & Settings'!$F$75:$F$96,MATCH(E18,'Rates & Settings'!$B$75:$B$96,0))),INDEX('Rates & Settings'!$D$75:$D$96,MATCH(E18,'Rates & Settings'!$B$75:$B$96,0))),0),0)) | AA18: =IF(B18="","",ROUND(AN18/12,0)) | AD18: =IF(B18="","",U18+W18+X18+Z18+IF(AB18<>"",N(AB18),AA18)+N(AC18)) | AE18: =IF(B18="","",Q18-AD18) | AF18: =IF(B18="","",ROUND(T18*'Rates & Settings'!$C$10,0)-AG18) | AG18: =IF(B18="","",IF(H18="Yes",ROUND(MIN(T18,'Rates & Settings'!$C$8)*'Rates & Settings'!$C$11,0),0)) | AH18: =IF(B18="","",ROUND(MIN(T18,'Rates & Settings'!$C$8)*'Rates & Settings'!$C$12,0)) | AI18: =IF(B18="","",ROUND(T18*'Rates & Settings'!$C$13,0)) | AJ18: =IF(B18="","",IF(V18="Yes",ROUNDUP(Q18*'Rates & Settings'!$C$16,0),0)) | AK18: =IF(B18="","",IFERROR(IF(Z18=0,0,IF(INDEX('Rates & Settings'!$C$75:$C$96,MATCH(E18,'Rates & Settings'!$B$75:$B$96,0))="Percent",MIN(Z18*INDEX('Rates & Settings'!$E$75:$E$96,MATCH(E18,'Rates & Settings'!$B$75:$B$96,0)),INDEX('Rates & Settings'!$G$75:$G$96,MATCH(E18,'Rates & Settings'!$B$75:$B$96,0))),INDEX('Rates & Settings'!$E$75:$E$96,MATCH(E18,'Rates & Settings'!$B$75:$B$96,0)))),0)) | AL18: =IF(B18="","",Q18+AF18+AG18+AH18+AI18+AJ18+AK18) | AM18: =IF(B18="","",MAX(0,P18*12-'Rates & Settings'!$C$18)) | AN18: =IF(B18="","",IF(AM18<='Rates & Settings'!$C$19,0,MIN(SUMPRODUCT(--(AM18>'Rates & Settings'!$B$24:$B$30),AM18-'Rates & Settings'!$B$24:$B$30,'Rates & Settings'!$D$24:$D$30),AM18-'Rates & Settings'!$C$19))*(1+'Rates & Settings'!$C$20))
P19: =IF(B19="","",SUM(J19:O19)) | Q19: =IF(B19="","",ROUND(P19*N(I19)/'Rates & Settings'!$C$7,0)) | R19: =IF(B19="","",ROUND((N(J19)+N(K19))*N(I19)/'Rates & Settings'!$C$7,0)) | S19: =IF(B19="","",IF('Rates & Settings'!$C$14="Yes",MAX(R19,ROUND(Q19*0.5,0)),R19)) | T19: =IF(B19="","",IF(F19="Yes",IF(G19="Yes",MIN(S19,'Rates & Settings'!$C$8),S19),0)) | U19: =IF(B19="","",ROUND(T19*'Rates & Settings'!$C$9,0)) | V19: =IF(B19="","",IF(P19<='Rates & Settings'!$C$17,"Yes","No")) | W19: =IF(B19="","",IF(V19="Yes",ROUNDUP(Q19*'Rates & Settings'!$C$15,0),0)) | X19: =IF(B19="","",IF(Y19<>"",N(Y19),IF(MONTH('Rates & Settings'!$C$6)=2,SUMIFS('Rates & Settings'!$F$35:$F$70,'Rates & Settings'!$B$35:$B$70,E19,'Rates & Settings'!$C$35:$C$70,"<="&Q19,'Rates & Settings'!$D$35:$D$70,">="&Q19),SUMIFS('Rates & Settings'!$E$35:$E$70,'Rates & Settings'!$B$35:$B$70,E19,'Rates & Settings'!$C$35:$C$70,"<="&Q19,'Rates & Settings'!$D$35:$D$70,">="&Q19)))) | Z19: =IF(B19="","",IFERROR(IF(OR(INDEX('Rates & Settings'!$H$75:$H$96,MATCH(E19,'Rates & Settings'!$B$75:$B$96,0))="All",ISNUMBER(SEARCH(","&MONTH('Rates & Settings'!$C$6)&",",","&INDEX('Rates & Settings'!$H$75:$H$96,MATCH(E19,'Rates & Settings'!$B$75:$B$96,0))&","))),IF(INDEX('Rates & Settings'!$C$75:$C$96,MATCH(E19,'Rates & Settings'!$B$75:$B$96,0))="Percent",MIN(ROUND(Q19*INDEX('Rates & Settings'!$D$75:$D$96,MATCH(E19,'Rates & Settings'!$B$75:$B$96,0)),0),INDEX('Rates & Settings'!$F$75:$F$96,MATCH(E19,'Rates & Settings'!$B$75:$B$96,0))),INDEX('Rates & Settings'!$D$75:$D$96,MATCH(E19,'Rates & Settings'!$B$75:$B$96,0))),0),0)) | AA19: =IF(B19="","",ROUND(AN19/12,0)) | AD19: =IF(B19="","",U19+W19+X19+Z19+IF(AB19<>"",N(AB19),AA19)+N(AC19)) | AE19: =IF(B19="","",Q19-AD19) | AF19: =IF(B19="","",ROUND(T19*'Rates & Settings'!$C$10,0)-AG19) | AG19: =IF(B19="","",IF(H19="Yes",ROUND(MIN(T19,'Rates & Settings'!$C$8)*'Rates & Settings'!$C$11,0),0)) | AH19: =IF(B19="","",ROUND(MIN(T19,'Rates & Settings'!$C$8)*'Rates & Settings'!$C$12,0)) | AI19: =IF(B19="","",ROUND(T19*'Rates & Settings'!$C$13,0)) | AJ19: =IF(B19="","",IF(V19="Yes",ROUNDUP(Q19*'Rates & Settings'!$C$16,0),0)) | AK19: =IF(B19="","",IFERROR(IF(Z19=0,0,IF(INDEX('Rates & Settings'!$C$75:$C$96,MATCH(E19,'Rates & Settings'!$B$75:$B$96,0))="Percent",MIN(Z19*INDEX('Rates & Settings'!$E$75:$E$96,MATCH(E19,'Rates & Settings'!$B$75:$B$96,0)),INDEX('Rates & Settings'!$G$75:$G$96,MATCH(E19,'Rates & Settings'!$B$75:$B$96,0))),INDEX('Rates & Settings'!$E$75:$E$96,MATCH(E19,'Rates & Settings'!$B$75:$B$96,0)))),0)) | AL19: =IF(B19="","",Q19+AF19+AG19+AH19+AI19+AJ19+AK19) | AM19: =IF(B19="","",MAX(0,P19*12-'Rates & Settings'!$C$18)) | AN19: =IF(B19="","",IF(AM19<='Rates & Settings'!$C$19,0,MIN(SUMPRODUCT(--(AM19>'Rates & Settings'!$B$24:$B$30),AM19-'Rates & Settings'!$B$24:$B$30,'Rates & Settings'!$D$24:$D$30),AM19-'Rates & Settings'!$C$19))*(1+'Rates & Settings'!$C$20))
P20: =IF(B20="","",SUM(J20:O20)) | Q20: =IF(B20="","",ROUND(P20*N(I20)/'Rates & Settings'!$C$7,0)) | R20: =IF(B20="","",ROUND((N(J20)+N(K20))*N(I20)/'Rates & Settings'!$C$7,0)) | S20: =IF(B20="","",IF('Rates & Settings'!$C$14="Yes",MAX(R20,ROUND(Q20*0.5,0)),R20)) | T20: =IF(B20="","",IF(F20="Yes",IF(G20="Yes",MIN(S20,'Rates & Settings'!$C$8),S20),0)) | U20: =IF(B20="","",ROUND(T20*'Rates & Settings'!$C$9,0)) | V20: =IF(B20="","",IF(P20<='Rates & Settings'!$C$17,"Yes","No")) | W20: =IF(B20="","",IF(V20="Yes",ROUNDUP(Q20*'Rates & Settings'!$C$15,0),0)) | X20: =IF(B20="","",IF(Y20<>"",N(Y20),IF(MONTH('Rates & Settings'!$C$6)=2,SUMIFS('Rates & Settings'!$F$35:$F$70,'Rates & Settings'!$B$35:$B$70,E20,'Rates & Settings'!$C$35:$C$70,"<="&Q20,'Rates & Settings'!$D$35:$D$70,">="&Q20),SUMIFS('Rates & Settings'!$E$35:$E$70,'Rates & Settings'!$B$35:$B$70,E20,'Rates & Settings'!$C$35:$C$70,"<="&Q20,'Rates & Settings'!$D$35:$D$70,">="&Q20)))) | Z20: =IF(B20="","",IFERROR(IF(OR(INDEX('Rates & Settings'!$H$75:$H$96,MATCH(E20,'Rates & Settings'!$B$75:$B$96,0))="All",ISNUMBER(SEARCH(","&MONTH('Rates & Settings'!$C$6)&",",","&INDEX('Rates & Settings'!$H$75:$H$96,MATCH(E20,'Rates & Settings'!$B$75:$B$96,0))&","))),IF(INDEX('Rates & Settings'!$C$75:$C$96,MATCH(E20,'Rates & Settings'!$B$75:$B$96,0))="Percent",MIN(ROUND(Q20*INDEX('Rates & Settings'!$D$75:$D$96,MATCH(E20,'Rates & Settings'!$B$75:$B$96,0)),0),INDEX('Rates & Settings'!$F$75:$F$96,MATCH(E20,'Rates & Settings'!$B$75:$B$96,0))),INDEX('Rates & Settings'!$D$75:$D$96,MATCH(E20,'Rates & Settings'!$B$75:$B$96,0))),0),0)) | AA20: =IF(B20="","",ROUND(AN20/12,0)) | AD20: =IF(B20="","",U20+W20+X20+Z20+IF(AB20<>"",N(AB20),AA20)+N(AC20)) | AE20: =IF(B20="","",Q20-AD20) | AF20: =IF(B20="","",ROUND(T20*'Rates & Settings'!$C$10,0)-AG20) | AG20: =IF(B20="","",IF(H20="Yes",ROUND(MIN(T20,'Rates & Settings'!$C$8)*'Rates & Settings'!$C$11,0),0)) | AH20: =IF(B20="","",ROUND(MIN(T20,'Rates & Settings'!$C$8)*'Rates & Settings'!$C$12,0)) | AI20: =IF(B20="","",ROUND(T20*'Rates & Settings'!$C$13,0)) | AJ20: =IF(B20="","",IF(V20="Yes",ROUNDUP(Q20*'Rates & Settings'!$C$16,0),0)) | AK20: =IF(B20="","",IFERROR(IF(Z20=0,0,IF(INDEX('Rates & Settings'!$C$75:$C$96,MATCH(E20,'Rates & Settings'!$B$75:$B$96,0))="Percent",MIN(Z20*INDEX('Rates & Settings'!$E$75:$E$96,MATCH(E20,'Rates & Settings'!$B$75:$B$96,0)),INDEX('Rates & Settings'!$G$75:$G$96,MATCH(E20,'Rates & Settings'!$B$75:$B$96,0))),INDEX('Rates & Settings'!$E$75:$E$96,MATCH(E20,'Rates & Settings'!$B$75:$B$96,0)))),0)) | AL20: =IF(B20="","",Q20+AF20+AG20+AH20+AI20+AJ20+AK20) | AM20: =IF(B20="","",MAX(0,P20*12-'Rates & Settings'!$C$18)) | AN20: =IF(B20="","",IF(AM20<='Rates & Settings'!$C$19,0,MIN(SUMPRODUCT(--(AM20>'Rates & Settings'!$B$24:$B$30),AM20-'Rates & Settings'!$B$24:$B$30,'Rates & Settings'!$D$24:$D$30),AM20-'Rates & Settings'!$C$19))*(1+'Rates & Settings'!$C$20))
P21: =IF(B21="","",SUM(J21:O21)) | Q21: =IF(B21="","",ROUND(P21*N(I21)/'Rates & Settings'!$C$7,0)) | R21: =IF(B21="","",ROUND((N(J21)+N(K21))*N(I21)/'Rates & Settings'!$C$7,0)) | S21: =IF(B21="","",IF('Rates & Settings'!$C$14="Yes",MAX(R21,ROUND(Q21*0.5,0)),R21)) | T21: =IF(B21="","",IF(F21="Yes",IF(G21="Yes",MIN(S21,'Rates & Settings'!$C$8),S21),0)) | U21: =IF(B21="","",ROUND(T21*'Rates & Settings'!$C$9,0)) | V21: =IF(B21="","",IF(P21<='Rates & Settings'!$C$17,"Yes","No")) | W21: =IF(B21="","",IF(V21="Yes",ROUNDUP(Q21*'Rates & Settings'!$C$15,0),0)) | X21: =IF(B21="","",IF(Y21<>"",N(Y21),IF(MONTH('Rates & Settings'!$C$6)=2,SUMIFS('Rates & Settings'!$F$35:$F$70,'Rates & Settings'!$B$35:$B$70,E21,'Rates & Settings'!$C$35:$C$70,"<="&Q21,'Rates & Settings'!$D$35:$D$70,">="&Q21),SUMIFS('Rates & Settings'!$E$35:$E$70,'Rates & Settings'!$B$35:$B$70,E21,'Rates & Settings'!$C$35:$C$70,"<="&Q21,'Rates & Settings'!$D$35:$D$70,">="&Q21)))) | Z21: =IF(B21="","",IFERROR(IF(OR(INDEX('Rates & Settings'!$H$75:$H$96,MATCH(E21,'Rates & Settings'!$B$75:$B$96,0))="All",ISNUMBER(SEARCH(","&MONTH('Rates & Settings'!$C$6)&",",","&INDEX('Rates & Settings'!$H$75:$H$96,MATCH(E21,'Rates & Settings'!$B$75:$B$96,0))&","))),IF(INDEX('Rates & Settings'!$C$75:$C$96,MATCH(E21,'Rates & Settings'!$B$75:$B$96,0))="Percent",MIN(ROUND(Q21*INDEX('Rates & Settings'!$D$75:$D$96,MATCH(E21,'Rates & Settings'!$B$75:$B$96,0)),0),INDEX('Rates & Settings'!$F$75:$F$96,MATCH(E21,'Rates & Settings'!$B$75:$B$96,0))),INDEX('Rates & Settings'!$D$75:$D$96,MATCH(E21,'Rates & Settings'!$B$75:$B$96,0))),0),0)) | AA21: =IF(B21="","",ROUND(AN21/12,0)) | AD21: =IF(B21="","",U21+W21+X21+Z21+IF(AB21<>"",N(AB21),AA21)+N(AC21)) | AE21: =IF(B21="","",Q21-AD21) | AF21: =IF(B21="","",ROUND(T21*'Rates & Settings'!$C$10,0)-AG21) | AG21: =IF(B21="","",IF(H21="Yes",ROUND(MIN(T21,'Rates & Settings'!$C$8)*'Rates & Settings'!$C$11,0),0)) | AH21: =IF(B21="","",ROUND(MIN(T21,'Rates & Settings'!$C$8)*'Rates & Settings'!$C$12,0)) | AI21: =IF(B21="","",ROUND(T21*'Rates & Settings'!$C$13,0)) | AJ21: =IF(B21="","",IF(V21="Yes",ROUNDUP(Q21*'Rates & Settings'!$C$16,0),0)) | AK21: =IF(B21="","",IFERROR(IF(Z21=0,0,IF(INDEX('Rates & Settings'!$C$75:$C$96,MATCH(E21,'Rates & Settings'!$B$75:$B$96,0))="Percent",MIN(Z21*INDEX('Rates & Settings'!$E$75:$E$96,MATCH(E21,'Rates & Settings'!$B$75:$B$96,0)),INDEX('Rates & Settings'!$G$75:$G$96,MATCH(E21,'Rates & Settings'!$B$75:$B$96,0))),INDEX('Rates & Settings'!$E$75:$E$96,MATCH(E21,'Rates & Settings'!$B$75:$B$96,0)))),0)) | AL21: =IF(B21="","",Q21+AF21+AG21+AH21+AI21+AJ21+AK21) | AM21: =IF(B21="","",MAX(0,P21*12-'Rates & Settings'!$C$18)) | AN21: =IF(B21="","",IF(AM21<='Rates & Settings'!$C$19,0,MIN(SUMPRODUCT(--(AM21>'Rates & Settings'!$B$24:$B$30),AM21-'Rates & Settings'!$B$24:$B$30,'Rates & Settings'!$D$24:$D$30),AM21-'Rates & Settings'!$C$19))*(1+'Rates & Settings'!$C$20))
P22: =IF(B22="","",SUM(J22:O22)) | Q22: =IF(B22="","",ROUND(P22*N(I22)/'Rates & Settings'!$C$7,0)) | R22: =IF(B22="","",ROUND((N(J22)+N(K22))*N(I22)/'Rates & Settings'!$C$7,0)) | S22: =IF(B22="","",IF('Rates & Settings'!$C$14="Yes",MAX(R22,ROUND(Q22*0.5,0)),R22)) | T22: =IF(B22="","",IF(F22="Yes",IF(G22="Yes",MIN(S22,'Rates & Settings'!$C$8),S22),0)) | U22: =IF(B22="","",ROUND(T22*'Rates & Settings'!$C$9,0)) | V22: =IF(B22="","",IF(P22<='Rates & Settings'!$C$17,"Yes","No")) | W22: =IF(B22="","",IF(V22="Yes",ROUNDUP(Q22*'Rates & Settings'!$C$15,0),0)) | X22: =IF(B22="","",IF(Y22<>"",N(Y22),IF(MONTH('Rates & Settings'!$C$6)=2,SUMIFS('Rates & Settings'!$F$35:$F$70,'Rates & Settings'!$B$35:$B$70,E22,'Rates & Settings'!$C$35:$C$70,"<="&Q22,'Rates & Settings'!$D$35:$D$70,">="&Q22),SUMIFS('Rates & Settings'!$E$35:$E$70,'Rates & Settings'!$B$35:$B$70,E22,'Rates & Settings'!$C$35:$C$70,"<="&Q22,'Rates & Settings'!$D$35:$D$70,">="&Q22)))) | Z22: =IF(B22="","",IFERROR(IF(OR(INDEX('Rates & Settings'!$H$75:$H$96,MATCH(E22,'Rates & Settings'!$B$75:$B$96,0))="All",ISNUMBER(SEARCH(","&MONTH('Rates & Settings'!$C$6)&",",","&INDEX('Rates & Settings'!$H$75:$H$96,MATCH(E22,'Rates & Settings'!$B$75:$B$96,0))&","))),IF(INDEX('Rates & Settings'!$C$75:$C$96,MATCH(E22,'Rates & Settings'!$B$75:$B$96,0))="Percent",MIN(ROUND(Q22*INDEX('Rates & Settings'!$D$75:$D$96,MATCH(E22,'Rates & Settings'!$B$75:$B$96,0)),0),INDEX('Rates & Settings'!$F$75:$F$96,MATCH(E22,'Rates & Settings'!$B$75:$B$96,0))),INDEX('Rates & Settings'!$D$75:$D$96,MATCH(E22,'Rates & Settings'!$B$75:$B$96,0))),0),0)) | AA22: =IF(B22="","",ROUND(AN22/12,0)) | AD22: =IF(B22="","",U22+W22+X22+Z22+IF(AB22<>"",N(AB22),AA22)+N(AC22)) | AE22: =IF(B22="","",Q22-AD22) | AF22: =IF(B22="","",ROUND(T22*'Rates & Settings'!$C$10,0)-AG22) | AG22: =IF(B22="","",IF(H22="Yes",ROUND(MIN(T22,'Rates & Settings'!$C$8)*'Rates & Settings'!$C$11,0),0)) | AH22: =IF(B22="","",ROUND(MIN(T22,'Rates & Settings'!$C$8)*'Rates & Settings'!$C$12,0)) | AI22: =IF(B22="","",ROUND(T22*'Rates & Settings'!$C$13,0)) | AJ22: =IF(B22="","",IF(V22="Yes",ROUNDUP(Q22*'Rates & Settings'!$C$16,0),0)) | AK22: =IF(B22="","",IFERROR(IF(Z22=0,0,IF(INDEX('Rates & Settings'!$C$75:$C$96,MATCH(E22,'Rates & Settings'!$B$75:$B$96,0))="Percent",MIN(Z22*INDEX('Rates & Settings'!$E$75:$E$96,MATCH(E22,'Rates & Settings'!$B$75:$B$96,0)),INDEX('Rates & Settings'!$G$75:$G$96,MATCH(E22,'Rates & Settings'!$B$75:$B$96,0))),INDEX('Rates & Settings'!$E$75:$E$96,MATCH(E22,'Rates & Settings'!$B$75:$B$96,0)))),0)) | AL22: =IF(B22="","",Q22+AF22+AG22+AH22+AI22+AJ22+AK22) | AM22: =IF(B22="","",MAX(0,P22*12-'Rates & Settings'!$C$18)) | AN22: =IF(B22="","",IF(AM22<='Rates & Settings'!$C$19,0,MIN(SUMPRODUCT(--(AM22>'Rates & Settings'!$B$24:$B$30),AM22-'Rates & Settings'!$B$24:$B$30,'Rates & Settings'!$D$24:$D$30),AM22-'Rates & Settings'!$C$19))*(1+'Rates & Settings'!$C$20))
... P105: =IF(B105="","",SUM(J105:O105)) | Q105: =IF(B105="","",ROUND(P105*N(I105)/'Rates & Settings'!$C$7,0)) | R105: =IF(B105="","",ROUND((N(J105)+N(K105))*N(I105)/'Rates & Settings'!$C$7,0)) | S105: =IF(B105="","",IF('Rates & Settings'!$C$14="Yes",MAX(R105,ROUND(Q105*0.5,0)),R105)) | T105: =IF(B105="","",IF(F105="Yes",IF(G105="Yes",MIN(S105,'Rates & Settings'!$C$8),S105),0)) | U105: =IF(B105="","",ROUND(T105*'Rates & Settings'!$C$9,0)) | V105: =IF(B105="","",IF(P105<='Rates & Settings'!$C$17,"Yes","No")) | W105: =IF(B105="","",IF(V105="Yes",ROUNDUP(Q105*'Rates & Settings'!$C$15,0),0)) | X105: =IF(B105="","",IF(Y105<>"",N(Y105),IF(MONTH('Rates & Settings'!$C$6)=2,SUMIFS('Rates & Settings'!$F$35:$F$70,'Rates & Settings'!$B$35:$B$70,E105,'Rates & Settings'!$C$35:$C$70,"<="&Q105,'Rates & Settings'!$D$35:$D$70,">="&Q105),SUMIFS('Rates & Settings'!$E$35:$E$70,'Rates & Settings'!$B$35:$B$70,E105,'Rates & Settings'!$C$35:$C$70,"<="&Q105,'Rates & Settings'!$D$35:$D$70,">="&Q105)))) | Z105: =IF(B105="","",IFERROR(IF(OR(INDEX('Rates & Settings'!$H$75:$H$96,MATCH(E105,'Rates & Settings'!$B$75:$B$96,0))="All",ISNUMBER(SEARCH(","&MONTH('Rates & Settings'!$C$6)&",",","&INDEX('Rates & Settings'!$H$75:$H$96,MATCH(E105,'Rates & Settings'!$B$75:$B$96,0))&","))),IF(INDEX('Rates & Settings'!$C$75:$C$96,MATCH(E105,'Rates & Settings'!$B$75:$B$96,0))="Percent",MIN(ROUND(Q105*INDEX('Rates & Settings'!$D$75:$D$96,MATCH(E105,'Rates & Settings'!$B$75:$B$96,0)),0),INDEX('Rates & Settings'!$F$75:$F$96,MATCH(E105,'Rates & Settings'!$B$75:$B$96,0))),INDEX('Rates & Settings'!$D$75:$D$96,MATCH(E105,'Rates & Settings'!$B$75:$B$96,0))),0),0)) | AA105: =IF(B105="","",ROUND(AN105/12,0)) | AD105: =IF(B105="","",U105+W105+X105+Z105+IF(AB105<>"",N(AB105),AA105)+N(AC105)) | AE105: =IF(B105="","",Q105-AD105) | AF105: =IF(B105="","",ROUND(T105*'Rates & Settings'!$C$10,0)-AG105) | AG105: =IF(B105="","",IF(H105="Yes",ROUND(MIN(T105,'Rates & Settings'!$C$8)*'Rates & Settings'!$C$11,0),0)) | AH105: =IF(B105="","",ROUND(MIN(T105,'Rates & Settings'!$C$8)*'Rates & Settings'!$C$12,0)) | AI105: =IF(B105="","",ROUND(T105*'Rates & Settings'!$C$13,0)) | AJ105: =IF(B105="","",IF(V105="Yes",ROUNDUP(Q105*'Rates & Settings'!$C$16,0),0)) | AK105: =IF(B105="","",IFERROR(IF(Z105=0,0,IF(INDEX('Rates & Settings'!$C$75:$C$96,MATCH(E105,'Rates & Settings'!$B$75:$B$96,0))="Percent",MIN(Z105*INDEX('Rates & Settings'!$E$75:$E$96,MATCH(E105,'Rates & Settings'!$B$75:$B$96,0)),INDEX('Rates & Settings'!$G$75:$G$96,MATCH(E105,'Rates & Settings'!$B$75:$B$96,0))),INDEX('Rates & Settings'!$E$75:$E$96,MATCH(E105,'Rates & Settings'!$B$75:$B$96,0)))),0)) | AL105: =IF(B105="","",Q105+AF105+AG105+AH105+AI105+AJ105+AK105) | AM105: =IF(B105="","",MAX(0,P105*12-'Rates & Settings'!$C$18)) | AN105: =IF(B105="","",IF(AM105<='Rates & Settings'!$C$19,0,MIN(SUMPRODUCT(--(AM105>'Rates & Settings'!$B$24:$B$30),AM105-'Rates & Settings'!$B$24:$B$30,'Rates & Settings'!$D$24:$D$30),AM105-'Rates & Settings'!$C$19))*(1+'Rates & Settings'!$C$20))
B106: Total | J106: =SUM(J6:J105) -> 152000 | K106: =SUM(K6:K105) -> 1000 | L106: =SUM(L6:L105) -> 75500 | M106: =SUM(M6:M105) -> 8000 | N106: =SUM(N6:N105) -> 61500 | O106: =SUM(O6:O105) -> 10000 | P106: =SUM(P6:P105) -> 308000 | Q106: =SUM(Q6:Q105) -> 302194 | ... U106: =SUM(U6:U105) -> 10452 | W106: =SUM(W6:W105) -> 285 | X106: =SUM(X6:X105) -> 530 | Y106: =SUM(Y6:Y105) -> 0 | Z106: =SUM(Z6:Z105) -> 35 | AA106: =SUM(AA6:AA105) -> 7345 | AB106: =SUM(AB6:AB105) -> 0 | AC106: =SUM(AC6:AC105) -> 0 | AD106: =SUM(AD6:AD105) -> 18647 | ... AN106: =SUM(AN6:AN105) -> 88140

Sheet Rates & Settings
B2: Rates & settings
B3: Pre-filled for Tax Year 2026-27. Blue cells can be changed.
B5: Company name | C5: Sample Technologies Pvt Ltd | K5: Haryana
B6: Payroll month (any date in the month) | C6: 46296 | K6: Delhi
B7: Days in payroll month | C7: =DAY(EOMONTH($C$6,0)) -> 31 | D7: Formula | K7: Uttar Pradesh
B8: PF wage ceiling (₹ per month) | C8: 25000 | D8: From 17 Sep 2026 (earlier ₹15,000) | K8: Rajasthan
B9: PF — employee rate | C9: 0.12 | K9: Maharashtra (Men)
B10: PF — employer total rate | C10: 0.12 | K10: Maharashtra (Women)
B11: EPS (pension) rate | C11: 0.0833 | D11: Part of the employer's 12% | K11: Karnataka
B12: EDLI rate | C12: 0.005 | K12: Tamil Nadu
B13: PF admin charges | C13: 0.005 | K13: Telangana
B14: Apply Labour Code 50% wage rule? | C14: Yes | D14: Yes / No | K14: Andhra Pradesh
B15: ESI — employee rate | C15: 0.0075 | K15: West Bengal
B16: ESI — employer rate | C16: 0.0325 | K16: Gujarat
B17: ESI wage limit (fixed gross per month) | C17: 21000 | D17: ₹25,000 for employees with disability | K17: Madhya Pradesh
B18: Standard deduction — new regime (₹ per year) | C18: 75000 | D18: For TDS estimate | K18: Odisha
B19: Rebate threshold — new regime (₹) | C19: 1200000 | D19: No tax up to this taxable income | K19: Kerala
B20: Health & education cess | C20: 0.04 | K20: Punjab
K21: Chandigarh
B22: Income tax slabs — new regime, Tax Year 2026-27 | K22: Chhattisgarh
B23: Taxable income above (₹) | C23: Rate | D23: Rate step | K23: Goa
B24: 0 | C24: 0 | D24: =C24 -> 0 | K24: Uttarakhand
B25: 400000 | C25: 0.05 | D25: =C25-C24 -> 0.05 | K25: Himachal Pradesh
B26: 800000 | C26: 0.1 | D26: =C26-C25 -> 0.05 | K26: Bihar
B27: 1200000 | C27: 0.15 | D27: =C27-C26 -> 0.05 | K27: Jharkhand
B28: 1600000 | C28: 0.2 | D28: =C28-C27 -> 0.05 | K28: Assam
B29: 2000000 | C29: 0.25 | D29: =C29-C28 -> 0.05 | K29: Other
B30: 2400000 | C30: 0.3 | D30: =C30-C29 -> 0.05
B33: Professional Tax — monthly slabs (gross earned salary)
B34: State | C34: Salary from (₹) | D34: Salary to (₹) | E34: Monthly PT (₹) | F34: February PT (₹)
B35: Maharashtra (Men) | C35: 0 | D35: 7500 | E35: 0 | F35: 0
B36: Maharashtra (Men) | C36: 7501 | D36: 10000 | E36: 175 | F36: 175
B37: Maharashtra (Men) | C37: 10001 | D37: 999999999 | E37: 200 | F37: 300
