Workbook

Sheet How to use
B2: MyFinMantra — TDS Calculator & Interest (Income-tax Act, 2025)
B3: Client service format · Clear books. Confident business.
B5: Purpose | C5: Section-wise TDS on payments to residents under the Income-tax Act, 2025 (section 393, with the old 1961 Act section alongside), a TDS register that applies thresholds automatically, interest for late deduction and late payment under section 398, late fee under section 427, and a quarterly summary.
B7: Colour legend
B8: 12,500 | C8: Blue text on yellow = input. Type or paste your client's figures here.
B9: Formula | C9: Black text = formula. Don't overwrite; it updates automatically.
B10: Header | C10: Section and column headings.
B12: Steps
B13: Step 1 | C13: On 'Settings', enter the deductor's name, TAN and the 'as on' date (defaults to today).
B14: Step 2 | C14: Use 'Quick Calculator' for a single payment: choose the nature of payment, payee type and amount.
B15: Step 3 | C15: For the month's payments, use 'TDS Register': one row per payment or credit. Thresholds, rate, TDS, due date and interest calculate automatically.
B16: Step 4 | C16: Enter the date TDS was deducted and the date it was paid to see any interest due.
B17: Step 5 | C17: On 'Summary', see TDS by section, the challans due and quarterly statement late fees.
B19: Notes
C20: Interest (section 398(3)(a)): 1% a month for late deduction (from the date tax was deductible to the date deducted) and 1.5% a month for late payment (from the date deducted to the date paid). Part of a month counts as a full month; months are counted as calendar months, as TRACES does.
C21: Late fee (section 427): ₹200 a day from the statement due date until filed, capped at the TDS for the quarter. Penalty under section 461 (₹10,000 to ₹1 lakh) is separate.
C22: No PAN: the higher of 20% or the applicable rate (5% for purchase of goods).
C23: Aggregate thresholds: once a payee's yearly total crosses the limit, TDS applies to the whole amount, including earlier payments that were below the limit — the register adds them to the crossing payment.
C24: Salary TDS (section 392) is calculated in the Payroll Calculator template. Payments to non-residents (section 393(2)) are not covered.
C25: Section references and payment codes are as published for Tax Year 2026-27; verify with the Act and Rules before relying on them.
B27: Sample figures are filled in so you can see how the format works. Replace them with your own data.
B29: Free template by MyFinMantra
B30: Accounting, GST, payroll and Virtual CFO services · www.myfinmantra.com · WhatsApp +91 97118 99555
B31: General template for guidance only — verify rates and rules for your case. Not professional advice.

Sheet Quick Calculator
B2: Quick TDS calculator
B3: One payment at a time
B5: Nature of payment | C5: Contractor / sub-contractor payments
B6: Payee type | C6: Firm / LLP / others
B7: PAN available? | C7: Yes
B8: Amount of this payment / credit (₹) | C8: 45000
B9: Already paid to this payee this year, same nature (₹) | C9: 70000
B10: Of which, TDS not yet deducted (₹) | C10: 70000
B11: Date of payment or credit | C11: 46310
B12: Result
B13: Old section (1961 Act) | C13: =INDEX('TDS Rates'!$C$6:$C$40,MATCH($C$5,'TDS Rates'!$B$6:$B$40,0)) -> 194C
B14: New section (Income-tax Act, 2025) | C14: =INDEX('TDS Rates'!$D$6:$D$40,MATCH($C$5,'TDS Rates'!$B$6:$B$40,0)) -> 393(1) Table Sl. 6(i)
B15: Payment code | C15: =INDEX('TDS Rates'!$E$6:$E$40,MATCH($C$5,'TDS Rates'!$B$6:$B$40,0)) -> 1023 / 1024
B16: Threshold | C16: =IF(INDEX('TDS Rates'!$F$6:$F$40,MATCH($C$5,'TDS Rates'!$B$6:$B$40,0))="NONE","No threshold",IF(INDEX('TDS Rates'!$F$6:$F$40,MATCH($C$5,'TDS Rates'!$B$6:$B$40,0))="PER","Above ₹"&TEXT(INDEX('TDS Rates'!$G$6:$G$40,MATCH($C$5,'TDS Rates'!$B$6:$B$40,0)),"#,##0")&" per payment / month",IF(INDEX('TDS Rates'!$F$6:$F$40,MATCH($C$5,'TDS Rates'!$B$6:$B$40,0))="EXCESS","Only on amount above ₹"&TEXT(INDEX('TDS Rates'!$H$6:$H$40,MATCH($C$5,'TDS Rates'!$B$6:$B$40,0)),"#,##0")&" a year",IF(INDEX('TDS Rates'!$F$6:$F$40,MATCH($C$5,'TDS Rates'!$B$6:$B$40,0))="SA","Above ₹"&TEXT(INDEX('TDS Rates'!$G$6:$G$40,MATCH($C$5,'TDS Rates'!$B$6:$B$40,0)),"#,##0")&" per payment or ₹"&TEXT(INDEX('TDS Rates'!$H$6:$H$40,MATCH($C$5,'TDS Rates'!$B$6:$B$40,0)),"#,##0")&" a year","Above ₹"&TEXT(INDEX('TDS Rates'!$H$6:$H$40,MATCH($C$5,'TDS Rates'!$B$6:$B$40,0)),"#,##0")&" a year")))) -> Above ₹30,000 per payment or ₹100,000 a year
B17: Amount liable to TDS (₹) | C17: =IF(INDEX('TDS Rates'!$F$6:$F$40,MATCH($C$5,'TDS Rates'!$B$6:$B$40,0))="NONE",$C$8,IF(INDEX('TDS Rates'!$F$6:$F$40,MATCH($C$5,'TDS Rates'!$B$6:$B$40,0))="PER",IF($C$8>INDEX('TDS Rates'!$G$6:$G$40,MATCH($C$5,'TDS Rates'!$B$6:$B$40,0)),$C$8,0),IF(INDEX('TDS Rates'!$F$6:$F$40,MATCH($C$5,'TDS Rates'!$B$6:$B$40,0))="EXCESS",MAX(0,$C$9+$C$8-INDEX('TDS Rates'!$H$6:$H$40,MATCH($C$5,'TDS Rates'!$B$6:$B$40,0)))-MAX(0,$C$9-INDEX('TDS Rates'!$H$6:$H$40,MATCH($C$5,'TDS Rates'!$B$6:$B$40,0))),IF(INDEX('TDS Rates'!$F$6:$F$40,MATCH($C$5,'TDS Rates'!$B$6:$B$40,0))="SA",IF($C$9+$C$8>INDEX('TDS Rates'!$H$6:$H$40,MATCH($C$5,'TDS Rates'!$B$6:$B$40,0)),$C$8+$C$10,IF($C$8>INDEX('TDS Rates'!$G$6:$G$40,MATCH($C$5,'TDS Rates'!$B$6:$B$40,0)),$C$8,0)),IF($C$9+$C$8>INDEX('TDS Rates'!$H$6:$H$40,MATCH($C$5,'TDS Rates'!$B$6:$B$40,0)),$C$8+$C$10,0))))) -> 115000
B18: TDS rate | C18: =IF($C$7="No",IF(INDEX('TDS Rates'!$C$6:$C$40,MATCH($C$5,'TDS Rates'!$B$6:$B$40,0))="194Q",Settings!$C$14,MAX(Settings!$C$13,IF($C$6="Individual / HUF",INDEX('TDS Rates'!$I$6:$I$40,MATCH($C$5,'TDS Rates'!$B$6:$B$40,0)),IF($C$6="Company",INDEX('TDS Rates'!$J$6:$J$40,MATCH($C$5,'TDS Rates'!$B$6:$B$40,0)),INDEX('TDS Rates'!$K$6:$K$40,MATCH($C$5,'TDS Rates'!$B$6:$B$40,0)))))),IF($C$6="Individual / HUF",INDEX('TDS Rates'!$I$6:$I$40,MATCH($C$5,'TDS Rates'!$B$6:$B$40,0)),IF($C$6="Company",INDEX('TDS Rates'!$J$6:$J$40,MATCH($C$5,'TDS Rates'!$B$6:$B$40,0)),INDEX('TDS Rates'!$K$6:$K$40,MATCH($C$5,'TDS Rates'!$B$6:$B$40,0))))) -> 0.02
B19: TDS to deduct (₹) | C19: =ROUND(C17*C18,0) -> 2300
B20: Deposit due by (if deducted on payment date) | C20: =IF(INDEX('TDS Rates'!$E$6:$E$40,MATCH($C$5,'TDS Rates'!$B$6:$B$40,0))="Form 141",EOMONTH($C$11,0)+30,IF(MONTH($C$11)=3,DATE(YEAR($C$11),4,30),DATE(YEAR($C$11),MONTH($C$11)+1,7))) -> 46333
B21: Notes | C21: =IF(INDEX('TDS Rates'!$L$6:$L$40,MATCH($C$5,'TDS Rates'!$B$6:$B$40,0))="","",INDEX('TDS Rates'!$L$6:$L$40,MATCH($C$5,'TDS Rates'!$B$6:$B$40,0)))
B24: Interest and late fee
B25: TDS amount (₹) | C25: =C19 -> 2300
B26: Date tax was deductible (payment / credit date) | C26: =$C$11 -> 46310
B27: Date TDS was actually deducted | C27: 46329
B28: Due date for deposit (month after deduction) | C28: =IF(INDEX('TDS Rates'!$E$6:$E$40,MATCH($C$5,'TDS Rates'!$B$6:$B$40,0))="Form 141",EOMONTH(C27,0)+30,IF(MONTH(C27)=3,DATE(YEAR(C27),4,30),DATE(YEAR(C27),MONTH(C27)+1,7))) -> 46363
B29: Date TDS was paid | C29: 46366
B30: Quarterly statement due date | C30: 46418
B31: Date statement filed | C31: 46427
B33: Result
B34: Months — late deduction | C34: =IF(C27<=C26,0,((YEAR(C27)-YEAR(C26))*12+MONTH(C27)-MONTH(C26)+1)) -> 2
B35: Interest @ 1% a month — late deduction (₹) | C35: =ROUND(C25*Settings!$C$10*C34,0) -> 46
B36: Months — late payment | C36: =IF(C29<=C28,0,((YEAR(C29)-YEAR(C27))*12+MONTH(C29)-MONTH(C27)+1)) -> 2
B37: Interest @ 1.5% a month — late payment (₹) | C37: =ROUND(C25*Settings!$C$11*C36,0) -> 69
B38: Total interest (₹) | C38: =C35+C37 -> 115
B39: Days statement filed late | C39: =MAX(0,C31-C30) -> 9
B40: Late fee u/s 427 (₹200 a day, max TDS) (₹) | C40: =MIN(C39*Settings!$C$12,C25) -> 1800
B42: The late fee covers the TDS of the whole quarter's statement — use the quarter's total TDS for an exact figure (see 'Summary').

Sheet TDS Register
B2: TDS register
B3: =Settings!$C$5&" · TAN "&Settings!$C$6&" · as on "&TEXT(Settings!$C$9,"dd-mmm-yyyy") -> Sample Services Pvt Ltd · TAN DELS12345A · as on 27-Oct-2026
B5: Date of payment / credit | C5: Payee name | D5: PAN | E5: Payee type | F5: PAN available? | G5: Nature of payment | H5: Amount (₹) | I5: New section (2025 Act) | J5: Old section | K5: Payment code | L5: Paid earlier this year (₹) | M5: Earlier, TDS not deducted (₹) | N5: Amount liable to TDS (₹) | O5: Rate | P5: TDS (₹) | Q5: Deposit due by | R5: Date TDS deducted | S5: Date TDS paid | T5: Challan / BSR ref. | U5: Months — late deduction | V5: Interest 1% (₹) | W5: Months — late payment | X5: Interest 1.5% (₹) | Y5: Total interest (₹) | Z5: Status | AA5: Key
B6: 46183 | C6: Sharma Contractors | D6: AAAFS1234K | E6: Firm / LLP / others | F6: Yes | G6: Contractor / sub-contractor payments | H6: 25000 | I6: =IF(OR(G6="",H6=""),"",IFERROR(INDEX('TDS Rates'!$D$6:$D$40,MATCH(G6,'TDS Rates'!$B$6:$B$40,0)),"Check nature")) -> 393(1) Table Sl. 6(i) | J6: =IF(OR(G6="",H6=""),"",IFERROR(INDEX('TDS Rates'!$C$6:$C$40,MATCH(G6,'TDS Rates'!$B$6:$B$40,0)),"")) -> 194C | K6: =IF(OR(G6="",H6=""),"",IFERROR(INDEX('TDS Rates'!$E$6:$E$40,MATCH(G6,'TDS Rates'!$B$6:$B$40,0)),"")) -> 1023 / 1024 | L6: =IF(OR(G6="",H6=""),"",0) -> 0 | M6: =IF(OR(G6="",H6=""),"",0) -> 0 | N6: =IF(OR(G6="",H6=""),"",IFERROR(IF(INDEX('TDS Rates'!$F$6:$F$40,MATCH(G6,'TDS Rates'!$B$6:$B$40,0))="NONE",H6,IF(INDEX('TDS Rates'!$F$6:$F$40,MATCH(G6,'TDS Rates'!$B$6:$B$40,0))="PER",IF(H6>INDEX('TDS Rates'!$G$6:$G$40,MATCH(G6,'TDS Rates'!$B$6:$B$40,0)),H6,0),IF(INDEX('TDS Rates'!$F$6:$F$40,MATCH(G6,'TDS Rates'!$B$6:$B$40,0))="EXCESS",MAX(0,L6+H6-INDEX('TDS Rates'!$H$6:$H$40,MATCH(G6,'TDS Rates'!$B$6:$B$40,0)))-MAX(0,L6-INDEX('TDS Rates'!$H$6:$H$40,MATCH(G6,'TDS Rates'!$B$6:$B$40,0))),IF(INDEX('TDS Rates'!$F$6:$F$40,MATCH(G6,'TDS Rates'!$B$6:$B$40,0))="SA",IF(L6+H6>INDEX('TDS Rates'!$H$6:$H$40,MATCH(G6,'TDS Rates'!$B$6:$B$40,0)),H6+M6,IF(H6>INDEX('TDS Rates'!$G$6:$G$40,MATCH(G6,'TDS Rates'!$B$6:$B$40,0)),H6,0)),IF(L6+H6>INDEX('TDS Rates'!$H$6:$H$40,MATCH(G6,'TDS Rates'!$B$6:$B$40,0)),H6+M6,0))))),0)) -> 0 | O6: =IF(OR(G6="",H6=""),"",IFERROR(IF(F6="No",IF(INDEX('TDS Rates'!$C$6:$C$40,MATCH(G6,'TDS Rates'!$B$6:$B$40,0))="194Q",Settings!$C$14,MAX(Settings!$C$13,IF(E6="Individual / HUF",INDEX('TDS Rates'!$I$6:$I$40,MATCH(G6,'TDS Rates'!$B$6:$B$40,0)),IF(E6="Company",INDEX('TDS Rates'!$J$6:$J$40,MATCH(G6,'TDS Rates'!$B$6:$B$40,0)),INDEX('TDS Rates'!$K$6:$K$40,MATCH(G6,'TDS Rates'!$B$6:$B$40,0)))))),IF(E6="Individual / HUF",INDEX('TDS Rates'!$I$6:$I$40,MATCH(G6,'TDS Rates'!$B$6:$B$40,0)),IF(E6="Company",INDEX('TDS Rates'!$J$6:$J$40,MATCH(G6,'TDS Rates'!$B$6:$B$40,0)),INDEX('TDS Rates'!$K$6:$K$40,MATCH(G6,'TDS Rates'!$B$6:$B$40,0))))),0)) -> 0.02 | P6: =IF(OR(G6="",H6=""),"",ROUND(N6*O6,0)) -> 0 | Q6: =IF(OR(G6="",H6=""),"",IFERROR(IF(INDEX('TDS Rates'!$E$6:$E$40,MATCH(G6,'TDS Rates'!$B$6:$B$40,0))="Form 141",EOMONTH(IF(R6="",B6,R6),0)+30,IF(MONTH(IF(R6="",B6,R6))=3,DATE(YEAR(IF(R6="",B6,R6)),4,30),DATE(YEAR(IF(R6="",B6,R6)),MONTH(IF(R6="",B6,R6))+1,7))),"")) -> 46210 | U6: =IF(OR(G6="",H6=""),"",IF(P6=0,0,IF(IF(R6="",Settings!$C$9,R6)<=B6,0,((YEAR(IF(R6="",Settings!$C$9,R6))-YEAR(B6))*12+MONTH(IF(R6="",Settings!$C$9,R6))-MONTH(B6)+1)))) -> 0 | V6: =IF(OR(G6="",H6=""),"",ROUND(P6*Settings!$C$10*U6,0)) -> 0 | W6: =IF(OR(G6="",H6=""),"",IF(OR(P6=0,R6=""),0,IF(IF(S6="",Settings!$C$9,S6)<=Q6,0,((YEAR(IF(S6="",Settings!$C$9,S6))-YEAR(R6))*12+MONTH(IF(S6="",Settings!$C$9,S6))-MONTH(R6)+1)))) -> 0 | X6: =IF(OR(G6="",H6=""),"",ROUND(P6*Settings!$C$11*W6,0)) -> 0 | Y6: =IF(OR(G6="",H6=""),"",V6+X6) -> 0 | Z6: =IF(OR(G6="",H6=""),"",IF(P6=0,"Below threshold",IF(R6="","Not yet deducted",IF(S6="",IF(Settings!$C$9>Q6,"Overdue — pay now","Deducted, due "&TEXT(Q6,"dd-mmm")),IF(S6<=Q6,IF(N(U6)>0,"Deducted late, paid on time","Paid on time"),"Paid late"))))) -> Below threshold | AA6: =IF(OR(G6="",H6=""),"",IF(D6<>"",UPPER(TRIM(D6)),UPPER(TRIM(C6)))) -> AAAFS1234K
B7: 46215 | C7: Sharma Contractors | D7: AAAFS1234K | E7: Firm / LLP / others | F7: Yes | G7: Contractor / sub-contractor payments | H7: 28000 | I7: =IF(OR(G7="",H7=""),"",IFERROR(INDEX('TDS Rates'!$D$6:$D$40,MATCH(G7,'TDS Rates'!$B$6:$B$40,0)),"Check nature")) -> 393(1) Table Sl. 6(i) | J7: =IF(OR(G7="",H7=""),"",IFERROR(INDEX('TDS Rates'!$C$6:$C$40,MATCH(G7,'TDS Rates'!$B$6:$B$40,0)),"")) -> 194C | K7: =IF(OR(G7="",H7=""),"",IFERROR(INDEX('TDS Rates'!$E$6:$E$40,MATCH(G7,'TDS Rates'!$B$6:$B$40,0)),"")) -> 1023 / 1024 | L7: =IF(OR(G7="",H7=""),"",SUMIFS(H$6:H6,AA$6:AA6,AA7,G$6:G6,G7)) -> 25000 | M7: =IF(OR(G7="",H7=""),"",SUMIFS(H$6:H6,AA$6:AA6,AA7,G$6:G6,G7,N$6:N6,0)) -> 25000 | N7: =IF(OR(G7="",H7=""),"",IFERROR(IF(INDEX('TDS Rates'!$F$6:$F$40,MATCH(G7,'TDS Rates'!$B$6:$B$40,0))="NONE",H7,IF(INDEX('TDS Rates'!$F$6:$F$40,MATCH(G7,'TDS Rates'!$B$6:$B$40,0))="PER",IF(H7>INDEX('TDS Rates'!$G$6:$G$40,MATCH(G7,'TDS Rates'!$B$6:$B$40,0)),H7,0),IF(INDEX('TDS Rates'!$F$6:$F$40,MATCH(G7,'TDS Rates'!$B$6:$B$40,0))="EXCESS",MAX(0,L7+H7-INDEX('TDS Rates'!$H$6:$H$40,MATCH(G7,'TDS Rates'!$B$6:$B$40,0)))-MAX(0,L7-INDEX('TDS Rates'!$H$6:$H$40,MATCH(G7,'TDS Rates'!$B$6:$B$40,0))),IF(INDEX('TDS Rates'!$F$6:$F$40,MATCH(G7,'TDS Rates'!$B$6:$B$40,0))="SA",IF(L7+H7>INDEX('TDS Rates'!$H$6:$H$40,MATCH(G7,'TDS Rates'!$B$6:$B$40,0)),H7+M7,IF(H7>INDEX('TDS Rates'!$G$6:$G$40,MATCH(G7,'TDS Rates'!$B$6:$B$40,0)),H7,0)),IF(L7+H7>INDEX('TDS Rates'!$H$6:$H$40,MATCH(G7,'TDS Rates'!$B$6:$B$40,0)),H7+M7,0))))),0)) -> 0 | O7: =IF(OR(G7="",H7=""),"",IFERROR(IF(F7="No",IF(INDEX('TDS Rates'!$C$6:$C$40,MATCH(G7,'TDS Rates'!$B$6:$B$40,0))="194Q",Settings!$C$14,MAX(Settings!$C$13,IF(E7="Individual / HUF",INDEX('TDS Rates'!$I$6:$I$40,MATCH(G7,'TDS Rates'!$B$6:$B$40,0)),IF(E7="Company",INDEX('TDS Rates'!$J$6:$J$40,MATCH(G7,'TDS Rates'!$B$6:$B$40,0)),INDEX('TDS Rates'!$K$6:$K$40,MATCH(G7,'TDS Rates'!$B$6:$B$40,0)))))),IF(E7="Individual / HUF",INDEX('TDS Rates'!$I$6:$I$40,MATCH(G7,'TDS Rates'!$B$6:$B$40,0)),IF(E7="Company",INDEX('TDS Rates'!$J$6:$J$40,MATCH(G7,'TDS Rates'!$B$6:$B$40,0)),INDEX('TDS Rates'!$K$6:$K$40,MATCH(G7,'TDS Rates'!$B$6:$B$40,0))))),0)) -> 0.02 | P7: =IF(OR(G7="",H7=""),"",ROUND(N7*O7,0)) -> 0 | Q7: =IF(OR(G7="",H7=""),"",IFERROR(IF(INDEX('TDS Rates'!$E$6:$E$40,MATCH(G7,'TDS Rates'!$B$6:$B$40,0))="Form 141",EOMONTH(IF(R7="",B7,R7),0)+30,IF(MONTH(IF(R7="",B7,R7))=3,DATE(YEAR(IF(R7="",B7,R7)),4,30),DATE(YEAR(IF(R7="",B7,R7)),MONTH(IF(R7="",B7,R7))+1,7))),"")) -> 46241 | U7: =IF(OR(G7="",H7=""),"",IF(P7=0,0,IF(IF(R7="",Settings!$C$9,R7)<=B7,0,((YEAR(IF(R7="",Settings!$C$9,R7))-YEAR(B7))*12+MONTH(IF(R7="",Settings!$C$9,R7))-MONTH(B7)+1)))) -> 0 | V7: =IF(OR(G7="",H7=""),"",ROUND(P7*Settings!$C$10*U7,0)) -> 0 | W7: =IF(OR(G7="",H7=""),"",IF(OR(P7=0,R7=""),0,IF(IF(S7="",Settings!$C$9,S7)<=Q7,0,((YEAR(IF(S7="",Settings!$C$9,S7))-YEAR(R7))*12+MONTH(IF(S7="",Settings!$C$9,S7))-MONTH(R7)+1)))) -> 0 | X7: =IF(OR(G7="",H7=""),"",ROUND(P7*Settings!$C$11*W7,0)) -> 0 | Y7: =IF(OR(G7="",H7=""),"",V7+X7) -> 0 | Z7: =IF(OR(G7="",H7=""),"",IF(P7=0,"Below threshold",IF(R7="","Not yet deducted",IF(S7="",IF(Settings!$C$9>Q7,"Overdue — pay now","Deducted, due "&TEXT(Q7,"dd-mmm")),IF(S7<=Q7,IF(N(U7)>0,"Deducted late, paid on time","Paid on time"),"Paid late"))))) -> Below threshold | AA7: =IF(OR(G7="",H7=""),"",IF(D7<>"",UPPER(TRIM(D7)),UPPER(TRIM(C7)))) -> AAAFS1234K
B8: 46280 | C8: Sharma Contractors | D8: AAAFS1234K | E8: Firm / LLP / others | F8: Yes | G8: Contractor / sub-contractor payments | H8: 60000 | I8: =IF(OR(G8="",H8=""),"",IFERROR(INDEX('TDS Rates'!$D$6:$D$40,MATCH(G8,'TDS Rates'!$B$6:$B$40,0)),"Check nature")) -> 393(1) Table Sl. 6(i) | J8: =IF(OR(G8="",H8=""),"",IFERROR(INDEX('TDS Rates'!$C$6:$C$40,MATCH(G8,'TDS Rates'!$B$6:$B$40,0)),"")) -> 194C | K8: =IF(OR(G8="",H8=""),"",IFERROR(INDEX('TDS Rates'!$E$6:$E$40,MATCH(G8,'TDS Rates'!$B$6:$B$40,0)),"")) -> 1023 / 1024 | L8: =IF(OR(G8="",H8=""),"",SUMIFS(H$6:H7,AA$6:AA7,AA8,G$6:G7,G8)) -> 53000 | M8: =IF(OR(G8="",H8=""),"",SUMIFS(H$6:H7,AA$6:AA7,AA8,G$6:G7,G8,N$6:N7,0)) -> 53000 | N8: =IF(OR(G8="",H8=""),"",IFERROR(IF(INDEX('TDS Rates'!$F$6:$F$40,MATCH(G8,'TDS Rates'!$B$6:$B$40,0))="NONE",H8,IF(INDEX('TDS Rates'!$F$6:$F$40,MATCH(G8,'TDS Rates'!$B$6:$B$40,0))="PER",IF(H8>INDEX('TDS Rates'!$G$6:$G$40,MATCH(G8,'TDS Rates'!$B$6:$B$40,0)),H8,0),IF(INDEX('TDS Rates'!$F$6:$F$40,MATCH(G8,'TDS Rates'!$B$6:$B$40,0))="EXCESS",MAX(0,L8+H8-INDEX('TDS Rates'!$H$6:$H$40,MATCH(G8,'TDS Rates'!$B$6:$B$40,0)))-MAX(0,L8-INDEX('TDS Rates'!$H$6:$H$40,MATCH(G8,'TDS Rates'!$B$6:$B$40,0))),IF(INDEX('TDS Rates'!$F$6:$F$40,MATCH(G8,'TDS Rates'!$B$6:$B$40,0))="SA",IF(L8+H8>INDEX('TDS Rates'!$H$6:$H$40,MATCH(G8,'TDS Rates'!$B$6:$B$40,0)),H8+M8,IF(H8>INDEX('TDS Rates'!$G$6:$G$40,MATCH(G8,'TDS Rates'!$B$6:$B$40,0)),H8,0)),IF(L8+H8>INDEX('TDS Rates'!$H$6:$H$40,MATCH(G8,'TDS Rates'!$B$6:$B$40,0)),H8+M8,0))))),0)) -> 113000 | O8: =IF(OR(G8="",H8=""),"",IFERROR(IF(F8="No",IF(INDEX('TDS Rates'!$C$6:$C$40,MATCH(G8,'TDS Rates'!$B$6:$B$40,0))="194Q",Settings!$C$14,MAX(Settings!$C$13,IF(E8="Individual / HUF",INDEX('TDS Rates'!$I$6:$I$40,MATCH(G8,'TDS Rates'!$B$6:$B$40,0)),IF(E8="Company",INDEX('TDS Rates'!$J$6:$J$40,MATCH(G8,'TDS Rates'!$B$6:$B$40,0)),INDEX('TDS Rates'!$K$6:$K$40,MATCH(G8,'TDS Rates'!$B$6:$B$40,0)))))),IF(E8="Individual / HUF",INDEX('TDS Rates'!$I$6:$I$40,MATCH(G8,'TDS Rates'!$B$6:$B$40,0)),IF(E8="Company",INDEX('TDS Rates'!$J$6:$J$40,MATCH(G8,'TDS Rates'!$B$6:$B$40,0)),INDEX('TDS Rates'!$K$6:$K$40,MATCH(G8,'TDS Rates'!$B$6:$B$40,0))))),0)) -> 0.02 | P8: =IF(OR(G8="",H8=""),"",ROUND(N8*O8,0)) -> 2260 | Q8: =IF(OR(G8="",H8=""),"",IFERROR(IF(INDEX('TDS Rates'!$E$6:$E$40,MATCH(G8,'TDS Rates'!$B$6:$B$40,0))="Form 141",EOMONTH(IF(R8="",B8,R8),0)+30,IF(MONTH(IF(R8="",B8,R8))=3,DATE(YEAR(IF(R8="",B8,R8)),4,30),DATE(YEAR(IF(R8="",B8,R8)),MONTH(IF(R8="",B8,R8))+1,7))),"")) -> 46302 | R8: 46280 | S8: 46302 | T8: 0510308 / 00045 | U8: =IF(OR(G8="",H8=""),"",IF(P8=0,0,IF(IF(R8="",Settings!$C$9,R8)<=B8,0,((YEAR(IF(R8="",Settings!$C$9,R8))-YEAR(B8))*12+MONTH(IF(R8="",Settings!$C$9,R8))-MONTH(B8)+1)))) -> 0 | V8: =IF(OR(G8="",H8=""),"",ROUND(P8*Settings!$C$10*U8,0)) -> 0 | W8: =IF(OR(G8="",H8=""),"",IF(OR(P8=0,R8=""),0,IF(IF(S8="",Settings!$C$9,S8)<=Q8,0,((YEAR(IF(S8="",Settings!$C$9,S8))-YEAR(R8))*12+MONTH(IF(S8="",Settings!$C$9,S8))-MONTH(R8)+1)))) -> 0 | X8: =IF(OR(G8="",H8=""),"",ROUND(P8*Settings!$C$11*W8,0)) -> 0 | Y8: =IF(OR(G8="",H8=""),"",V8+X8) -> 0 | Z8: =IF(OR(G8="",H8=""),"",IF(P8=0,"Below threshold",IF(R8="","Not yet deducted",IF(S8="",IF(Settings!$C$9>Q8,"Overdue — pay now","Deducted, due "&TEXT(Q8,"dd-mmm")),IF(S8<=Q8,IF(N(U8)>0,"Deducted late, paid on time","Paid on time"),"Paid late"))))) -> Paid on time | AA8: =IF(OR(G8="",H8=""),"",IF(D8<>"",UPPER(TRIM(D8)),UPPER(TRIM(C8)))) -> AAAFS1234K
B9: 46295 | C9: Rao & Associates | D9: AAAFR5678L | E9: Firm / LLP / others | F9: Yes | G9: Professional fees, royalty, non-compete fees | H9: 75000 | I9: =IF(OR(G9="",H9=""),"",IFERROR(INDEX('TDS Rates'!$D$6:$D$40,MATCH(G9,'TDS Rates'!$B$6:$B$40,0)),"Check nature")) -> 393(1) Table Sl. 6(iii) | J9: =IF(OR(G9="",H9=""),"",IFERROR(INDEX('TDS Rates'!$C$6:$C$40,MATCH(G9,'TDS Rates'!$B$6:$B$40,0)),"")) -> 194J(b) | K9: =IF(OR(G9="",H9=""),"",IFERROR(INDEX('TDS Rates'!$E$6:$E$40,MATCH(G9,'TDS Rates'!$B$6:$B$40,0)),"")) -> 1027 | L9: =IF(OR(G9="",H9=""),"",SUMIFS(H$6:H8,AA$6:AA8,AA9,G$6:G8,G9)) -> 0 | M9: =IF(OR(G9="",H9=""),"",SUMIFS(H$6:H8,AA$6:AA8,AA9,G$6:G8,G9,N$6:N8,0)) -> 0 | N9: =IF(OR(G9="",H9=""),"",IFERROR(IF(INDEX('TDS Rates'!$F$6:$F$40,MATCH(G9,'TDS Rates'!$B$6:$B$40,0))="NONE",H9,IF(INDEX('TDS Rates'!$F$6:$F$40,MATCH(G9,'TDS Rates'!$B$6:$B$40,0))="PER",IF(H9>INDEX('TDS Rates'!$G$6:$G$40,MATCH(G9,'TDS Rates'!$B$6:$B$40,0)),H9,0),IF(INDEX('TDS Rates'!$F$6:$F$40,MATCH(G9,'TDS Rates'!$B$6:$B$40,0))="EXCESS",MAX(0,L9+H9-INDEX('TDS Rates'!$H$6:$H$40,MATCH(G9,'TDS Rates'!$B$6:$B$40,0)))-MAX(0,L9-INDEX('TDS Rates'!$H$6:$H$40,MATCH(G9,'TDS Rates'!$B$6:$B$40,0))),IF(INDEX('TDS Rates'!$F$6:$F$40,MATCH(G9,'TDS Rates'!$B$6:$B$40,0))="SA",IF(L9+H9>INDEX('TDS Rates'!$H$6:$H$40,MATCH(G9,'TDS Rates'!$B$6:$B$40,0)),H9+M9,IF(H9>INDEX('TDS Rates'!$G$6:$G$40,MATCH(G9,'TDS Rates'!$B$6:$B$40,0)),H9,0)),IF(L9+H9>INDEX('TDS Rates'!$H$6:$H$40,MATCH(G9,'TDS Rates'!$B$6:$B$40,0)),H9+M9,0))))),0)) -> 75000 | O9: =IF(OR(G9="",H9=""),"",IFERROR(IF(F9="No",IF(INDEX('TDS Rates'!$C$6:$C$40,MATCH(G9,'TDS Rates'!$B$6:$B$40,0))="194Q",Settings!$C$14,MAX(Settings!$C$13,IF(E9="Individual / HUF",INDEX('TDS Rates'!$I$6:$I$40,MATCH(G9,'TDS Rates'!$B$6:$B$40,0)),IF(E9="Company",INDEX('TDS Rates'!$J$6:$J$40,MATCH(G9,'TDS Rates'!$B$6:$B$40,0)),INDEX('TDS Rates'!$K$6:$K$40,MATCH(G9,'TDS Rates'!$B$6:$B$40,0)))))),IF(E9="Individual / HUF",INDEX('TDS Rates'!$I$6:$I$40,MATCH(G9,'TDS Rates'!$B$6:$B$40,0)),IF(E9="Company",INDEX('TDS Rates'!$J$6:$J$40,MATCH(G9,'TDS Rates'!$B$6:$B$40,0)),INDEX('TDS Rates'!$K$6:$K$40,MATCH(G9,'TDS Rates'!$B$6:$B$40,0))))),0)) -> 0.1 | P9: =IF(OR(G9="",H9=""),"",ROUND(N9*O9,0)) -> 7500 | Q9: =IF(OR(G9="",H9=""),"",IFERROR(IF(INDEX('TDS Rates'!$E$6:$E$40,MATCH(G9,'TDS Rates'!$B$6:$B$40,0))="Form 141",EOMONTH(IF(R9="",B9,R9),0)+30,IF(MONTH(IF(R9="",B9,R9))=3,DATE(YEAR(IF(R9="",B9,R9)),4,30),DATE(YEAR(IF(R9="",B9,R9)),MONTH(IF(R9="",B9,R9))+1,7))),"")) -> 46333 | R9: 46315 | S9: 46331 | T9: 0510308 / 00051 | U9: =IF(OR(G9="",H9=""),"",IF(P9=0,0,IF(IF(R9="",Settings!$C$9,R9)<=B9,0,((YEAR(IF(R9="",Settings!$C$9,R9))-YEAR(B9))*12+MONTH(IF(R9="",Settings!$C$9,R9))-MONTH(B9)+1)))) -> 2 | V9: =IF(OR(G9="",H9=""),"",ROUND(P9*Settings!$C$10*U9,0)) -> 150 | W9: =IF(OR(G9="",H9=""),"",IF(OR(P9=0,R9=""),0,IF(IF(S9="",Settings!$C$9,S9)<=Q9,0,((YEAR(IF(S9="",Settings!$C$9,S9))-YEAR(R9))*12+MONTH(IF(S9="",Settings!$C$9,S9))-MONTH(R9)+1)))) -> 0 | X9: =IF(OR(G9="",H9=""),"",ROUND(P9*Settings!$C$11*W9,0)) -> 0 | Y9: =IF(OR(G9="",H9=""),"",V9+X9) -> 150 | Z9: =IF(OR(G9="",H9=""),"",IF(P9=0,"Below threshold",IF(R9="","Not yet deducted",IF(S9="",IF(Settings!$C$9>Q9,"Overdue — pay now","Deducted, due "&TEXT(Q9,"dd-mmm")),IF(S9<=Q9,IF(N(U9)>0,"Deducted late, paid on time","Paid on time"),"Paid late"))))) -> Deducted late, paid on time | AA9: =IF(OR(G9="",H9=""),"",IF(D9<>"",UPPER(TRIM(D9)),UPPER(TRIM(C9)))) -> AAAFR5678L
B10: 46296 | C10: Mehta Properties | D10: ABCPM4321Q | E10: Individual / HUF | F10: Yes | G10: Rent — land, building, furniture | H10: 90000 | I10: =IF(OR(G10="",H10=""),"",IFERROR(INDEX('TDS Rates'!$D$6:$D$40,MATCH(G10,'TDS Rates'!$B$6:$B$40,0)),"Check nature")) -> 393(1) Table Sl. 2(ii) | J10: =IF(OR(G10="",H10=""),"",IFERROR(INDEX('TDS Rates'!$C$6:$C$40,MATCH(G10,'TDS Rates'!$B$6:$B$40,0)),"")) -> 194-I(b) | K10: =IF(OR(G10="",H10=""),"",IFERROR(INDEX('TDS Rates'!$E$6:$E$40,MATCH(G10,'TDS Rates'!$B$6:$B$40,0)),"")) -> 1009 | L10: =IF(OR(G10="",H10=""),"",SUMIFS(H$6:H9,AA$6:AA9,AA10,G$6:G9,G10)) -> 0 | M10: =IF(OR(G10="",H10=""),"",SUMIFS(H$6:H9,AA$6:AA9,AA10,G$6:G9,G10,N$6:N9,0)) -> 0 | N10: =IF(OR(G10="",H10=""),"",IFERROR(IF(INDEX('TDS Rates'!$F$6:$F$40,MATCH(G10,'TDS Rates'!$B$6:$B$40,0))="NONE",H10,IF(INDEX('TDS Rates'!$F$6:$F$40,MATCH(G10,'TDS Rates'!$B$6:$B$40,0))="PER",IF(H10>INDEX('TDS Rates'!$G$6:$G$40,MATCH(G10,'TDS Rates'!$B$6:$B$40,0)),H10,0),IF(INDEX('TDS Rates'!$F$6:$F$40,MATCH(G10,'TDS Rates'!$B$6:$B$40,0))="EXCESS",MAX(0,L10+H10-INDEX('TDS Rates'!$H$6:$H$40,MATCH(G10,'TDS Rates'!$B$6:$B$40,0)))-MAX(0,L10-INDEX('TDS Rates'!$H$6:$H$40,MATCH(G10,'TDS Rates'!$B$6:$B$40,0))),IF(INDEX('TDS Rates'!$F$6:$F$40,MATCH(G10,'TDS Rates'!$B$6:$B$40,0))="SA",IF(L10+H10>INDEX('TDS Rates'!$H$6:$H$40,MATCH(G10,'TDS Rates'!$B$6:$B$40,0)),H10+M10,IF(H10>INDEX('TDS Rates'!$G$6:$G$40,MATCH(G10,'TDS Rates'!$B$6:$B$40,0)),H10,0)),IF(L10+H10>INDEX('TDS Rates'!$H$6:$H$40,MATCH(G10,'TDS Rates'!$B$6:$B$40,0)),H10+M10,0))))),0)) -> 90000 | O10: =IF(OR(G10="",H10=""),"",IFERROR(IF(F10="No",IF(INDEX('TDS Rates'!$C$6:$C$40,MATCH(G10,'TDS Rates'!$B$6:$B$40,0))="194Q",Settings!$C$14,MAX(Settings!$C$13,IF(E10="Individual / HUF",INDEX('TDS Rates'!$I$6:$I$40,MATCH(G10,'TDS Rates'!$B$6:$B$40,0)),IF(E10="Company",INDEX('TDS Rates'!$J$6:$J$40,MATCH(G10,'TDS Rates'!$B$6:$B$40,0)),INDEX('TDS Rates'!$K$6:$K$40,MATCH(G10,'TDS Rates'!$B$6:$B$40,0)))))),IF(E10="Individual / HUF",INDEX('TDS Rates'!$I$6:$I$40,MATCH(G10,'TDS Rates'!$B$6:$B$40,0)),IF(E10="Company",INDEX('TDS Rates'!$J$6:$J$40,MATCH(G10,'TDS Rates'!$B$6:$B$40,0)),INDEX('TDS Rates'!$K$6:$K$40,MATCH(G10,'TDS Rates'!$B$6:$B$40,0))))),0)) -> 0.1 | P10: =IF(OR(G10="",H10=""),"",ROUND(N10*O10,0)) -> 9000 | Q10: =IF(OR(G10="",H10=""),"",IFERROR(IF(INDEX('TDS Rates'!$E$6:$E$40,MATCH(G10,'TDS Rates'!$B$6:$B$40,0))="Form 141",EOMONTH(IF(R10="",B10,R10),0)+30,IF(MONTH(IF(R10="",B10,R10))=3,DATE(YEAR(IF(R10="",B10,R10)),4,30),DATE(YEAR(IF(R10="",B10,R10)),MONTH(IF(R10="",B10,R10))+1,7))),"")) -> 46333 | R10: 46296 | U10: =IF(OR(G10="",H10=""),"",IF(P10=0,0,IF(IF(R10="",Settings!$C$9,R10)<=B10,0,((YEAR(IF(R10="",Settings!$C$9,R10))-YEAR(B10))*12+MONTH(IF(R10="",Settings!$C$9,R10))-MONTH(B10)+1)))) -> 0 | V10: =IF(OR(G10="",H10=""),"",ROUND(P10*Settings!$C$10*U10,0)) -> 0 | W10: =IF(OR(G10="",H10=""),"",IF(OR(P10=0,R10=""),0,IF(IF(S10="",Settings!$C$9,S10)<=Q10,0,((YEAR(IF(S10="",Settings!$C$9,S10))-YEAR(R10))*12+MONTH(IF(S10="",Settings!$C$9,S10))-MONTH(R10)+1)))) -> 0 | X10: =IF(OR(G10="",H10=""),"",ROUND(P10*Settings!$C$11*W10,0)) -> 0 | Y10: =IF(OR(G10="",H10=""),"",V10+X10) -> 0 | Z10: =IF(OR(G10="",H10=""),"",IF(P10=0,"Below threshold",IF(R10="","Not yet deducted",IF(S10="",IF(Settings!$C$9>Q10,"Overdue — pay now","Deducted, due "&TEXT(Q10,"dd-mmm")),IF(S10<=Q10,IF(N(U10)>0,"Deducted late, paid on time","Paid on time"),"Paid late"))))) -> Deducted, due 07-Nov | AA10: =IF(OR(G10="",H10=""),"",IF(D10<>"",UPPER(TRIM(D10)),UPPER(TRIM(C10)))) -> ABCPM4321Q
B11: 46300 | C11: Quick Couriers | E11: Individual / HUF | F11: No | G11: Commission or brokerage | H11: 25000 | I11: =IF(OR(G11="",H11=""),"",IFERROR(INDEX('TDS Rates'!$D$6:$D$40,MATCH(G11,'TDS Rates'!$B$6:$B$40,0)),"Check nature")) -> 393(1) Table Sl. 1(ii) | J11: =IF(OR(G11="",H11=""),"",IFERROR(INDEX('TDS Rates'!$C$6:$C$40,MATCH(G11,'TDS Rates'!$B$6:$B$40,0)),"")) -> 194H | K11: =IF(OR(G11="",H11=""),"",IFERROR(INDEX('TDS Rates'!$E$6:$E$40,MATCH(G11,'TDS Rates'!$B$6:$B$40,0)),"")) -> 1006 | L11: =IF(OR(G11="",H11=""),"",SUMIFS(H$6:H10,AA$6:AA10,AA11,G$6:G10,G11)) -> 0 | M11: =IF(OR(G11="",H11=""),"",SUMIFS(H$6:H10,AA$6:AA10,AA11,G$6:G10,G11,N$6:N10,0)) -> 0 | N11: =IF(OR(G11="",H11=""),"",IFERROR(IF(INDEX('TDS Rates'!$F$6:$F$40,MATCH(G11,'TDS Rates'!$B$6:$B$40,0))="NONE",H11,IF(INDEX('TDS Rates'!$F$6:$F$40,MATCH(G11,'TDS Rates'!$B$6:$B$40,0))="PER",IF(H11>INDEX('TDS Rates'!$G$6:$G$40,MATCH(G11,'TDS Rates'!$B$6:$B$40,0)),H11,0),IF(INDEX('TDS Rates'!$F$6:$F$40,MATCH(G11,'TDS Rates'!$B$6:$B$40,0))="EXCESS",MAX(0,L11+H11-INDEX('TDS Rates'!$H$6:$H$40,MATCH(G11,'TDS Rates'!$B$6:$B$40,0)))-MAX(0,L11-INDEX('TDS Rates'!$H$6:$H$40,MATCH(G11,'TDS Rates'!$B$6:$B$40,0))),IF(INDEX('TDS Rates'!$F$6:$F$40,MATCH(G11,'TDS Rates'!$B$6:$B$40,0))="SA",IF(L11+H11>INDEX('TDS Rates'!$H$6:$H$40,MATCH(G11,'TDS Rates'!$B$6:$B$40,0)),H11+M11,IF(H11>INDEX('TDS Rates'!$G$6:$G$40,MATCH(G11,'TDS Rates'!$B$6:$B$40,0)),H11,0)),IF(L11+H11>INDEX('TDS Rates'!$H$6:$H$40,MATCH(G11,'TDS Rates'!$B$6:$B$40,0)),H11+M11,0))))),0)) -> 25000 | O11: =IF(OR(G11="",H11=""),"",IFERROR(IF(F11="No",IF(INDEX('TDS Rates'!$C$6:$C$40,MATCH(G11,'TDS Rates'!$B$6:$B$40,0))="194Q",Settings!$C$14,MAX(Settings!$C$13,IF(E11="Individual / HUF",INDEX('TDS Rates'!$I$6:$I$40,MATCH(G11,'TDS Rates'!$B$6:$B$40,0)),IF(E11="Company",INDEX('TDS Rates'!$J$6:$J$40,MATCH(G11,'TDS Rates'!$B$6:$B$40,0)),INDEX('TDS Rates'!$K$6:$K$40,MATCH(G11,'TDS Rates'!$B$6:$B$40,0)))))),IF(E11="Individual / HUF",INDEX('TDS Rates'!$I$6:$I$40,MATCH(G11,'TDS Rates'!$B$6:$B$40,0)),IF(E11="Company",INDEX('TDS Rates'!$J$6:$J$40,MATCH(G11,'TDS Rates'!$B$6:$B$40,0)),INDEX('TDS Rates'!$K$6:$K$40,MATCH(G11,'TDS Rates'!$B$6:$B$40,0))))),0)) -> 0.2 | P11: =IF(OR(G11="",H11=""),"",ROUND(N11*O11,0)) -> 5000 | Q11: =IF(OR(G11="",H11=""),"",IFERROR(IF(INDEX('TDS Rates'!$E$6:$E$40,MATCH(G11,'TDS Rates'!$B$6:$B$40,0))="Form 141",EOMONTH(IF(R11="",B11,R11),0)+30,IF(MONTH(IF(R11="",B11,R11))=3,DATE(YEAR(IF(R11="",B11,R11)),4,30),DATE(YEAR(IF(R11="",B11,R11)),MONTH(IF(R11="",B11,R11))+1,7))),"")) -> 46333 | R11: 46300 | U11: =IF(OR(G11="",H11=""),"",IF(P11=0,0,IF(IF(R11="",Settings!$C$9,R11)<=B11,0,((YEAR(IF(R11="",Settings!$C$9,R11))-YEAR(B11))*12+MONTH(IF(R11="",Settings!$C$9,R11))-MONTH(B11)+1)))) -> 0 | V11: =IF(OR(G11="",H11=""),"",ROUND(P11*Settings!$C$10*U11,0)) -> 0 | W11: =IF(OR(G11="",H11=""),"",IF(OR(P11=0,R11=""),0,IF(IF(S11="",Settings!$C$9,S11)<=Q11,0,((YEAR(IF(S11="",Settings!$C$9,S11))-YEAR(R11))*12+MONTH(IF(S11="",Settings!$C$9,S11))-MONTH(R11)+1)))) -> 0 | X11: =IF(OR(G11="",H11=""),"",ROUND(P11*Settings!$C$11*W11,0)) -> 0 | Y11: =IF(OR(G11="",H11=""),"",V11+X11) -> 0 | Z11: =IF(OR(G11="",H11=""),"",IF(P11=0,"Below threshold",IF(R11="","Not yet deducted",IF(S11="",IF(Settings!$C$9>Q11,"Overdue — pay now","Deducted, due "&TEXT(Q11,"dd-mmm")),IF(S11<=Q11,IF(N(U11)>0,"Deducted late, paid on time","Paid on time"),"Paid late"))))) -> Deducted, due 07-Nov | AA11: =IF(OR(G11="",H11=""),"",IF(D11<>"",UPPER(TRIM(D11)),UPPER(TRIM(C11)))) -> QUICK COURIERS
I12: =IF(OR(G12="",H12=""),"",IFERROR(INDEX('TDS Rates'!$D$6:$D$40,MATCH(G12,'TDS Rates'!$B$6:$B$40,0)),"Check nature")) | J12: =IF(OR(G12="",H12=""),"",IFERROR(INDEX('TDS Rates'!$C$6:$C$40,MATCH(G12,'TDS Rates'!$B$6:$B$40,0)),"")) | K12: =IF(OR(G12="",H12=""),"",IFERROR(INDEX('TDS Rates'!$E$6:$E$40,MATCH(G12,'TDS Rates'!$B$6:$B$40,0)),"")) | L12: =IF(OR(G12="",H12=""),"",SUMIFS(H$6:H11,AA$6:AA11,AA12,G$6:G11,G12)) | M12: =IF(OR(G12="",H12=""),"",SUMIFS(H$6:H11,AA$6:AA11,AA12,G$6:G11,G12,N$6:N11,0)) | N12: =IF(OR(G12="",H12=""),"",IFERROR(IF(INDEX('TDS Rates'!$F$6:$F$40,MATCH(G12,'TDS Rates'!$B$6:$B$40,0))="NONE",H12,IF(INDEX('TDS Rates'!$F$6:$F$40,MATCH(G12,'TDS Rates'!$B$6:$B$40,0))="PER",IF(H12>INDEX('TDS Rates'!$G$6:$G$40,MATCH(G12,'TDS Rates'!$B$6:$B$40,0)),H12,0),IF(INDEX('TDS Rates'!$F$6:$F$40,MATCH(G12,'TDS Rates'!$B$6:$B$40,0))="EXCESS",MAX(0,L12+H12-INDEX('TDS Rates'!$H$6:$H$40,MATCH(G12,'TDS Rates'!$B$6:$B$40,0)))-MAX(0,L12-INDEX('TDS Rates'!$H$6:$H$40,MATCH(G12,'TDS Rates'!$B$6:$B$40,0))),IF(INDEX('TDS Rates'!$F$6:$F$40,MATCH(G12,'TDS Rates'!$B$6:$B$40,0))="SA",IF(L12+H12>INDEX('TDS Rates'!$H$6:$H$40,MATCH(G12,'TDS Rates'!$B$6:$B$40,0)),H12+M12,IF(H12>INDEX('TDS Rates'!$G$6:$G$40,MATCH(G12,'TDS Rates'!$B$6:$B$40,0)),H12,0)),IF(L12+H12>INDEX('TDS Rates'!$H$6:$H$40,MATCH(G12,'TDS Rates'!$B$6:$B$40,0)),H12+M12,0))))),0)) | O12: =IF(OR(G12="",H12=""),"",IFERROR(IF(F12="No",IF(INDEX('TDS Rates'!$C$6:$C$40,MATCH(G12,'TDS Rates'!$B$6:$B$40,0))="194Q",Settings!$C$14,MAX(Settings!$C$13,IF(E12="Individual / HUF",INDEX('TDS Rates'!$I$6:$I$40,MATCH(G12,'TDS Rates'!$B$6:$B$40,0)),IF(E12="Company",INDEX('TDS Rates'!$J$6:$J$40,MATCH(G12,'TDS Rates'!$B$6:$B$40,0)),INDEX('TDS Rates'!$K$6:$K$40,MATCH(G12,'TDS Rates'!$B$6:$B$40,0)))))),IF(E12="Individual / HUF",INDEX('TDS Rates'!$I$6:$I$40,MATCH(G12,'TDS Rates'!$B$6:$B$40,0)),IF(E12="Company",INDEX('TDS Rates'!$J$6:$J$40,MATCH(G12,'TDS Rates'!$B$6:$B$40,0)),INDEX('TDS Rates'!$K$6:$K$40,MATCH(G12,'TDS Rates'!$B$6:$B$40,0))))),0)) | P12: =IF(OR(G12="",H12=""),"",ROUND(N12*O12,0)) | Q12: =IF(OR(G12="",H12=""),"",IFERROR(IF(INDEX('TDS Rates'!$E$6:$E$40,MATCH(G12,'TDS Rates'!$B$6:$B$40,0))="Form 141",EOMONTH(IF(R12="",B12,R12),0)+30,IF(MONTH(IF(R12="",B12,R12))=3,DATE(YEAR(IF(R12="",B12,R12)),4,30),DATE(YEAR(IF(R12="",B12,R12)),MONTH(IF(R12="",B12,R12))+1,7))),"")) | U12: =IF(OR(G12="",H12=""),"",IF(P12=0,0,IF(IF(R12="",Settings!$C$9,R12)<=B12,0,((YEAR(IF(R12="",Settings!$C$9,R12))-YEAR(B12))*12+MONTH(IF(R12="",Settings!$C$9,R12))-MONTH(B12)+1)))) | V12: =IF(OR(G12="",H12=""),"",ROUND(P12*Settings!$C$10*U12,0)) | W12: =IF(OR(G12="",H12=""),"",IF(OR(P12=0,R12=""),0,IF(IF(S12="",Settings!$C$9,S12)<=Q12,0,((YEAR(IF(S12="",Settings!$C$9,S12))-YEAR(R12))*12+MONTH(IF(S12="",Settings!$C$9,S12))-MONTH(R12)+1)))) | X12: =IF(OR(G12="",H12=""),"",ROUND(P12*Settings!$C$11*W12,0)) | Y12: =IF(OR(G12="",H12=""),"",V12+X12) | Z12: =IF(OR(G12="",H12=""),"",IF(P12=0,"Below threshold",IF(R12="","Not yet deducted",IF(S12="",IF(Settings!$C$9>Q12,"Overdue — pay now","Deducted, due "&TEXT(Q12,"dd-mmm")),IF(S12<=Q12,IF(N(U12)>0,"Deducted late, paid on time","Paid on time"),"Paid late"))))) | AA12: =IF(OR(G12="",H12=""),"",IF(D12<>"",UPPER(TRIM(D12)),UPPER(TRIM(C12))))
I13: =IF(OR(G13="",H13=""),"",IFERROR(INDEX('TDS Rates'!$D$6:$D$40,MATCH(G13,'TDS Rates'!$B$6:$B$40,0)),"Check nature")) | J13: =IF(OR(G13="",H13=""),"",IFERROR(INDEX('TDS Rates'!$C$6:$C$40,MATCH(G13,'TDS Rates'!$B$6:$B$40,0)),"")) | K13: =IF(OR(G13="",H13=""),"",IFERROR(INDEX('TDS Rates'!$E$6:$E$40,MATCH(G13,'TDS Rates'!$B$6:$B$40,0)),"")) | L13: =IF(OR(G13="",H13=""),"",SUMIFS(H$6:H12,AA$6:AA12,AA13,G$6:G12,G13)) | M13: =IF(OR(G13="",H13=""),"",SUMIFS(H$6:H12,AA$6:AA12,AA13,G$6:G12,G13,N$6:N12,0)) | N13: =IF(OR(G13="",H13=""),"",IFERROR(IF(INDEX('TDS Rates'!$F$6:$F$40,MATCH(G13,'TDS Rates'!$B$6:$B$40,0))="NONE",H13,IF(INDEX('TDS Rates'!$F$6:$F$40,MATCH(G13,'TDS Rates'!$B$6:$B$40,0))="PER",IF(H13>INDEX('TDS Rates'!$G$6:$G$40,MATCH(G13,'TDS Rates'!$B$6:$B$40,0)),H13,0),IF(INDEX('TDS Rates'!$F$6:$F$40,MATCH(G13,'TDS Rates'!$B$6:$B$40,0))="EXCESS",MAX(0,L13+H13-INDEX('TDS Rates'!$H$6:$H$40,MATCH(G13,'TDS Rates'!$B$6:$B$40,0)))-MAX(0,L13-INDEX('TDS Rates'!$H$6:$H$40,MATCH(G13,'TDS Rates'!$B$6:$B$40,0))),IF(INDEX('TDS Rates'!$F$6:$F$40,MATCH(G13,'TDS Rates'!$B$6:$B$40,0))="SA",IF(L13+H13>INDEX('TDS Rates'!$H$6:$H$40,MATCH(G13,'TDS Rates'!$B$6:$B$40,0)),H13+M13,IF(H13>INDEX('TDS Rates'!$G$6:$G$40,MATCH(G13,'TDS Rates'!$B$6:$B$40,0)),H13,0)),IF(L13+H13>INDEX('TDS Rates'!$H$6:$H$40,MATCH(G13,'TDS Rates'!$B$6:$B$40,0)),H13+M13,0))))),0)) | O13: =IF(OR(G13="",H13=""),"",IFERROR(IF(F13="No",IF(INDEX('TDS Rates'!$C$6:$C$40,MATCH(G13,'TDS Rates'!$B$6:$B$40,0))="194Q",Settings!$C$14,MAX(Settings!$C$13,IF(E13="Individual / HUF",INDEX('TDS Rates'!$I$6:$I$40,MATCH(G13,'TDS Rates'!$B$6:$B$40,0)),IF(E13="Company",INDEX('TDS Rates'!$J$6:$J$40,MATCH(G13,'TDS Rates'!$B$6:$B$40,0)),INDEX('TDS Rates'!$K$6:$K$40,MATCH(G13,'TDS Rates'!$B$6:$B$40,0)))))),IF(E13="Individual / HUF",INDEX('TDS Rates'!$I$6:$I$40,MATCH(G13,'TDS Rates'!$B$6:$B$40,0)),IF(E13="Company",INDEX('TDS Rates'!$J$6:$J$40,MATCH(G13,'TDS Rates'!$B$6:$B$40,0)),INDEX('TDS Rates'!$K$6:$K$40,MATCH(G13,'TDS Rates'!$B$6:$B$40,0))))),0)) | P13: =IF(OR(G13="",H13=""),"",ROUND(N13*O13,0)) | Q13: =IF(OR(G13="",H13=""),"",IFERROR(IF(INDEX('TDS Rates'!$E$6:$E$40,MATCH(G13,'TDS Rates'!$B$6:$B$40,0))="Form 141",EOMONTH(IF(R13="",B13,R13),0)+30,IF(MONTH(IF(R13="",B13,R13))=3,DATE(YEAR(IF(R13="",B13,R13)),4,30),DATE(YEAR(IF(R13="",B13,R13)),MONTH(IF(R13="",B13,R13))+1,7))),"")) | U13: =IF(OR(G13="",H13=""),"",IF(P13=0,0,IF(IF(R13="",Settings!$C$9,R13)<=B13,0,((YEAR(IF(R13="",Settings!$C$9,R13))-YEAR(B13))*12+MONTH(IF(R13="",Settings!$C$9,R13))-MONTH(B13)+1)))) | V13: =IF(OR(G13="",H13=""),"",ROUND(P13*Settings!$C$10*U13,0)) | W13: =IF(OR(G13="",H13=""),"",IF(OR(P13=0,R13=""),0,IF(IF(S13="",Settings!$C$9,S13)<=Q13,0,((YEAR(IF(S13="",Settings!$C$9,S13))-YEAR(R13))*12+MONTH(IF(S13="",Settings!$C$9,S13))-MONTH(R13)+1)))) | X13: =IF(OR(G13="",H13=""),"",ROUND(P13*Settings!$C$11*W13,0)) | Y13: =IF(OR(G13="",H13=""),"",V13+X13) | Z13: =IF(OR(G13="",H13=""),"",IF(P13=0,"Below threshold",IF(R13="","Not yet deducted",IF(S13="",IF(Settings!$C$9>Q13,"Overdue — pay now","Deducted, due "&TEXT(Q13,"dd-mmm")),IF(S13<=Q13,IF(N(U13)>0,"Deducted late, paid on time","Paid on time"),"Paid late"))))) | AA13: =IF(OR(G13="",H13=""),"",IF(D13<>"",UPPER(TRIM(D13)),UPPER(TRIM(C13))))
I14: =IF(OR(G14="",H14=""),"",IFERROR(INDEX('TDS Rates'!$D$6:$D$40,MATCH(G14,'TDS Rates'!$B$6:$B$40,0)),"Check nature")) | J14: =IF(OR(G14="",H14=""),"",IFERROR(INDEX('TDS Rates'!$C$6:$C$40,MATCH(G14,'TDS Rates'!$B$6:$B$40,0)),"")) | K14: =IF(OR(G14="",H14=""),"",IFERROR(INDEX('TDS Rates'!$E$6:$E$40,MATCH(G14,'TDS Rates'!$B$6:$B$40,0)),"")) | L14: =IF(OR(G14="",H14=""),"",SUMIFS(H$6:H13,AA$6:AA13,AA14,G$6:G13,G14)) | M14: =IF(OR(G14="",H14=""),"",SUMIFS(H$6:H13,AA$6:AA13,AA14,G$6:G13,G14,N$6:N13,0)) | N14: =IF(OR(G14="",H14=""),"",IFERROR(IF(INDEX('TDS Rates'!$F$6:$F$40,MATCH(G14,'TDS Rates'!$B$6:$B$40,0))="NONE",H14,IF(INDEX('TDS Rates'!$F$6:$F$40,MATCH(G14,'TDS Rates'!$B$6:$B$40,0))="PER",IF(H14>INDEX('TDS Rates'!$G$6:$G$40,MATCH(G14,'TDS Rates'!$B$6:$B$40,0)),H14,0),IF(INDEX('TDS Rates'!$F$6:$F$40,MATCH(G14,'TDS Rates'!$B$6:$B$40,0))="EXCESS",MAX(0,L14+H14-INDEX('TDS Rates'!$H$6:$H$40,MATCH(G14,'TDS Rates'!$B$6:$B$40,0)))-MAX(0,L14-INDEX('TDS Rates'!$H$6:$H$40,MATCH(G14,'TDS Rates'!$B$6:$B$40,0))),IF(INDEX('TDS Rates'!$F$6:$F$40,MATCH(G14,'TDS Rates'!$B$6:$B$40,0))="SA",IF(L14+H14>INDEX('TDS Rates'!$H$6:$H$40,MATCH(G14,'TDS Rates'!$B$6:$B$40,0)),H14+M14,IF(H14>INDEX('TDS Rates'!$G$6:$G$40,MATCH(G14,'TDS Rates'!$B$6:$B$40,0)),H14,0)),IF(L14+H14>INDEX('TDS Rates'!$H$6:$H$40,MATCH(G14,'TDS Rates'!$B$6:$B$40,0)),H14+M14,0))))),0)) | O14: =IF(OR(G14="",H14=""),"",IFERROR(IF(F14="No",IF(INDEX('TDS Rates'!$C$6:$C$40,MATCH(G14,'TDS Rates'!$B$6:$B$40,0))="194Q",Settings!$C$14,MAX(Settings!$C$13,IF(E14="Individual / HUF",INDEX('TDS Rates'!$I$6:$I$40,MATCH(G14,'TDS Rates'!$B$6:$B$40,0)),IF(E14="Company",INDEX('TDS Rates'!$J$6:$J$40,MATCH(G14,'TDS Rates'!$B$6:$B$40,0)),INDEX('TDS Rates'!$K$6:$K$40,MATCH(G14,'TDS Rates'!$B$6:$B$40,0)))))),IF(E14="Individual / HUF",INDEX('TDS Rates'!$I$6:$I$40,MATCH(G14,'TDS Rates'!$B$6:$B$40,0)),IF(E14="Company",INDEX('TDS Rates'!$J$6:$J$40,MATCH(G14,'TDS Rates'!$B$6:$B$40,0)),INDEX('TDS Rates'!$K$6:$K$40,MATCH(G14,'TDS Rates'!$B$6:$B$40,0))))),0)) | P14: =IF(OR(G14="",H14=""),"",ROUND(N14*O14,0)) | Q14: =IF(OR(G14="",H14=""),"",IFERROR(IF(INDEX('TDS Rates'!$E$6:$E$40,MATCH(G14,'TDS Rates'!$B$6:$B$40,0))="Form 141",EOMONTH(IF(R14="",B14,R14),0)+30,IF(MONTH(IF(R14="",B14,R14))=3,DATE(YEAR(IF(R14="",B14,R14)),4,30),DATE(YEAR(IF(R14="",B14,R14)),MONTH(IF(R14="",B14,R14))+1,7))),"")) | U14: =IF(OR(G14="",H14=""),"",IF(P14=0,0,IF(IF(R14="",Settings!$C$9,R14)<=B14,0,((YEAR(IF(R14="",Settings!$C$9,R14))-YEAR(B14))*12+MONTH(IF(R14="",Settings!$C$9,R14))-MONTH(B14)+1)))) | V14: =IF(OR(G14="",H14=""),"",ROUND(P14*Settings!$C$10*U14,0)) | W14: =IF(OR(G14="",H14=""),"",IF(OR(P14=0,R14=""),0,IF(IF(S14="",Settings!$C$9,S14)<=Q14,0,((YEAR(IF(S14="",Settings!$C$9,S14))-YEAR(R14))*12+MONTH(IF(S14="",Settings!$C$9,S14))-MONTH(R14)+1)))) | X14: =IF(OR(G14="",H14=""),"",ROUND(P14*Settings!$C$11*W14,0)) | Y14: =IF(OR(G14="",H14=""),"",V14+X14) | Z14: =IF(OR(G14="",H14=""),"",IF(P14=0,"Below threshold",IF(R14="","Not yet deducted",IF(S14="",IF(Settings!$C$9>Q14,"Overdue — pay now","Deducted, due "&TEXT(Q14,"dd-mmm")),IF(S14<=Q14,IF(N(U14)>0,"Deducted late, paid on time","Paid on time"),"Paid late"))))) | AA14: =IF(OR(G14="",H14=""),"",IF(D14<>"",UPPER(TRIM(D14)),UPPER(TRIM(C14))))
I15: =IF(OR(G15="",H15=""),"",IFERROR(INDEX('TDS Rates'!$D$6:$D$40,MATCH(G15,'TDS Rates'!$B$6:$B$40,0)),"Check nature")) | J15: =IF(OR(G15="",H15=""),"",IFERROR(INDEX('TDS Rates'!$C$6:$C$40,MATCH(G15,'TDS Rates'!$B$6:$B$40,0)),"")) | K15: =IF(OR(G15="",H15=""),"",IFERROR(INDEX('TDS Rates'!$E$6:$E$40,MATCH(G15,'TDS Rates'!$B$6:$B$40,0)),"")) | L15: =IF(OR(G15="",H15=""),"",SUMIFS(H$6:H14,AA$6:AA14,AA15,G$6:G14,G15)) | M15: =IF(OR(G15="",H15=""),"",SUMIFS(H$6:H14,AA$6:AA14,AA15,G$6:G14,G15,N$6:N14,0)) | N15: =IF(OR(G15="",H15=""),"",IFERROR(IF(INDEX('TDS Rates'!$F$6:$F$40,MATCH(G15,'TDS Rates'!$B$6:$B$40,0))="NONE",H15,IF(INDEX('TDS Rates'!$F$6:$F$40,MATCH(G15,'TDS Rates'!$B$6:$B$40,0))="PER",IF(H15>INDEX('TDS Rates'!$G$6:$G$40,MATCH(G15,'TDS Rates'!$B$6:$B$40,0)),H15,0),IF(INDEX('TDS Rates'!$F$6:$F$40,MATCH(G15,'TDS Rates'!$B$6:$B$40,0))="EXCESS",MAX(0,L15+H15-INDEX('TDS Rates'!$H$6:$H$40,MATCH(G15,'TDS Rates'!$B$6:$B$40,0)))-MAX(0,L15-INDEX('TDS Rates'!$H$6:$H$40,MATCH(G15,'TDS Rates'!$B$6:$B$40,0))),IF(INDEX('TDS Rates'!$F$6:$F$40,MATCH(G15,'TDS Rates'!$B$6:$B$40,0))="SA",IF(L15+H15>INDEX('TDS Rates'!$H$6:$H$40,MATCH(G15,'TDS Rates'!$B$6:$B$40,0)),H15+M15,IF(H15>INDEX('TDS Rates'!$G$6:$G$40,MATCH(G15,'TDS Rates'!$B$6:$B$40,0)),H15,0)),IF(L15+H15>INDEX('TDS Rates'!$H$6:$H$40,MATCH(G15,'TDS Rates'!$B$6:$B$40,0)),H15+M15,0))))),0)) | O15: =IF(OR(G15="",H15=""),"",IFERROR(IF(F15="No",IF(INDEX('TDS Rates'!$C$6:$C$40,MATCH(G15,'TDS Rates'!$B$6:$B$40,0))="194Q",Settings!$C$14,MAX(Settings!$C$13,IF(E15="Individual / HUF",INDEX('TDS Rates'!$I$6:$I$40,MATCH(G15,'TDS Rates'!$B$6:$B$40,0)),IF(E15="Company",INDEX('TDS Rates'!$J$6:$J$40,MATCH(G15,'TDS Rates'!$B$6:$B$40,0)),INDEX('TDS Rates'!$K$6:$K$40,MATCH(G15,'TDS Rates'!$B$6:$B$40,0)))))),IF(E15="Individual / HUF",INDEX('TDS Rates'!$I$6:$I$40,MATCH(G15,'TDS Rates'!$B$6:$B$40,0)),IF(E15="Company",INDEX('TDS Rates'!$J$6:$J$40,MATCH(G15,'TDS Rates'!$B$6:$B$40,0)),INDEX('TDS Rates'!$K$6:$K$40,MATCH(G15,'TDS Rates'!$B$6:$B$40,0))))),0)) | P15: =IF(OR(G15="",H15=""),"",ROUND(N15*O15,0)) | Q15: =IF(OR(G15="",H15=""),"",IFERROR(IF(INDEX('TDS Rates'!$E$6:$E$40,MATCH(G15,'TDS Rates'!$B$6:$B$40,0))="Form 141",EOMONTH(IF(R15="",B15,R15),0)+30,IF(MONTH(IF(R15="",B15,R15))=3,DATE(YEAR(IF(R15="",B15,R15)),4,30),DATE(YEAR(IF(R15="",B15,R15)),MONTH(IF(R15="",B15,R15))+1,7))),"")) | U15: =IF(OR(G15="",H15=""),"",IF(P15=0,0,IF(IF(R15="",Settings!$C$9,R15)<=B15,0,((YEAR(IF(R15="",Settings!$C$9,R15))-YEAR(B15))*12+MONTH(IF(R15="",Settings!$C$9,R15))-MONTH(B15)+1)))) | V15: =IF(OR(G15="",H15=""),"",ROUND(P15*Settings!$C$10*U15,0)) | W15: =IF(OR(G15="",H15=""),"",IF(OR(P15=0,R15=""),0,IF(IF(S15="",Settings!$C$9,S15)<=Q15,0,((YEAR(IF(S15="",Settings!$C$9,S15))-YEAR(R15))*12+MONTH(IF(S15="",Settings!$C$9,S15))-MONTH(R15)+1)))) | X15: =IF(OR(G15="",H15=""),"",ROUND(P15*Settings!$C$11*W15,0)) | Y15: =IF(OR(G15="",H15=""),"",V15+X15) | Z15: =IF(OR(G15="",H15=""),"",IF(P15=0,"Below threshold",IF(R15="","Not yet deducted",IF(S15="",IF(Settings!$C$9>Q15,"Overdue — pay now","Deducted, due "&TEXT(Q15,"dd-mmm")),IF(S15<=Q15,IF(N(U15)>0,"Deducted late, paid on time","Paid on time"),"Paid late"))))) | AA15: =IF(OR(G15="",H15=""),"",IF(D15<>"",UPPER(TRIM(D15)),UPPER(TRIM(C15))))
I16: =IF(OR(G16="",H16=""),"",IFERROR(INDEX('TDS Rates'!$D$6:$D$40,MATCH(G16,'TDS Rates'!$B$6:$B$40,0)),"Check nature")) | J16: =IF(OR(G16="",H16=""),"",IFERROR(INDEX('TDS Rates'!$C$6:$C$40,MATCH(G16,'TDS Rates'!$B$6:$B$40,0)),"")) | K16: =IF(OR(G16="",H16=""),"",IFERROR(INDEX('TDS Rates'!$E$6:$E$40,MATCH(G16,'TDS Rates'!$B$6:$B$40,0)),"")) | L16: =IF(OR(G16="",H16=""),"",SUMIFS(H$6:H15,AA$6:AA15,AA16,G$6:G15,G16)) | M16: =IF(OR(G16="",H16=""),"",SUMIFS(H$6:H15,AA$6:AA15,AA16,G$6:G15,G16,N$6:N15,0)) | N16: =IF(OR(G16="",H16=""),"",IFERROR(IF(INDEX('TDS Rates'!$F$6:$F$40,MATCH(G16,'TDS Rates'!$B$6:$B$40,0))="NONE",H16,IF(INDEX('TDS Rates'!$F$6:$F$40,MATCH(G16,'TDS Rates'!$B$6:$B$40,0))="PER",IF(H16>INDEX('TDS Rates'!$G$6:$G$40,MATCH(G16,'TDS Rates'!$B$6:$B$40,0)),H16,0),IF(INDEX('TDS Rates'!$F$6:$F$40,MATCH(G16,'TDS Rates'!$B$6:$B$40,0))="EXCESS",MAX(0,L16+H16-INDEX('TDS Rates'!$H$6:$H$40,MATCH(G16,'TDS Rates'!$B$6:$B$40,0)))-MAX(0,L16-INDEX('TDS Rates'!$H$6:$H$40,MATCH(G16,'TDS Rates'!$B$6:$B$40,0))),IF(INDEX('TDS Rates'!$F$6:$F$40,MATCH(G16,'TDS Rates'!$B$6:$B$40,0))="SA",IF(L16+H16>INDEX('TDS Rates'!$H$6:$H$40,MATCH(G16,'TDS Rates'!$B$6:$B$40,0)),H16+M16,IF(H16>INDEX('TDS Rates'!$G$6:$G$40,MATCH(G16,'TDS Rates'!$B$6:$B$40,0)),H16,0)),IF(L16+H16>INDEX('TDS Rates'!$H$6:$H$40,MATCH(G16,'TDS Rates'!$B$6:$B$40,0)),H16+M16,0))))),0)) | O16: =IF(OR(G16="",H16=""),"",IFERROR(IF(F16="No",IF(INDEX('TDS Rates'!$C$6:$C$40,MATCH(G16,'TDS Rates'!$B$6:$B$40,0))="194Q",Settings!$C$14,MAX(Settings!$C$13,IF(E16="Individual / HUF",INDEX('TDS Rates'!$I$6:$I$40,MATCH(G16,'TDS Rates'!$B$6:$B$40,0)),IF(E16="Company",INDEX('TDS Rates'!$J$6:$J$40,MATCH(G16,'TDS Rates'!$B$6:$B$40,0)),INDEX('TDS Rates'!$K$6:$K$40,MATCH(G16,'TDS Rates'!$B$6:$B$40,0)))))),IF(E16="Individual / HUF",INDEX('TDS Rates'!$I$6:$I$40,MATCH(G16,'TDS Rates'!$B$6:$B$40,0)),IF(E16="Company",INDEX('TDS Rates'!$J$6:$J$40,MATCH(G16,'TDS Rates'!$B$6:$B$40,0)),INDEX('TDS Rates'!$K$6:$K$40,MATCH(G16,'TDS Rates'!$B$6:$B$40,0))))),0)) | P16: =IF(OR(G16="",H16=""),"",ROUND(N16*O16,0)) | Q16: =IF(OR(G16="",H16=""),"",IFERROR(IF(INDEX('TDS Rates'!$E$6:$E$40,MATCH(G16,'TDS Rates'!$B$6:$B$40,0))="Form 141",EOMONTH(IF(R16="",B16,R16),0)+30,IF(MONTH(IF(R16="",B16,R16))=3,DATE(YEAR(IF(R16="",B16,R16)),4,30),DATE(YEAR(IF(R16="",B16,R16)),MONTH(IF(R16="",B16,R16))+1,7))),"")) | U16: =IF(OR(G16="",H16=""),"",IF(P16=0,0,IF(IF(R16="",Settings!$C$9,R16)<=B16,0,((YEAR(IF(R16="",Settings!$C$9,R16))-YEAR(B16))*12+MONTH(IF(R16="",Settings!$C$9,R16))-MONTH(B16)+1)))) | V16: =IF(OR(G16="",H16=""),"",ROUND(P16*Settings!$C$10*U16,0)) | W16: =IF(OR(G16="",H16=""),"",IF(OR(P16=0,R16=""),0,IF(IF(S16="",Settings!$C$9,S16)<=Q16,0,((YEAR(IF(S16="",Settings!$C$9,S16))-YEAR(R16))*12+MONTH(IF(S16="",Settings!$C$9,S16))-MONTH(R16)+1)))) | X16: =IF(OR(G16="",H16=""),"",ROUND(P16*Settings!$C$11*W16,0)) | Y16: =IF(OR(G16="",H16=""),"",V16+X16) | Z16: =IF(OR(G16="",H16=""),"",IF(P16=0,"Below threshold",IF(R16="","Not yet deducted",IF(S16="",IF(Settings!$C$9>Q16,"Overdue — pay now","Deducted, due "&TEXT(Q16,"dd-mmm")),IF(S16<=Q16,IF(N(U16)>0,"Deducted late, paid on time","Paid on time"),"Paid late"))))) | AA16: =IF(OR(G16="",H16=""),"",IF(D16<>"",UPPER(TRIM(D16)),UPPER(TRIM(C16))))
I17: =IF(OR(G17="",H17=""),"",IFERROR(INDEX('TDS Rates'!$D$6:$D$40,MATCH(G17,'TDS Rates'!$B$6:$B$40,0)),"Check nature")) | J17: =IF(OR(G17="",H17=""),"",IFERROR(INDEX('TDS Rates'!$C$6:$C$40,MATCH(G17,'TDS Rates'!$B$6:$B$40,0)),"")) | K17: =IF(OR(G17="",H17=""),"",IFERROR(INDEX('TDS Rates'!$E$6:$E$40,MATCH(G17,'TDS Rates'!$B$6:$B$40,0)),"")) | L17: =IF(OR(G17="",H17=""),"",SUMIFS(H$6:H16,AA$6:AA16,AA17,G$6:G16,G17)) | M17: =IF(OR(G17="",H17=""),"",SUMIFS(H$6:H16,AA$6:AA16,AA17,G$6:G16,G17,N$6:N16,0)) | N17: =IF(OR(G17="",H17=""),"",IFERROR(IF(INDEX('TDS Rates'!$F$6:$F$40,MATCH(G17,'TDS Rates'!$B$6:$B$40,0))="NONE",H17,IF(INDEX('TDS Rates'!$F$6:$F$40,MATCH(G17,'TDS Rates'!$B$6:$B$40,0))="PER",IF(H17>INDEX('TDS Rates'!$G$6:$G$40,MATCH(G17,'TDS Rates'!$B$6:$B$40,0)),H17,0),IF(INDEX('TDS Rates'!$F$6:$F$40,MATCH(G17,'TDS Rates'!$B$6:$B$40,0))="EXCESS",MAX(0,L17+H17-INDEX('TDS Rates'!$H$6:$H$40,MATCH(G17,'TDS Rates'!$B$6:$B$40,0)))-MAX(0,L17-INDEX('TDS Rates'!$H$6:$H$40,MATCH(G17,'TDS Rates'!$B$6:$B$40,0))),IF(INDEX('TDS Rates'!$F$6:$F$40,MATCH(G17,'TDS Rates'!$B$6:$B$40,0))="SA",IF(L17+H17>INDEX('TDS Rates'!$H$6:$H$40,MATCH(G17,'TDS Rates'!$B$6:$B$40,0)),H17+M17,IF(H17>INDEX('TDS Rates'!$G$6:$G$40,MATCH(G17,'TDS Rates'!$B$6:$B$40,0)),H17,0)),IF(L17+H17>INDEX('TDS Rates'!$H$6:$H$40,MATCH(G17,'TDS Rates'!$B$6:$B$40,0)),H17+M17,0))))),0)) | O17: =IF(OR(G17="",H17=""),"",IFERROR(IF(F17="No",IF(INDEX('TDS Rates'!$C$6:$C$40,MATCH(G17,'TDS Rates'!$B$6:$B$40,0))="194Q",Settings!$C$14,MAX(Settings!$C$13,IF(E17="Individual / HUF",INDEX('TDS Rates'!$I$6:$I$40,MATCH(G17,'TDS Rates'!$B$6:$B$40,0)),IF(E17="Company",INDEX('TDS Rates'!$J$6:$J$40,MATCH(G17,'TDS Rates'!$B$6:$B$40,0)),INDEX('TDS Rates'!$K$6:$K$40,MATCH(G17,'TDS Rates'!$B$6:$B$40,0)))))),IF(E17="Individual / HUF",INDEX('TDS Rates'!$I$6:$I$40,MATCH(G17,'TDS Rates'!$B$6:$B$40,0)),IF(E17="Company",INDEX('TDS Rates'!$J$6:$J$40,MATCH(G17,'TDS Rates'!$B$6:$B$40,0)),INDEX('TDS Rates'!$K$6:$K$40,MATCH(G17,'TDS Rates'!$B$6:$B$40,0))))),0)) | P17: =IF(OR(G17="",H17=""),"",ROUND(N17*O17,0)) | Q17: =IF(OR(G17="",H17=""),"",IFERROR(IF(INDEX('TDS Rates'!$E$6:$E$40,MATCH(G17,'TDS Rates'!$B$6:$B$40,0))="Form 141",EOMONTH(IF(R17="",B17,R17),0)+30,IF(MONTH(IF(R17="",B17,R17))=3,DATE(YEAR(IF(R17="",B17,R17)),4,30),DATE(YEAR(IF(R17="",B17,R17)),MONTH(IF(R17="",B17,R17))+1,7))),"")) | U17: =IF(OR(G17="",H17=""),"",IF(P17=0,0,IF(IF(R17="",Settings!$C$9,R17)<=B17,0,((YEAR(IF(R17="",Settings!$C$9,R17))-YEAR(B17))*12+MONTH(IF(R17="",Settings!$C$9,R17))-MONTH(B17)+1)))) | V17: =IF(OR(G17="",H17=""),"",ROUND(P17*Settings!$C$10*U17,0)) | W17: =IF(OR(G17="",H17=""),"",IF(OR(P17=0,R17=""),0,IF(IF(S17="",Settings!$C$9,S17)<=Q17,0,((YEAR(IF(S17="",Settings!$C$9,S17))-YEAR(R17))*12+MONTH(IF(S17="",Settings!$C$9,S17))-MONTH(R17)+1)))) | X17: =IF(OR(G17="",H17=""),"",ROUND(P17*Settings!$C$11*W17,0)) | Y17: =IF(OR(G17="",H17=""),"",V17+X17) | Z17: =IF(OR(G17="",H17=""),"",IF(P17=0,"Below threshold",IF(R17="","Not yet deducted",IF(S17="",IF(Settings!$C$9>Q17,"Overdue — pay now","Deducted, due "&TEXT(Q17,"dd-mmm")),IF(S17<=Q17,IF(N(U17)>0,"Deducted late, paid on time","Paid on time"),"Paid late"))))) | AA17: =IF(OR(G17="",H17=""),"",IF(D17<>"",UPPER(TRIM(D17)),UPPER(TRIM(C17))))
I18: =IF(OR(G18="",H18=""),"",IFERROR(INDEX('TDS Rates'!$D$6:$D$40,MATCH(G18,'TDS Rates'!$B$6:$B$40,0)),"Check nature")) | J18: =IF(OR(G18="",H18=""),"",IFERROR(INDEX('TDS Rates'!$C$6:$C$40,MATCH(G18,'TDS Rates'!$B$6:$B$40,0)),"")) | K18: =IF(OR(G18="",H18=""),"",IFERROR(INDEX('TDS Rates'!$E$6:$E$40,MATCH(G18,'TDS Rates'!$B$6:$B$40,0)),"")) | L18: =IF(OR(G18="",H18=""),"",SUMIFS(H$6:H17,AA$6:AA17,AA18,G$6:G17,G18)) | M18: =IF(OR(G18="",H18=""),"",SUMIFS(H$6:H17,AA$6:AA17,AA18,G$6:G17,G18,N$6:N17,0)) | N18: =IF(OR(G18="",H18=""),"",IFERROR(IF(INDEX('TDS Rates'!$F$6:$F$40,MATCH(G18,'TDS Rates'!$B$6:$B$40,0))="NONE",H18,IF(INDEX('TDS Rates'!$F$6:$F$40,MATCH(G18,'TDS Rates'!$B$6:$B$40,0))="PER",IF(H18>INDEX('TDS Rates'!$G$6:$G$40,MATCH(G18,'TDS Rates'!$B$6:$B$40,0)),H18,0),IF(INDEX('TDS Rates'!$F$6:$F$40,MATCH(G18,'TDS Rates'!$B$6:$B$40,0))="EXCESS",MAX(0,L18+H18-INDEX('TDS Rates'!$H$6:$H$40,MATCH(G18,'TDS Rates'!$B$6:$B$40,0)))-MAX(0,L18-INDEX('TDS Rates'!$H$6:$H$40,MATCH(G18,'TDS Rates'!$B$6:$B$40,0))),IF(INDEX('TDS Rates'!$F$6:$F$40,MATCH(G18,'TDS Rates'!$B$6:$B$40,0))="SA",IF(L18+H18>INDEX('TDS Rates'!$H$6:$H$40,MATCH(G18,'TDS Rates'!$B$6:$B$40,0)),H18+M18,IF(H18>INDEX('TDS Rates'!$G$6:$G$40,MATCH(G18,'TDS Rates'!$B$6:$B$40,0)),H18,0)),IF(L18+H18>INDEX('TDS Rates'!$H$6:$H$40,MATCH(G18,'TDS Rates'!$B$6:$B$40,0)),H18+M18,0))))),0)) | O18: =IF(OR(G18="",H18=""),"",IFERROR(IF(F18="No",IF(INDEX('TDS Rates'!$C$6:$C$40,MATCH(G18,'TDS Rates'!$B$6:$B$40,0))="194Q",Settings!$C$14,MAX(Settings!$C$13,IF(E18="Individual / HUF",INDEX('TDS Rates'!$I$6:$I$40,MATCH(G18,'TDS Rates'!$B$6:$B$40,0)),IF(E18="Company",INDEX('TDS Rates'!$J$6:$J$40,MATCH(G18,'TDS Rates'!$B$6:$B$40,0)),INDEX('TDS Rates'!$K$6:$K$40,MATCH(G18,'TDS Rates'!$B$6:$B$40,0)))))),IF(E18="Individual / HUF",INDEX('TDS Rates'!$I$6:$I$40,MATCH(G18,'TDS Rates'!$B$6:$B$40,0)),IF(E18="Company",INDEX('TDS Rates'!$J$6:$J$40,MATCH(G18,'TDS Rates'!$B$6:$B$40,0)),INDEX('TDS Rates'!$K$6:$K$40,MATCH(G18,'TDS Rates'!$B$6:$B$40,0))))),0)) | P18: =IF(OR(G18="",H18=""),"",ROUND(N18*O18,0)) | Q18: =IF(OR(G18="",H18=""),"",IFERROR(IF(INDEX('TDS Rates'!$E$6:$E$40,MATCH(G18,'TDS Rates'!$B$6:$B$40,0))="Form 141",EOMONTH(IF(R18="",B18,R18),0)+30,IF(MONTH(IF(R18="",B18,R18))=3,DATE(YEAR(IF(R18="",B18,R18)),4,30),DATE(YEAR(IF(R18="",B18,R18)),MONTH(IF(R18="",B18,R18))+1,7))),"")) | U18: =IF(OR(G18="",H18=""),"",IF(P18=0,0,IF(IF(R18="",Settings!$C$9,R18)<=B18,0,((YEAR(IF(R18="",Settings!$C$9,R18))-YEAR(B18))*12+MONTH(IF(R18="",Settings!$C$9,R18))-MONTH(B18)+1)))) | V18: =IF(OR(G18="",H18=""),"",ROUND(P18*Settings!$C$10*U18,0)) | W18: =IF(OR(G18="",H18=""),"",IF(OR(P18=0,R18=""),0,IF(IF(S18="",Settings!$C$9,S18)<=Q18,0,((YEAR(IF(S18="",Settings!$C$9,S18))-YEAR(R18))*12+MONTH(IF(S18="",Settings!$C$9,S18))-MONTH(R18)+1)))) | X18: =IF(OR(G18="",H18=""),"",ROUND(P18*Settings!$C$11*W18,0)) | Y18: =IF(OR(G18="",H18=""),"",V18+X18) | Z18: =IF(OR(G18="",H18=""),"",IF(P18=0,"Below threshold",IF(R18="","Not yet deducted",IF(S18="",IF(Settings!$C$9>Q18,"Overdue — pay now","Deducted, due "&TEXT(Q18,"dd-mmm")),IF(S18<=Q18,IF(N(U18)>0,"Deducted late, paid on time","Paid on time"),"Paid late"))))) | AA18: =IF(OR(G18="",H18=""),"",IF(D18<>"",UPPER(TRIM(D18)),UPPER(TRIM(C18))))
I19: =IF(OR(G19="",H19=""),"",IFERROR(INDEX('TDS Rates'!$D$6:$D$40,MATCH(G19,'TDS Rates'!$B$6:$B$40,0)),"Check nature")) | J19: =IF(OR(G19="",H19=""),"",IFERROR(INDEX('TDS Rates'!$C$6:$C$40,MATCH(G19,'TDS Rates'!$B$6:$B$40,0)),"")) | K19: =IF(OR(G19="",H19=""),"",IFERROR(INDEX('TDS Rates'!$E$6:$E$40,MATCH(G19,'TDS Rates'!$B$6:$B$40,0)),"")) | L19: =IF(OR(G19="",H19=""),"",SUMIFS(H$6:H18,AA$6:AA18,AA19,G$6:G18,G19)) | M19: =IF(OR(G19="",H19=""),"",SUMIFS(H$6:H18,AA$6:AA18,AA19,G$6:G18,G19,N$6:N18,0)) | N19: =IF(OR(G19="",H19=""),"",IFERROR(IF(INDEX('TDS Rates'!$F$6:$F$40,MATCH(G19,'TDS Rates'!$B$6:$B$40,0))="NONE",H19,IF(INDEX('TDS Rates'!$F$6:$F$40,MATCH(G19,'TDS Rates'!$B$6:$B$40,0))="PER",IF(H19>INDEX('TDS Rates'!$G$6:$G$40,MATCH(G19,'TDS Rates'!$B$6:$B$40,0)),H19,0),IF(INDEX('TDS Rates'!$F$6:$F$40,MATCH(G19,'TDS Rates'!$B$6:$B$40,0))="EXCESS",MAX(0,L19+H19-INDEX('TDS Rates'!$H$6:$H$40,MATCH(G19,'TDS Rates'!$B$6:$B$40,0)))-MAX(0,L19-INDEX('TDS Rates'!$H$6:$H$40,MATCH(G19,'TDS Rates'!$B$6:$B$40,0))),IF(INDEX('TDS Rates'!$F$6:$F$40,MATCH(G19,'TDS Rates'!$B$6:$B$40,0))="SA",IF(L19+H19>INDEX('TDS Rates'!$H$6:$H$40,MATCH(G19,'TDS Rates'!$B$6:$B$40,0)),H19+M19,IF(H19>INDEX('TDS Rates'!$G$6:$G$40,MATCH(G19,'TDS Rates'!$B$6:$B$40,0)),H19,0)),IF(L19+H19>INDEX('TDS Rates'!$H$6:$H$40,MATCH(G19,'TDS Rates'!$B$6:$B$40,0)),H19+M19,0))))),0)) | O19: =IF(OR(G19="",H19=""),"",IFERROR(IF(F19="No",IF(INDEX('TDS Rates'!$C$6:$C$40,MATCH(G19,'TDS Rates'!$B$6:$B$40,0))="194Q",Settings!$C$14,MAX(Settings!$C$13,IF(E19="Individual / HUF",INDEX('TDS Rates'!$I$6:$I$40,MATCH(G19,'TDS Rates'!$B$6:$B$40,0)),IF(E19="Company",INDEX('TDS Rates'!$J$6:$J$40,MATCH(G19,'TDS Rates'!$B$6:$B$40,0)),INDEX('TDS Rates'!$K$6:$K$40,MATCH(G19,'TDS Rates'!$B$6:$B$40,0)))))),IF(E19="Individual / HUF",INDEX('TDS Rates'!$I$6:$I$40,MATCH(G19,'TDS Rates'!$B$6:$B$40,0)),IF(E19="Company",INDEX('TDS Rates'!$J$6:$J$40,MATCH(G19,'TDS Rates'!$B$6:$B$40,0)),INDEX('TDS Rates'!$K$6:$K$40,MATCH(G19,'TDS Rates'!$B$6:$B$40,0))))),0)) | P19: =IF(OR(G19="",H19=""),"",ROUND(N19*O19,0)) | Q19: =IF(OR(G19="",H19=""),"",IFERROR(IF(INDEX('TDS Rates'!$E$6:$E$40,MATCH(G19,'TDS Rates'!$B$6:$B$40,0))="Form 141",EOMONTH(IF(R19="",B19,R19),0)+30,IF(MONTH(IF(R19="",B19,R19))=3,DATE(YEAR(IF(R19="",B19,R19)),4,30),DATE(YEAR(IF(R19="",B19,R19)),MONTH(IF(R19="",B19,R19))+1,7))),"")) | U19: =IF(OR(G19="",H19=""),"",IF(P19=0,0,IF(IF(R19="",Settings!$C$9,R19)<=B19,0,((YEAR(IF(R19="",Settings!$C$9,R19))-YEAR(B19))*12+MONTH(IF(R19="",Settings!$C$9,R19))-MONTH(B19)+1)))) | V19: =IF(OR(G19="",H19=""),"",ROUND(P19*Settings!$C$10*U19,0)) | W19: =IF(OR(G19="",H19=""),"",IF(OR(P19=0,R19=""),0,IF(IF(S19="",Settings!$C$9,S19)<=Q19,0,((YEAR(IF(S19="",Settings!$C$9,S19))-YEAR(R19))*12+MONTH(IF(S19="",Settings!$C$9,S19))-MONTH(R19)+1)))) | X19: =IF(OR(G19="",H19=""),"",ROUND(P19*Settings!$C$11*W19,0)) | Y19: =IF(OR(G19="",H19=""),"",V19+X19) | Z19: =IF(OR(G19="",H19=""),"",IF(P19=0,"Below threshold",IF(R19="","Not yet deducted",IF(S19="",IF(Settings!$C$9>Q19,"Overdue — pay now","Deducted, due "&TEXT(Q19,"dd-mmm")),IF(S19<=Q19,IF(N(U19)>0,"Deducted late, paid on time","Paid on time"),"Paid late"))))) | AA19: =IF(OR(G19="",H19=""),"",IF(D19<>"",UPPER(TRIM(D19)),UPPER(TRIM(C19))))
I20: =IF(OR(G20="",H20=""),"",IFERROR(INDEX('TDS Rates'!$D$6:$D$40,MATCH(G20,'TDS Rates'!$B$6:$B$40,0)),"Check nature")) | J20: =IF(OR(G20="",H20=""),"",IFERROR(INDEX('TDS Rates'!$C$6:$C$40,MATCH(G20,'TDS Rates'!$B$6:$B$40,0)),"")) | K20: =IF(OR(G20="",H20=""),"",IFERROR(INDEX('TDS Rates'!$E$6:$E$40,MATCH(G20,'TDS Rates'!$B$6:$B$40,0)),"")) | L20: =IF(OR(G20="",H20=""),"",SUMIFS(H$6:H19,AA$6:AA19,AA20,G$6:G19,G20)) | M20: =IF(OR(G20="",H20=""),"",SUMIFS(H$6:H19,AA$6:AA19,AA20,G$6:G19,G20,N$6:N19,0)) | N20: =IF(OR(G20="",H20=""),"",IFERROR(IF(INDEX('TDS Rates'!$F$6:$F$40,MATCH(G20,'TDS Rates'!$B$6:$B$40,0))="NONE",H20,IF(INDEX('TDS Rates'!$F$6:$F$40,MATCH(G20,'TDS Rates'!$B$6:$B$40,0))="PER",IF(H20>INDEX('TDS Rates'!$G$6:$G$40,MATCH(G20,'TDS Rates'!$B$6:$B$40,0)),H20,0),IF(INDEX('TDS Rates'!$F$6:$F$40,MATCH(G20,'TDS Rates'!$B$6:$B$40,0))="EXCESS",MAX(0,L20+H20-INDEX('TDS Rates'!$H$6:$H$40,MATCH(G20,'TDS Rates'!$B$6:$B$40,0)))-MAX(0,L20-INDEX('TDS Rates'!$H$6:$H$40,MATCH(G20,'TDS Rates'!$B$6:$B$40,0))),IF(INDEX('TDS Rates'!$F$6:$F$40,MATCH(G20,'TDS Rates'!$B$6:$B$40,0))="SA",IF(L20+H20>INDEX('TDS Rates'!$H$6:$H$40,MATCH(G20,'TDS Rates'!$B$6:$B$40,0)),H20+M20,IF(H20>INDEX('TDS Rates'!$G$6:$G$40,MATCH(G20,'TDS Rates'!$B$6:$B$40,0)),H20,0)),IF(L20+H20>INDEX('TDS Rates'!$H$6:$H$40,MATCH(G20,'TDS Rates'!$B$6:$B$40,0)),H20+M20,0))))),0)) | O20: =IF(OR(G20="",H20=""),"",IFERROR(IF(F20="No",IF(INDEX('TDS Rates'!$C$6:$C$40,MATCH(G20,'TDS Rates'!$B$6:$B$40,0))="194Q",Settings!$C$14,MAX(Settings!$C$13,IF(E20="Individual / HUF",INDEX('TDS Rates'!$I$6:$I$40,MATCH(G20,'TDS Rates'!$B$6:$B$40,0)),IF(E20="Company",INDEX('TDS Rates'!$J$6:$J$40,MATCH(G20,'TDS Rates'!$B$6:$B$40,0)),INDEX('TDS Rates'!$K$6:$K$40,MATCH(G20,'TDS Rates'!$B$6:$B$40,0)))))),IF(E20="Individual / HUF",INDEX('TDS Rates'!$I$6:$I$40,MATCH(G20,'TDS Rates'!$B$6:$B$40,0)),IF(E20="Company",INDEX('TDS Rates'!$J$6:$J$40,MATCH(G20,'TDS Rates'!$B$6:$B$40,0)),INDEX('TDS Rates'!$K$6:$K$40,MATCH(G20,'TDS Rates'!$B$6:$B$40,0))))),0)) | P20: =IF(OR(G20="",H20=""),"",ROUND(N20*O20,0)) | Q20: =IF(OR(G20="",H20=""),"",IFERROR(IF(INDEX('TDS Rates'!$E$6:$E$40,MATCH(G20,'TDS Rates'!$B$6:$B$40,0))="Form 141",EOMONTH(IF(R20="",B20,R20),0)+30,IF(MONTH(IF(R20="",B20,R20))=3,DATE(YEAR(IF(R20="",B20,R20)),4,30),DATE(YEAR(IF(R20="",B20,R20)),MONTH(IF(R20="",B20,R20))+1,7))),"")) | U20: =IF(OR(G20="",H20=""),"",IF(P20=0,0,IF(IF(R20="",Settings!$C$9,R20)<=B20,0,((YEAR(IF(R20="",Settings!$C$9,R20))-YEAR(B20))*12+MONTH(IF(R20="",Settings!$C$9,R20))-MONTH(B20)+1)))) | V20: =IF(OR(G20="",H20=""),"",ROUND(P20*Settings!$C$10*U20,0)) | W20: =IF(OR(G20="",H20=""),"",IF(OR(P20=0,R20=""),0,IF(IF(S20="",Settings!$C$9,S20)<=Q20,0,((YEAR(IF(S20="",Settings!$C$9,S20))-YEAR(R20))*12+MONTH(IF(S20="",Settings!$C$9,S20))-MONTH(R20)+1)))) | X20: =IF(OR(G20="",H20=""),"",ROUND(P20*Settings!$C$11*W20,0)) | Y20: =IF(OR(G20="",H20=""),"",V20+X20) | Z20: =IF(OR(G20="",H20=""),"",IF(P20=0,"Below threshold",IF(R20="","Not yet deducted",IF(S20="",IF(Settings!$C$9>Q20,"Overdue — pay now","Deducted, due "&TEXT(Q20,"dd-mmm")),IF(S20<=Q20,IF(N(U20)>0,"Deducted late, paid on time","Paid on time"),"Paid late"))))) | AA20: =IF(OR(G20="",H20=""),"",IF(D20<>"",UPPER(TRIM(D20)),UPPER(TRIM(C20))))
